Workbook

Sheet dashboard
A1: CBAM Policy Dashboard — Pass 7
A2: 5 countries × 8 products × 12 years. 5-scope coverage flags, global MRV per product, exports-only tax option, BF-BOF integrated, NH₃ chain explicitly accounted, EF matrix included.
A4: 1. COUNTRY & VIEW SETTINGS
A5: Country selector | B5: egy | C5: → | D5: Choose from: egy, alb, uzb, aze, ind.
A6: Detail year (for price-impact table) | B6: 2030 | C6: → | D6: Year for the price-impact section. | P6: =MATCH(TEXT($B$6,"0"),input_data!$M$3:$X$3,0) -> 7
A7: Pass-through θ (share of wedge to buyer prices) | B7: 0.7 | C7: → | D7: Share of carbon wedge passed to buyers (rest hits producer margins).
A9: 2. POLICY CHOICES
A10: 2a. Coverage flags — what the domestic CP is levied on (1 = covered, 0 = not)
A11: Coverage S1.fc (Scope 1 — Fuel combustion CO₂) | B11: 1 | C11: → | D11: Combustion fuels (heat, steam).
A12: Coverage S1.fp (Scope 1 — Fuel-as-reductant CO₂) | B12: 1 | C12: → | D12: Fuel-as-reductant (BF coke + PCI, DRI shaft NG, SMR reformer NG).
A13: Coverage S1.np (Scope 1 — Non-fuel process CO₂) | B13: 1 | C13: → | D13: Calcination CO₂ (cement, anode), urea CO₂ uptake (negative for urea).
A14: Coverage S1.no (Scope 1 — Non-CO₂ GHG (CO₂e)) | B14: 1 | C14: → | D14: N₂O from HNO₃, PFCs from Hall-Héroult.
A15: Coverage S2 (Scope 2 — Electricity (indirect)) | B15: 1 | C15: → | D15: Indirect electricity emissions.
A17: 2b. MRV per product (global — applies to all countries; 1 = MRV verified, EU uses actual)
A18: Product → | B18: DRI | C18: Scrap | D18: BF-BOF | E18: Cement | F18: NH₃ | G18: Urea | H18: AN | I18: Al
A19: MRV flag (edit here): | B19: 1 | C19: 1 | D19: 1 | E19: 1 | F19: 1 | G19: 1 | H19: 1 | I19: 1
A20: CBAM S2 scope (reg., Annex II = 0): | B20: =INDEX(input_data!$L:$L,MATCH("all.in.cs2.stl.drg.---",input_data!$A:$A,0)) -> 0 | C20: =INDEX(input_data!$L:$L,MATCH("all.in.cs2.stl.scr.---",input_data!$A:$A,0)) -> 0 | D20: =INDEX(input_data!$L:$L,MATCH("all.in.cs2.stl.bof.---",input_data!$A:$A,0)) -> 0 | E20: =INDEX(input_data!$L:$L,MATCH("all.in.cs2.cmt.dry.---",input_data!$A:$A,0)) -> 1 | F20: =INDEX(input_data!$L:$L,MATCH("all.in.cs2.frt.amc.---",input_data!$A:$A,0)) -> 1 | G20: =INDEX(input_data!$L:$L,MATCH("all.in.cs2.frt.ure.---",input_data!$A:$A,0)) -> 1 | H20: =INDEX(input_data!$L:$L,MATCH("all.in.cs2.frt.nit.---",input_data!$A:$A,0)) -> 1 | I20: =INDEX(input_data!$L:$L,MATCH("all.in.cs2.alu.prp.---",input_data!$A:$A,0)) -> 0
A22: 2c. Tax only exports? (1 = yes — no domestic CP on home consumption; 0 = no) | B22: 0 | C22: → | D22: When 1, the country's CP is levied only on EU + non-EU exports (not on domestic-consumed product). Useful for politically-constrained pricing.
A24: 3. CARBON PRICE TIME SERIES
A25: row | B25: unit | D25: 2024 | E25: 2025 | F25: 2026 | G25: 2027 | H25: 2028 | I25: 2029 | J25: 2030 | K25: 2031 | L25: 2032 | M25: 2033 | N25: 2034 | O25: 2035
A26: EU ETS price | B26: EUR/tCO2 | D26: =INDEX(input_data!$M:$X,MATCH("all.in.ets.---.---.---",input_data!$A:$A,0),1) -> 85 | E26: =INDEX(input_data!$M:$X,MATCH("all.in.ets.---.---.---",input_data!$A:$A,0),2) -> 90 | F26: =INDEX(input_data!$M:$X,MATCH("all.in.ets.---.---.---",input_data!$A:$A,0),3) -> 100 | G26: =INDEX(input_data!$M:$X,MATCH("all.in.ets.---.---.---",input_data!$A:$A,0),4) -> 105 | H26: =INDEX(input_data!$M:$X,MATCH("all.in.ets.---.---.---",input_data!$A:$A,0),5) -> 110 | I26: =INDEX(input_data!$M:$X,MATCH("all.in.ets.---.---.---",input_data!$A:$A,0),6) -> 110 | J26: =INDEX(input_data!$M:$X,MATCH("all.in.ets.---.---.---",input_data!$A:$A,0),7) -> 115 | K26: =INDEX(input_data!$M:$X,MATCH("all.in.ets.---.---.---",input_data!$A:$A,0),8) -> 120 | L26: =INDEX(input_data!$M:$X,MATCH("all.in.ets.---.---.---",input_data!$A:$A,0),9) -> 125 | M26: =INDEX(input_data!$M:$X,MATCH("all.in.ets.---.---.---",input_data!$A:$A,0),10) -> 130 | N26: =INDEX(input_data!$M:$X,MATCH("all.in.ets.---.---.---",input_data!$A:$A,0),11) -> 135 | O26: =INDEX(input_data!$M:$X,MATCH("all.in.ets.---.---.---",input_data!$A:$A,0),12) -> 140
A27: CBAM factor | B27: fraction | D27: =INDEX(input_data!$M:$X,MATCH("all.in.cbf.---.---.---",input_data!$A:$A,0),1) -> 0 | E27: =INDEX(input_data!$M:$X,MATCH("all.in.cbf.---.---.---",input_data!$A:$A,0),2) -> 0 | F27: =INDEX(input_data!$M:$X,MATCH("all.in.cbf.---.---.---",input_data!$A:$A,0),3) -> 0.025 | G27: =INDEX(input_data!$M:$X,MATCH("all.in.cbf.---.---.---",input_data!$A:$A,0),4) -> 0.05 | H27: =INDEX(input_data!$M:$X,MATCH("all.in.cbf.---.---.---",input_data!$A:$A,0),5) -> 0.1 | I27: =INDEX(input_data!$M:$X,MATCH("all.in.cbf.---.---.---",input_data!$A:$A,0),6) -> 0.225 | J27: =INDEX(input_data!$M:$X,MATCH("all.in.cbf.---.---.---",input_data!$A:$A,0),7) -> 0.485 | K27: =INDEX(input_data!$M:$X,MATCH("all.in.cbf.---.---.---",input_data!$A:$A,0),8) -> 0.61 | L27: =INDEX(input_data!$M:$X,MATCH("all.in.cbf.---.---.---",input_data!$A:$A,0),9) -> 0.735 | M27: =INDEX(input_data!$M:$X,MATCH("all.in.cbf.---.---.---",input_data!$A:$A,0),10) -> 0.86 | N27: =INDEX(input_data!$M:$X,MATCH("all.in.cbf.---.---.---",input_data!$A:$A,0),11) -> 1 | O27: =INDEX(input_data!$M:$X,MATCH("all.in.cbf.---.---.---",input_data!$A:$A,0),12) -> 1
A28: ↓ OPTIMAL CP (captures full CBAM as country revenue) | B28: USD/tCO2 | D28: =IFERROR((IFERROR(calculations!M21*calculations!M248,0)+IFERROR(calculations!M49*calculations!M253,0)+IFERROR(calculations!M77*calculations!M258,0)+IFERROR(calculations!M105*calculations!M263,0)+IFERROR(calculations!M133*calculations!M268,0)+IFERROR(calculations!M161*calculations!M273,0)+IFERROR(calculations!M189*calculations!M278,0)+IFERROR(calculations!M217*calculations!M283,0))/(IFERROR(calculations!M21/calculations!M20*((calculations!M41+calculations!M244)*$B$11+calculations!M42*$B$12+calculations!M43*$B$13+calculations!M44*$B$14+calculations!M45*$B$15*INDEX(input_data!$L:$L,MATCH("all.in.cs2.stl.drg.---",input_data!$A:$A,0))),0)+IFERROR(calculations!M49/calculations!M48*((calculations!M69+calculations!M249)*$B$11+calculations!M70*$B$12+calculations!M71*$B$13+calculations!M72*$B$14+calculations!M73*$B$15*INDEX(input_data!$L:$L,MATCH("all.in.cs2.stl.scr.---",input_data!$A:$A,0))),0)+IFERROR(calculations!M77/calculations!M76*((calculations!M97+calculations!M254)*$B$11+calculations!M98*$B$12+calculations!M99*$B$13+calculations!M100*$B$14+calculations!M101*$B$15*INDEX(input_data!$L:$L,MATCH("all.in.cs2.stl.bof.---",input_data!$A:$A,0))),0)+IFERROR(calculations!M105/calculations!M104*((calculations!M125+calculations!M259)*$B$11+calculations!M126*$B$12+calculations!M127*$B$13+calculations!M128*$B$14+calculations!M129*$B$15*INDEX(input_data!$L:$L,MATCH("all.in.cs2.cmt.dry.---",input_data!$A:$A,0))),0)+IFERROR(calculations!M133/calculations!M132*((calculations!M153+calculations!M264)*$B$11+calculations!M154*$B$12+calculations!M155*$B$13+calculations!M156*$B$14+calculations!M157*$B$15*INDEX(input_data!$L:$L,MATCH("all.in.cs2.frt.amc.---",input_data!$A:$A,0))),0)+IFERROR(calculations!M161/calculations!M160*((calculations!M181+calculations!M269)*$B$11+calculations!M182*$B$12+calculations!M183*$B$13+calculations!M184*$B$14+calculations!M185*$B$15*INDEX(input_data!$L:$L,MATCH("all.in.cs2.frt.ure.---",input_data!$A:$A,0))),0)+IFERROR(calculations!M189/calculations!M188*((calculations!M209+calculations!M274)*$B$11+calculations!M210*$B$12+calculations!M211*$B$13+calculations!M212*$B$14+calculations!M213*$B$15*INDEX(input_data!$L:$L,MATCH("all.in.cs2.frt.nit.---",input_data!$A:$A,0))),0)+IFERROR(calculations!M217/calculations!M216*((calculations!M237+calculations!M279)*$B$11+calculations!M238*$B$12+calculations!M239*$B$13+calculations!M240*$B$14+calculations!M241*$B$15*INDEX(input_data!$L:$L,MATCH("all.in.cs2.alu.prp.---",input_data!$A:$A,0))),0)),0) -> 0 | E28: =IFERROR((IFERROR(calculations!N21*calculations!N248,0)+IFERROR(calculations!N49*calculations!N253,0)+IFERROR(calculations!N77*calculations!N258,0)+IFERROR(calculations!N105*calculations!N263,0)+IFERROR(calculations!N133*calculations!N268,0)+IFERROR(calculations!N161*calculations!N273,0)+IFERROR(calculations!N189*calculations!N278,0)+IFERROR(calculations!N217*calculations!N283,0))/(IFERROR(calculations!N21/calculations!N20*((calculations!N41+calculations!N244)*$B$11+calculations!N42*$B$12+calculations!N43*$B$13+calculations!N44*$B$14+calculations!N45*$B$15*INDEX(input_data!$L:$L,MATCH("all.in.cs2.stl.drg.---",input_data!$A:$A,0))),0)+IFERROR(calculations!N49/calculations!N48*((calculations!N69+calculations!N249)*$B$11+calculations!N70*$B$12+calculations!N71*$B$13+calculations!N72*$B$14+calculations!N73*$B$15*INDEX(input_data!$L:$L,MATCH("all.in.cs2.stl.scr.---",input_data!$A:$A,0))),0)+IFERROR(calculations!N77/calculations!N76*((calculations!N97+calculations!N254)*$B$11+calculations!N98*$B$12+calculations!N99*$B$13+calculations!N100*$B$14+calculations!N101*$B$15*INDEX(input_data!$L:$L,MATCH("all.in.cs2.stl.bof.---",input_data!$A:$A,0))),0)+IFERROR(calculations!N105/calculations!N104*((calculations!N125+calculations!N259)*$B$11+calculations!N126*$B$12+calculations!N127*$B$13+calculations!N128*$B$14+calculations!N129*$B$15*INDEX(input_data!$L:$L,MATCH("all.in.cs2.cmt.dry.---",input_data!$A:$A,0))),0)+IFERROR(calculations!N133/calculations!N132*((calculations!N153+calculations!N264)*$B$11+calculations!N154*$B$12+calculations!N155*$B$13+calculations!N156*$B$14+calculations!N157*$B$15*INDEX(input_data!$L:$L,MATCH("all.in.cs2.frt.amc.---",input_data!$A:$A,0))),0)+IFERROR(calculations!N161/calculations!N160*((calculations!N181+calculations!N269)*$B$11+calculations!N182*$B$12+calculations!N183*$B$13+calculations!N184*$B$14+calculations!N185*$B$15*INDEX(input_data!$L:$L,MATCH("all.in.cs2.frt.ure.---",input_data!$A:$A,0))),0)+IFERROR(calculations!N189/calculations!N188*((calculations!N209+calculations!N274)*$B$11+calculations!N210*$B$12+calculations!N211*$B$13+calculations!N212*$B$14+calculations!N213*$B$15*INDEX(input_data!$L:$L,MATCH("all.in.cs2.frt.nit.---",input_data!$A:$A,0))),0)+IFERROR(calculations!N217/calculations!N216*((calculations!N237+calculations!N279)*$B$11+calculations!N238*$B$12+calculations!N239*$B$13+calculations!N240*$B$14+calculations!N241*$B$15*INDEX(input_data!$L:$L,MATCH("all.in.cs2.alu.prp.---",input_data!$A:$A,0))),0)),0) -> 0 | F28: =IFERROR((IFERROR(calculations!O21*calculations!O248,0)+IFERROR(calculations!O49*calculations!O253,0)+IFERROR(calculations!O77*calculations!O258,0)+IFERROR(calculations!O105*calculations!O263,0)+IFERROR(calculations!O133*calculations!O268,0)+IFERROR(calculations!O161*calculations!O273,0)+IFERROR(calculations!O189*calculations!O278,0)+IFERROR(calculations!O217*calculations!O283,0))/(IFERROR(calculations!O21/calculations!O20*((calculations!O41+calculations!O244)*$B$11+calculations!O42*$B$12+calculations!O43*$B$13+calculations!O44*$B$14+calculations!O45*$B$15*INDEX(input_data!$L:$L,MATCH("all.in.cs2.stl.drg.---",input_data!$A:$A,0))),0)+IFERROR(calculations!O49/calculations!O48*((calculations!O69+calculations!O249)*$B$11+calculations!O70*$B$12+calculations!O71*$B$13+calculations!O72*$B$14+calculations!O73*$B$15*INDEX(input_data!$L:$L,MATCH("all.in.cs2.stl.scr.---",input_data!$A:$A,0))),0)+IFERROR(calculations!O77/calculations!O76*((calculations!O97+calculations!O254)*$B$11+calculations!O98*$B$12+calculations!O99*$B$13+calculations!O100*$B$14+calculations!O101*$B$15*INDEX(input_data!$L:$L,MATCH("all.in.cs2.stl.bof.---",input_data!$A:$A,0))),0)+IFERROR(calculations!O105/calculations!O104*((calculations!O125+calculations!O259)*$B$11+calculations!O126*$B$12+calculations!O127*$B$13+calculations!O128*$B$14+calculations!O129*$B$15*INDEX(input_data!$L:$L,MATCH("all.in.cs2.cmt.dry.---",input_data!$A:$A,0))),0)+IFERROR(calculations!O133/calculations!O132*((calculations!O153+calculations!O264)*$B$11+calculations!O154*$B$12+calculations!O155*$B$13+calculations!O156*$B$14+calculations!O157*$B$15*INDEX(input_data!$L:$L,MATCH("all.in.cs2.frt.amc.---",input_data!$A:$A,0))),0)+IFERROR(calculations!O161/calculations!O160*((calculations!O181+calculations!O269)*$B$11+calculations!O182*$B$12+calculations!O183*$B$13+calculations!O184*$B$14+calculations!O185*$B$15*INDEX(input_data!$L:$L,MATCH("all.in.cs2.frt.ure.---",input_data!$A:$A,0))),0)+IFERROR(calculations!O189/calculations!O188*((calculations!O209+calculations!O274)*$B$11+calculations!O210*$B$12+calculations!O211*$B$13+calculations!O212*$B$14+calculations!O213*$B$15*INDEX(input_data!$L:$L,MATCH("all.in.cs2.frt.nit.---",input_data!$A:$A,0))),0)+IFERROR(calculations!O217/calculations!O216*((calculations!O237+calculations!O279)*$B$11+calculations!O238*$B$12+calculations!O239*$B$13+calculations!O240*$B$14+calculations!O241*$B$15*INDEX(input_data!$L:$L,MATCH("all.in.cs2.alu.prp.---",input_data!$A:$A,0))),0)),0) -> 58.95271 | G28: =IFERROR((IFERROR(calculations!P21*calculations!P248,0)+IFERROR(calculations!P49*calculations!P253,0)+IFERROR(calculations!P77*calculations!P258,0)+IFERROR(calculations!P105*calculations!P263,0)+IFERROR(calculations!P133*calculations!P268,0)+IFERROR(calculations!P161*calculations!P273,0)+IFERROR(calculations!P189*calculations!P278,0)+IFERROR(calculations!P217*calculations!P283,0))/(IFERROR(calculations!P21/calculations!P20*((calculations!P41+calculations!P244)*$B$11+calculations!P42*$B$12+calculations!P43*$B$13+calculations!P44*$B$14+calculations!P45*$B$15*INDEX(input_data!$L:$L,MATCH("all.in.cs2.stl.drg.---",input_data!$A:$A,0))),0)+IFERROR(calculations!P49/calculations!P48*((calculations!P69+calculations!P249)*$B$11+calculations!P70*$B$12+calculations!P71*$B$13+calculations!P72*$B$14+calculations!P73*$B$15*INDEX(input_data!$L:$L,MATCH("all.in.cs2.stl.scr.---",input_data!$A:$A,0))),0)+IFERROR(calculations!P77/calculations!P76*((calculations!P97+calculations!P254)*$B$11+calculations!P98*$B$12+calculations!P99*$B$13+calculations!P100*$B$14+calculations!P101*$B$15*INDEX(input_data!$L:$L,MATCH("all.in.cs2.stl.bof.---",input_data!$A:$A,0))),0)+IFERROR(calculations!P105/calculations!P104*((calculations!P125+calculations!P259)*$B$11+calculations!P126*$B$12+calculations!P127*$B$13+calculations!P128*$B$14+calculations!P129*$B$15*INDEX(input_data!$L:$L,MATCH("all.in.cs2.cmt.dry.---",input_data!$A:$A,0))),0)+IFERROR(calculations!P133/calculations!P132*((calculations!P153+calculations!P264)*$B$11+calculations!P154*$B$12+calculations!P155*$B$13+calculations!P156*$B$14+calculations!P157*$B$15*INDEX(input_data!$L:$L,MATCH("all.in.cs2.frt.amc.---",input_data!$A:$A,0))),0)+IFERROR(calculations!P161/calculations!P160*((calculations!P181+calculations!P269)*$B$11+calculations!P182*$B$12+calculations!P183*$B$13+calculations!P184*$B$14+calculations!P185*$B$15*INDEX(input_data!$L:$L,MATCH("all.in.cs2.frt.ure.---",input_data!$A:$A,0))),0)+IFERROR(calculations!P189/calculations!P188*((calculations!P209+calculations!P274)*$B$11+calculations!P210*$B$12+calculations!P211*$B$13+calculations!P212*$B$14+calculations!P213*$B$15*INDEX(input_data!$L:$L,MATCH("all.in.cs2.frt.nit.---",input_data!$A:$A,0))),0)+IFERROR(calculations!P217/calculations!P216*((calculations!P237+calculations!P279)*$B$11+calculations!P238*$B$12+calculations!P239*$B$13+calculations!P240*$B$14+calculations!P241*$B$15*INDEX(input_data!$L:$L,MATCH("all.in.cs2.alu.prp.---",input_data!$A:$A,0))),0)),0) -> 63.24289 | H28: =IFERROR((IFERROR(calculations!Q21*calculations!Q248,0)+IFERROR(calculations!Q49*calculations!Q253,0)+IFERROR(calculations!Q77*calculations!Q258,0)+IFERROR(calculations!Q105*calculations!Q263,0)+IFERROR(calculations!Q133*calculations!Q268,0)+IFERROR(calculations!Q161*calculations!Q273,0)+IFERROR(calculations!Q189*calculations!Q278,0)+IFERROR(calculations!Q217*calculations!Q283,0))/(IFERROR(calculations!Q21/calculations!Q20*((calculations!Q41+calculations!Q244)*$B$11+calculations!Q42*$B$12+calculations!Q43*$B$13+calculations!Q44*$B$14+calculations!Q45*$B$15*INDEX(input_data!$L:$L,MATCH("all.in.cs2.stl.drg.---",input_data!$A:$A,0))),0)+IFERROR(calculations!Q49/calculations!Q48*((calculations!Q69+calculations!Q249)*$B$11+calculations!Q70*$B$12+calculations!Q71*$B$13+calculations!Q72*$B$14+calculations!Q73*$B$15*INDEX(input_data!$L:$L,MATCH("all.in.cs2.stl.scr.---",input_data!$A:$A,0))),0)+IFERROR(calculations!Q77/calculations!Q76*((calculations!Q97+calculations!Q254)*$B$11+calculations!Q98*$B$12+calculations!Q99*$B$13+calculations!Q100*$B$14+calculations!Q101*$B$15*INDEX(input_data!$L:$L,MATCH("all.in.cs2.stl.bof.---",input_data!$A:$A,0))),0)+IFERROR(calculations!Q105/calculations!Q104*((calculations!Q125+calculations!Q259)*$B$11+calculations!Q126*$B$12+calculations!Q127*$B$13+calculations!Q128*$B$14+calculations!Q129*$B$15*INDEX(input_data!$L:$L,MATCH("all.in.cs2.cmt.dry.---",input_data!$A:$A,0))),0)+IFERROR(calculations!Q133/calculations!Q132*((calculations!Q153+calculations!Q264)*$B$11+calculations!Q154*$B$12+calculations!Q155*$B$13+calculations!Q156*$B$14+calculations!Q157*$B$15*INDEX(input_data!$L:$L,MATCH("all.in.cs2.frt.amc.---",input_data!$A:$A,0))),0)+IFERROR(calculations!Q161/calculations!Q160*((calculations!Q181+calculations!Q269)*$B$11+calculations!Q182*$B$12+calculations!Q183*$B$13+calculations!Q184*$B$14+calculations!Q185*$B$15*INDEX(input_data!$L:$L,MATCH("all.in.cs2.frt.ure.---",input_data!$A:$A,0))),0)+IFERROR(calculations!Q189/calculations!Q188*((calculations!Q209+calculations!Q274)*$B$11+calculations!Q210*$B$12+calculations!Q211*$B$13+calculations!Q212*$B$14+calculations!Q213*$B$15*INDEX(input_data!$L:$L,MATCH("all.in.cs2.frt.nit.---",input_data!$A:$A,0))),0)+IFERROR(calculations!Q217/calculations!Q216*((calculations!Q237+calculations!Q279)*$B$11+calculations!Q238*$B$12+calculations!Q239*$B$13+calculations!Q240*$B$14+calculations!Q241*$B$15*INDEX(input_data!$L:$L,MATCH("all.in.cs2.alu.prp.---",input_data!$A:$A,0))),0)),0) -> 68.910911 | I28: =IFERROR((IFERROR(calculations!R21*calculations!R248,0)+IFERROR(calculations!R49*calculations!R253,0)+IFERROR(calculations!R77*calculations!R258,0)+IFERROR(calculations!R105*calculations!R263,0)+IFERROR(calculations!R133*calculations!R268,0)+IFERROR(calculations!R161*calculations!R273,0)+IFERROR(calculations!R189*calculations!R278,0)+IFERROR(calculations!R217*calculations!R283,0))/(IFERROR(calculations!R21/calculations!R20*((calculations!R41+calculations!R244)*$B$11+calculations!R42*$B$12+calculations!R43*$B$13+calculations!R44*$B$14+calculations!R45*$B$15*INDEX(input_data!$L:$L,MATCH("all.in.cs2.stl.drg.---",input_data!$A:$A,0))),0)+IFERROR(calculations!R49/calculations!R48*((calculations!R69+calculations!R249)*$B$11+calculations!R70*$B$12+calculations!R71*$B$13+calculations!R72*$B$14+calculations!R73*$B$15*INDEX(input_data!$L:$L,MATCH("all.in.cs2.stl.scr.---",input_data!$A:$A,0))),0)+IFERROR(calculations!R77/calculations!R76*((calculations!R97+calculations!R254)*$B$11+calculations!R98*$B$12+calculations!R99*$B$13+calculations!R100*$B$14+calculations!R101*$B$15*INDEX(input_data!$L:$L,MATCH("all.in.cs2.stl.bof.---",input_data!$A:$A,0))),0)+IFERROR(calculations!R105/calculations!R104*((calculations!R125+calculations!R259)*$B$11+calculations!R126*$B$12+calculations!R127*$B$13+calculations!R128*$B$14+calculations!R129*$B$15*INDEX(input_data!$L:$L,MATCH("all.in.cs2.cmt.dry.---",input_data!$A:$A,0))),0)+IFERROR(calculations!R133/calculations!R132*((calculations!R153+calculations!R264)*$B$11+calculations!R154*$B$12+calculations!R155*$B$13+calculations!R156*$B$14+calculations!R157*$B$15*INDEX(input_data!$L:$L,MATCH("all.in.cs2.frt.amc.---",input_data!$A:$A,0))),0)+IFERROR(calculations!R161/calculations!R160*((calculations!R181+calculations!R269)*$B$11+calculations!R182*$B$12+calculations!R183*$B$13+calculations!R184*$B$14+calculations!R185*$B$15*INDEX(input_data!$L:$L,MATCH("all.in.cs2.frt.ure.---",input_data!$A:$A,0))),0)+IFERROR(calculations!R189/calculations!R188*((calculations!R209+calculations!R274)*$B$11+calculations!R210*$B$12+calculations!R211*$B$13+calculations!R212*$B$14+calculations!R213*$B$15*INDEX(input_data!$L:$L,MATCH("all.in.cs2.frt.nit.---",input_data!$A:$A,0))),0)+IFERROR(calculations!R217/calculations!R216*((calculations!R237+calculations!R279)*$B$11+calculations!R238*$B$12+calculations!R239*$B$13+calculations!R240*$B$14+calculations!R241*$B$15*INDEX(input_data!$L:$L,MATCH("all.in.cs2.alu.prp.---",input_data!$A:$A,0))),0)),0) -> 75.316603 | J28: =IFERROR((IFERROR(calculations!S21*calculations!S248,0)+IFERROR(calculations!S49*calculations!S253,0)+IFERROR(calculations!S77*calculations!S258,0)+IFERROR(calculations!S105*calculations!S263,0)+IFERROR(calculations!S133*calculations!S268,0)+IFERROR(calculations!S161*calculations!S273,0)+IFERROR(calculations!S189*calculations!S278,0)+IFERROR(calculations!S217*calculations!S283,0))/(IFERROR(calculations!S21/calculations!S20*((calculations!S41+calculations!S244)*$B$11+calculations!S42*$B$12+calculations!S43*$B$13+calculations!S44*$B$14+calculations!S45*$B$15*INDEX(input_data!$L:$L,MATCH("all.in.cs2.stl.drg.---",input_data!$A:$A,0))),0)+IFERROR(calculations!S49/calculations!S48*((calculations!S69+calculations!S249)*$B$11+calculations!S70*$B$12+calculations!S71*$B$13+calculations!S72*$B$14+calculations!S73*$B$15*INDEX(input_data!$L:$L,MATCH("all.in.cs2.stl.scr.---",input_data!$A:$A,0))),0)+IFERROR(calculations!S77/calculations!S76*((calculations!S97+calculations!S254)*$B$11+calculations!S98*$B$12+calculations!S99*$B$13+calculations!S100*$B$14+calculations!S101*$B$15*INDEX(input_data!$L:$L,MATCH("all.in.cs2.stl.bof.---",input_data!$A:$A,0))),0)+IFERROR(calculations!S105/calculations!S104*((calculations!S125+calculations!S259)*$B$11+calculations!S126*$B$12+calculations!S127*$B$13+calculations!S128*$B$14+calculations!S129*$B$15*INDEX(input_data!$L:$L,MATCH("all.in.cs2.cmt.dry.---",input_data!$A:$A,0))),0)+IFERROR(calculations!S133/calculations!S132*((calculations!S153+calculations!S264)*$B$11+calculations!S154*$B$12+calculations!S155*$B$13+calculations!S156*$B$14+calculations!S157*$B$15*INDEX(input_data!$L:$L,MATCH("all.in.cs2.frt.amc.---",input_data!$A:$A,0))),0)+IFERROR(calculations!S161/calculations!S160*((calculations!S181+calculations!S269)*$B$11+calculations!S182*$B$12+calculations!S183*$B$13+calculations!S184*$B$14+calculations!S185*$B$15*INDEX(input_data!$L:$L,MATCH("all.in.cs2.frt.ure.---",input_data!$A:$A,0))),0)+IFERROR(calculations!S189/calculations!S188*((calculations!S209+calculations!S274)*$B$11+calculations!S210*$B$12+calculations!S211*$B$13+calculations!S212*$B$14+calculations!S213*$B$15*INDEX(input_data!$L:$L,MATCH("all.in.cs2.frt.nit.---",input_data!$A:$A,0))),0)+IFERROR(calculations!S217/calculations!S216*((calculations!S237+calculations!S279)*$B$11+calculations!S238*$B$12+calculations!S239*$B$13+calculations!S240*$B$14+calculations!S241*$B$15*INDEX(input_data!$L:$L,MATCH("all.in.cs2.alu.prp.---",input_data!$A:$A,0))),0)),0) -> 94.247266 | K28: =IFERROR((IFERROR(calculations!T21*calculations!T248,0)+IFERROR(calculations!T49*calculations!T253,0)+IFERROR(calculations!T77*calculations!T258,0)+IFERROR(calculations!T105*calculations!T263,0)+IFERROR(calculations!T133*calculations!T268,0)+IFERROR(calculations!T161*calculations!T273,0)+IFERROR(calculations!T189*calculations!T278,0)+IFERROR(calculations!T217*calculations!T283,0))/(IFERROR(calculations!T21/calculations!T20*((calculations!T41+calculations!T244)*$B$11+calculations!T42*$B$12+calculations!T43*$B$13+calculations!T44*$B$14+calculations!T45*$B$15*INDEX(input_data!$L:$L,MATCH("all.in.cs2.stl.drg.---",input_data!$A:$A,0))),0)+IFERROR(calculations!T49/calculations!T48*((calculations!T69+calculations!T249)*$B$11+calculations!T70*$B$12+calculations!T71*$B$13+calculations!T72*$B$14+calculations!T73*$B$15*INDEX(input_data!$L:$L,MATCH("all.in.cs2.stl.scr.---",input_data!$A:$A,0))),0)+IFERROR(calculations!T77/calculations!T76*((calculations!T97+calculations!T254)*$B$11+calculations!T98*$B$12+calculations!T99*$B$13+calculations!T100*$B$14+calculations!T101*$B$15*INDEX(input_data!$L:$L,MATCH("all.in.cs2.stl.bof.---",input_data!$A:$A,0))),0)+IFERROR(calculations!T105/calculations!T104*((calculations!T125+calculations!T259)*$B$11+calculations!T126*$B$12+calculations!T127*$B$13+calculations!T128*$B$14+calculations!T129*$B$15*INDEX(input_data!$L:$L,MATCH("all.in.cs2.cmt.dry.---",input_data!$A:$A,0))),0)+IFERROR(calculations!T133/calculations!T132*((calculations!T153+calculations!T264)*$B$11+calculations!T154*$B$12+calculations!T155*$B$13+calculations!T156*$B$14+calculations!T157*$B$15*INDEX(input_data!$L:$L,MATCH("all.in.cs2.frt.amc.---",input_data!$A:$A,0))),0)+IFERROR(calculations!T161/calculations!T160*((calculations!T181+calculations!T269)*$B$11+calculations!T182*$B$12+calculations!T183*$B$13+calculations!T184*$B$14+calculations!T185*$B$15*INDEX(input_data!$L:$L,MATCH("all.in.cs2.frt.ure.---",input_data!$A:$A,0))),0)+IFERROR(calculations!T189/calculations!T188*((calculations!T209+calculations!T274)*$B$11+calculations!T210*$B$12+calculations!T211*$B$13+calculations!T212*$B$14+calculations!T213*$B$15*INDEX(input_data!$L:$L,MATCH("all.in.cs2.frt.nit.---",input_data!$A:$A,0))),0)+IFERROR(calculations!T217/calculations!T216*((calculations!T237+calculations!T279)*$B$11+calculations!T238*$B$12+calculations!T239*$B$13+calculations!T240*$B$14+calculations!T241*$B$15*INDEX(input_data!$L:$L,MATCH("all.in.cs2.alu.prp.---",input_data!$A:$A,0))),0)),0) -> 106.59872 | ... O28: =IFERROR((IFERROR(calculations!X21*calculations!X248,0)+IFERROR(calculations!X49*calculations!X253,0)+IFERROR(calculations!X77*calculations!X258,0)+IFERROR(calculations!X105*calculations!X263,0)+IFERROR(calculations!X133*calculations!X268,0)+IFERROR(calculations!X161*calculations!X273,0)+IFERROR(calculations!X189*calculations!X278,0)+IFERROR(calculations!X217*calculations!X283,0))/(IFERROR(calculations!X21/calculations!X20*((calculations!X41+calculations!X244)*$B$11+calculations!X42*$B$12+calculations!X43*$B$13+calculations!X44*$B$14+calculations!X45*$B$15*INDEX(input_data!$L:$L,MATCH("all.in.cs2.stl.drg.---",input_data!$A:$A,0))),0)+IFERROR(calculations!X49/calculations!X48*((calculations!X69+calculations!X249)*$B$11+calculations!X70*$B$12+calculations!X71*$B$13+calculations!X72*$B$14+calculations!X73*$B$15*INDEX(input_data!$L:$L,MATCH("all.in.cs2.stl.scr.---",input_data!$A:$A,0))),0)+IFERROR(calculations!X77/calculations!X76*((calculations!X97+calculations!X254)*$B$11+calculations!X98*$B$12+calculations!X99*$B$13+calculations!X100*$B$14+calculations!X101*$B$15*INDEX(input_data!$L:$L,MATCH("all.in.cs2.stl.bof.---",input_data!$A:$A,0))),0)+IFERROR(calculations!X105/calculations!X104*((calculations!X125+calculations!X259)*$B$11+calculations!X126*$B$12+calculations!X127*$B$13+calculations!X128*$B$14+calculations!X129*$B$15*INDEX(input_data!$L:$L,MATCH("all.in.cs2.cmt.dry.---",input_data!$A:$A,0))),0)+IFERROR(calculations!X133/calculations!X132*((calculations!X153+calculations!X264)*$B$11+calculations!X154*$B$12+calculations!X155*$B$13+calculations!X156*$B$14+calculations!X157*$B$15*INDEX(input_data!$L:$L,MATCH("all.in.cs2.frt.amc.---",input_data!$A:$A,0))),0)+IFERROR(calculations!X161/calculations!X160*((calculations!X181+calculations!X269)*$B$11+calculations!X182*$B$12+calculations!X183*$B$13+calculations!X184*$B$14+calculations!X185*$B$15*INDEX(input_data!$L:$L,MATCH("all.in.cs2.frt.ure.---",input_data!$A:$A,0))),0)+IFERROR(calculations!X189/calculations!X188*((calculations!X209+calculations!X274)*$B$11+calculations!X210*$B$12+calculations!X211*$B$13+calculations!X212*$B$14+calculations!X213*$B$15*INDEX(input_data!$L:$L,MATCH("all.in.cs2.frt.nit.---",input_data!$A:$A,0))),0)+IFERROR(calculations!X217/calculations!X216*((calculations!X237+calculations!X279)*$B$11+calculations!X238*$B$12+calculations!X239*$B$13+calculations!X240*$B$14+calculations!X241*$B$15*INDEX(input_data!$L:$L,MATCH("all.in.cs2.alu.prp.---",input_data!$A:$A,0))),0)),0) -> 154
A29: ↓ DOMESTIC CARBON PRICE (editable, default = optimal) | B29: USD/tCO2 | D29: =D28 -> 0 | E29: =E28 -> 0 | F29: =F28 -> 58.95271 | G29: =G28 -> 63.24289 | H29: =H28 -> 68.910911 | I29: =I28 -> 75.316603 | J29: =J28 -> 94.247266 | K29: =K28 -> 106.59872 | ... O29: =O28 -> 154
A31: 4. HEADLINE REVENUES (USD millions)
A32: row | B32: unit | D32: 2024 | E32: 2025 | F32: 2026 | G32: 2027 | H32: 2028 | I32: 2029 | J32: 2030 | K32: 2031 | L32: 2032 | M32: 2033 | N32: 2034 | O32: 2035
A33: EU CBAM obligation gross | B33: USD m | D33: =IFERROR(calculations!M21*calculations!M248,0)+IFERROR(calculations!M49*calculations!M253,0)+IFERROR(calculations!M77*calculations!M258,0)+IFERROR(calculations!M105*calculations!M263,0)+IFERROR(calculations!M133*calculations!M268,0)+IFERROR(calculations!M161*calculations!M273,0)+IFERROR(calculations!M189*calculations!M278,0)+IFERROR(calculations!M217*calculations!M283,0) -> 0 | E33: =IFERROR(calculations!N21*calculations!N248,0)+IFERROR(calculations!N49*calculations!N253,0)+IFERROR(calculations!N77*calculations!N258,0)+IFERROR(calculations!N105*calculations!N263,0)+IFERROR(calculations!N133*calculations!N268,0)+IFERROR(calculations!N161*calculations!N273,0)+IFERROR(calculations!N189*calculations!N278,0)+IFERROR(calculations!N217*calculations!N283,0) -> 0 | F33: =IFERROR(calculations!O21*calculations!O248,0)+IFERROR(calculations!O49*calculations!O253,0)+IFERROR(calculations!O77*calculations!O258,0)+IFERROR(calculations!O105*calculations!O263,0)+IFERROR(calculations!O133*calculations!O268,0)+IFERROR(calculations!O161*calculations!O273,0)+IFERROR(calculations!O189*calculations!O278,0)+IFERROR(calculations!O217*calculations!O283,0) -> 197.06749 | G33: =IFERROR(calculations!P21*calculations!P248,0)+IFERROR(calculations!P49*calculations!P253,0)+IFERROR(calculations!P77*calculations!P258,0)+IFERROR(calculations!P105*calculations!P263,0)+IFERROR(calculations!P133*calculations!P268,0)+IFERROR(calculations!P161*calculations!P273,0)+IFERROR(calculations!P189*calculations!P278,0)+IFERROR(calculations!P217*calculations!P283,0) -> 220.85903 | H33: =IFERROR(calculations!Q21*calculations!Q248,0)+IFERROR(calculations!Q49*calculations!Q253,0)+IFERROR(calculations!Q77*calculations!Q258,0)+IFERROR(calculations!Q105*calculations!Q263,0)+IFERROR(calculations!Q133*calculations!Q268,0)+IFERROR(calculations!Q161*calculations!Q273,0)+IFERROR(calculations!Q189*calculations!Q278,0)+IFERROR(calculations!Q217*calculations!Q283,0) -> 251.4489 | I33: =IFERROR(calculations!R21*calculations!R248,0)+IFERROR(calculations!R49*calculations!R253,0)+IFERROR(calculations!R77*calculations!R258,0)+IFERROR(calculations!R105*calculations!R263,0)+IFERROR(calculations!R133*calculations!R268,0)+IFERROR(calculations!R161*calculations!R273,0)+IFERROR(calculations!R189*calculations!R278,0)+IFERROR(calculations!R217*calculations!R283,0) -> 287.19454 | J33: =IFERROR(calculations!S21*calculations!S248,0)+IFERROR(calculations!S49*calculations!S253,0)+IFERROR(calculations!S77*calculations!S258,0)+IFERROR(calculations!S105*calculations!S263,0)+IFERROR(calculations!S133*calculations!S268,0)+IFERROR(calculations!S161*calculations!S273,0)+IFERROR(calculations!S189*calculations!S278,0)+IFERROR(calculations!S217*calculations!S283,0) -> 375.61474 | K33: =IFERROR(calculations!T21*calculations!T248,0)+IFERROR(calculations!T49*calculations!T253,0)+IFERROR(calculations!T77*calculations!T258,0)+IFERROR(calculations!T105*calculations!T263,0)+IFERROR(calculations!T133*calculations!T268,0)+IFERROR(calculations!T161*calculations!T273,0)+IFERROR(calculations!T189*calculations!T278,0)+IFERROR(calculations!T217*calculations!T283,0) -> 444.09747 | ... O33: =IFERROR(calculations!X21*calculations!X248,0)+IFERROR(calculations!X49*calculations!X253,0)+IFERROR(calculations!X77*calculations!X258,0)+IFERROR(calculations!X105*calculations!X263,0)+IFERROR(calculations!X133*calculations!X268,0)+IFERROR(calculations!X161*calculations!X273,0)+IFERROR(calculations!X189*calculations!X278,0)+IFERROR(calculations!X217*calculations!X283,0) -> 767.15512
A34: ● Country revenue on EU exports (total covered) | B34: USD m | D34: =IFERROR((calculations!M21/calculations!M20)*((calculations!M41+calculations!M244)*$B$11+calculations!M42*$B$12+calculations!M43*$B$13+calculations!M44*$B$14+calculations!M45*$B$15)*D29,0)+IFERROR((calculations!M49/calculations!M48)*((calculations!M69+calculations!M249)*$B$11+calculations!M70*$B$12+calculations!M71*$B$13+calculations!M72*$B$14+calculations!M73*$B$15)*D29,0)+IFERROR((calculations!M77/calculations!M76)*((calculations!M97+calculations!M254)*$B$11+calculations!M98*$B$12+calculations!M99*$B$13+calculations!M100*$B$14+calculations!M101*$B$15)*D29,0)+IFERROR((calculations!M105/calculations!M104)*((calculations!M125+calculations!M259)*$B$11+calculations!M126*$B$12+calculations!M127*$B$13+calculations!M128*$B$14+calculations!M129*$B$15)*D29,0)+IFERROR((calculations!M133/calculations!M132)*((calculations!M153+calculations!M264)*$B$11+calculations!M154*$B$12+calculations!M155*$B$13+calculations!M156*$B$14+calculations!M157*$B$15)*D29,0)+IFERROR((calculations!M161/calculations!M160)*((calculations!M181+calculations!M269)*$B$11+calculations!M182*$B$12+calculations!M183*$B$13+calculations!M184*$B$14+calculations!M185*$B$15)*D29,0)+IFERROR((calculations!M189/calculations!M188)*((calculations!M209+calculations!M274)*$B$11+calculations!M210*$B$12+calculations!M211*$B$13+calculations!M212*$B$14+calculations!M213*$B$15)*D29,0)+IFERROR((calculations!M217/calculations!M216)*((calculations!M237+calculations!M279)*$B$11+calculations!M238*$B$12+calculations!M239*$B$13+calculations!M240*$B$14+calculations!M241*$B$15)*D29,0) -> 0 | E34: =IFERROR((calculations!N21/calculations!N20)*((calculations!N41+calculations!N244)*$B$11+calculations!N42*$B$12+calculations!N43*$B$13+calculations!N44*$B$14+calculations!N45*$B$15)*E29,0)+IFERROR((calculations!N49/calculations!N48)*((calculations!N69+calculations!N249)*$B$11+calculations!N70*$B$12+calculations!N71*$B$13+calculations!N72*$B$14+calculations!N73*$B$15)*E29,0)+IFERROR((calculations!N77/calculations!N76)*((calculations!N97+calculations!N254)*$B$11+calculations!N98*$B$12+calculations!N99*$B$13+calculations!N100*$B$14+calculations!N101*$B$15)*E29,0)+IFERROR((calculations!N105/calculations!N104)*((calculations!N125+calculations!N259)*$B$11+calculations!N126*$B$12+calculations!N127*$B$13+calculations!N128*$B$14+calculations!N129*$B$15)*E29,0)+IFERROR((calculations!N133/calculations!N132)*((calculations!N153+calculations!N264)*$B$11+calculations!N154*$B$12+calculations!N155*$B$13+calculations!N156*$B$14+calculations!N157*$B$15)*E29,0)+IFERROR((calculations!N161/calculations!N160)*((calculations!N181+calculations!N269)*$B$11+calculations!N182*$B$12+calculations!N183*$B$13+calculations!N184*$B$14+calculations!N185*$B$15)*E29,0)+IFERROR((calculations!N189/calculations!N188)*((calculations!N209+calculations!N274)*$B$11+calculations!N210*$B$12+calculations!N211*$B$13+calculations!N212*$B$14+calculations!N213*$B$15)*E29,0)+IFERROR((calculations!N217/calculations!N216)*((calculations!N237+calculations!N279)*$B$11+calculations!N238*$B$12+calculations!N239*$B$13+calculations!N240*$B$14+calculations!N241*$B$15)*E29,0) -> 0 | F34: =IFERROR((calculations!O21/calculations!O20)*((calculations!O41+calculations!O244)*$B$11+calculations!O42*$B$12+calculations!O43*$B$13+calculations!O44*$B$14+calculations!O45*$B$15)*F29,0)+IFERROR((calculations!O49/calculations!O48)*((calculations!O69+calculations!O249)*$B$11+calculations!O70*$B$12+calculations!O71*$B$13+calculations!O72*$B$14+calculations!O73*$B$15)*F29,0)+IFERROR((calculations!O77/calculations!O76)*((calculations!O97+calculations!O254)*$B$11+calculations!O98*$B$12+calculations!O99*$B$13+calculations!O100*$B$14+calculations!O101*$B$15)*F29,0)+IFERROR((calculations!O105/calculations!O104)*((calculations!O125+calculations!O259)*$B$11+calculations!O126*$B$12+calculations!O127*$B$13+calculations!O128*$B$14+calculations!O129*$B$15)*F29,0)+IFERROR((calculations!O133/calculations!O132)*((calculations!O153+calculations!O264)*$B$11+calculations!O154*$B$12+calculations!O155*$B$13+calculations!O156*$B$14+calculations!O157*$B$15)*F29,0)+IFERROR((calculations!O161/calculations!O160)*((calculations!O181+calculations!O269)*$B$11+calculations!O182*$B$12+calculations!O183*$B$13+calculations!O184*$B$14+calculations!O185*$B$15)*F29,0)+IFERROR((calculations!O189/calculations!O188)*((calculations!O209+calculations!O274)*$B$11+calculations!O210*$B$12+calculations!O211*$B$13+calculations!O212*$B$14+calculations!O213*$B$15)*F29,0)+IFERROR((calculations!O217/calculations!O216)*((calculations!O237+calculations!O279)*$B$11+calculations!O238*$B$12+calculations!O239*$B$13+calculations!O240*$B$14+calculations!O241*$B$15)*F29,0) -> 259.30987 | G34: =IFERROR((calculations!P21/calculations!P20)*((calculations!P41+calculations!P244)*$B$11+calculations!P42*$B$12+calculations!P43*$B$13+calculations!P44*$B$14+calculations!P45*$B$15)*G29,0)+IFERROR((calculations!P49/calculations!P48)*((calculations!P69+calculations!P249)*$B$11+calculations!P70*$B$12+calculations!P71*$B$13+calculations!P72*$B$14+calculations!P73*$B$15)*G29,0)+IFERROR((calculations!P77/calculations!P76)*((calculations!P97+calculations!P254)*$B$11+calculations!P98*$B$12+calculations!P99*$B$13+calculations!P100*$B$14+calculations!P101*$B$15)*G29,0)+IFERROR((calculations!P105/calculations!P104)*((calculations!P125+calculations!P259)*$B$11+calculations!P126*$B$12+calculations!P127*$B$13+calculations!P128*$B$14+calculations!P129*$B$15)*G29,0)+IFERROR((calculations!P133/calculations!P132)*((calculations!P153+calculations!P264)*$B$11+calculations!P154*$B$12+calculations!P155*$B$13+calculations!P156*$B$14+calculations!P157*$B$15)*G29,0)+IFERROR((calculations!P161/calculations!P160)*((calculations!P181+calculations!P269)*$B$11+calculations!P182*$B$12+calculations!P183*$B$13+calculations!P184*$B$14+calculations!P185*$B$15)*G29,0)+IFERROR((calculations!P189/calculations!P188)*((calculations!P209+calculations!P274)*$B$11+calculations!P210*$B$12+calculations!P211*$B$13+calculations!P212*$B$14+calculations!P213*$B$15)*G29,0)+IFERROR((calculations!P217/calculations!P216)*((calculations!P237+calculations!P279)*$B$11+calculations!P238*$B$12+calculations!P239*$B$13+calculations!P240*$B$14+calculations!P241*$B$15)*G29,0) -> 289.37285 | H34: =IFERROR((calculations!Q21/calculations!Q20)*((calculations!Q41+calculations!Q244)*$B$11+calculations!Q42*$B$12+calculations!Q43*$B$13+calculations!Q44*$B$14+calculations!Q45*$B$15)*H29,0)+IFERROR((calculations!Q49/calculations!Q48)*((calculations!Q69+calculations!Q249)*$B$11+calculations!Q70*$B$12+calculations!Q71*$B$13+calculations!Q72*$B$14+calculations!Q73*$B$15)*H29,0)+IFERROR((calculations!Q77/calculations!Q76)*((calculations!Q97+calculations!Q254)*$B$11+calculations!Q98*$B$12+calculations!Q99*$B$13+calculations!Q100*$B$14+calculations!Q101*$B$15)*H29,0)+IFERROR((calculations!Q105/calculations!Q104)*((calculations!Q125+calculations!Q259)*$B$11+calculations!Q126*$B$12+calculations!Q127*$B$13+calculations!Q128*$B$14+calculations!Q129*$B$15)*H29,0)+IFERROR((calculations!Q133/calculations!Q132)*((calculations!Q153+calculations!Q264)*$B$11+calculations!Q154*$B$12+calculations!Q155*$B$13+calculations!Q156*$B$14+calculations!Q157*$B$15)*H29,0)+IFERROR((calculations!Q161/calculations!Q160)*((calculations!Q181+calculations!Q269)*$B$11+calculations!Q182*$B$12+calculations!Q183*$B$13+calculations!Q184*$B$14+calculations!Q185*$B$15)*H29,0)+IFERROR((calculations!Q189/calculations!Q188)*((calculations!Q209+calculations!Q274)*$B$11+calculations!Q210*$B$12+calculations!Q211*$B$13+calculations!Q212*$B$14+calculations!Q213*$B$15)*H29,0)+IFERROR((calculations!Q217/calculations!Q216)*((calculations!Q237+calculations!Q279)*$B$11+calculations!Q238*$B$12+calculations!Q239*$B$13+calculations!Q240*$B$14+calculations!Q241*$B$15)*H29,0) -> 328.01933 | I34: =IFERROR((calculations!R21/calculations!R20)*((calculations!R41+calculations!R244)*$B$11+calculations!R42*$B$12+calculations!R43*$B$13+calculations!R44*$B$14+calculations!R45*$B$15)*I29,0)+IFERROR((calculations!R49/calculations!R48)*((calculations!R69+calculations!R249)*$B$11+calculations!R70*$B$12+calculations!R71*$B$13+calculations!R72*$B$14+calculations!R73*$B$15)*I29,0)+IFERROR((calculations!R77/calculations!R76)*((calculations!R97+calculations!R254)*$B$11+calculations!R98*$B$12+calculations!R99*$B$13+calculations!R100*$B$14+calculations!R101*$B$15)*I29,0)+IFERROR((calculations!R105/calculations!R104)*((calculations!R125+calculations!R259)*$B$11+calculations!R126*$B$12+calculations!R127*$B$13+calculations!R128*$B$14+calculations!R129*$B$15)*I29,0)+IFERROR((calculations!R133/calculations!R132)*((calculations!R153+calculations!R264)*$B$11+calculations!R154*$B$12+calculations!R155*$B$13+calculations!R156*$B$14+calculations!R157*$B$15)*I29,0)+IFERROR((calculations!R161/calculations!R160)*((calculations!R181+calculations!R269)*$B$11+calculations!R182*$B$12+calculations!R183*$B$13+calculations!R184*$B$14+calculations!R185*$B$15)*I29,0)+IFERROR((calculations!R189/calculations!R188)*((calculations!R209+calculations!R274)*$B$11+calculations!R210*$B$12+calculations!R211*$B$13+calculations!R212*$B$14+calculations!R213*$B$15)*I29,0)+IFERROR((calculations!R217/calculations!R216)*((calculations!R237+calculations!R279)*$B$11+calculations!R238*$B$12+calculations!R239*$B$13+calculations!R240*$B$14+calculations!R241*$B$15)*I29,0) -> 372.99404 | J34: =IFERROR((calculations!S21/calculations!S20)*((calculations!S41+calculations!S244)*$B$11+calculations!S42*$B$12+calculations!S43*$B$13+calculations!S44*$B$14+calculations!S45*$B$15)*J29,0)+IFERROR((calculations!S49/calculations!S48)*((calculations!S69+calculations!S249)*$B$11+calculations!S70*$B$12+calculations!S71*$B$13+calculations!S72*$B$14+calculations!S73*$B$15)*J29,0)+IFERROR((calculations!S77/calculations!S76)*((calculations!S97+calculations!S254)*$B$11+calculations!S98*$B$12+calculations!S99*$B$13+calculations!S100*$B$14+calculations!S101*$B$15)*J29,0)+IFERROR((calculations!S105/calculations!S104)*((calculations!S125+calculations!S259)*$B$11+calculations!S126*$B$12+calculations!S127*$B$13+calculations!S128*$B$14+calculations!S129*$B$15)*J29,0)+IFERROR((calculations!S133/calculations!S132)*((calculations!S153+calculations!S264)*$B$11+calculations!S154*$B$12+calculations!S155*$B$13+calculations!S156*$B$14+calculations!S157*$B$15)*J29,0)+IFERROR((calculations!S161/calculations!S160)*((calculations!S181+calculations!S269)*$B$11+calculations!S182*$B$12+calculations!S183*$B$13+calculations!S184*$B$14+calculations!S185*$B$15)*J29,0)+IFERROR((calculations!S189/calculations!S188)*((calculations!S209+calculations!S274)*$B$11+calculations!S210*$B$12+calculations!S211*$B$13+calculations!S212*$B$14+calculations!S213*$B$15)*J29,0)+IFERROR((calculations!S217/calculations!S216)*((calculations!S237+calculations!S279)*$B$11+calculations!S238*$B$12+calculations!S239*$B$13+calculations!S240*$B$14+calculations!S241*$B$15)*J29,0) -> 485.6393 | K34: =IFERROR((calculations!T21/calculations!T20)*((calculations!T41+calculations!T244)*$B$11+calculations!T42*$B$12+calculations!T43*$B$13+calculations!T44*$B$14+calculations!T45*$B$15)*K29,0)+IFERROR((calculations!T49/calculations!T48)*((calculations!T69+calculations!T249)*$B$11+calculations!T70*$B$12+calculations!T71*$B$13+calculations!T72*$B$14+calculations!T73*$B$15)*K29,0)+IFERROR((calculations!T77/calculations!T76)*((calculations!T97+calculations!T254)*$B$11+calculations!T98*$B$12+calculations!T99*$B$13+calculations!T100*$B$14+calculations!T101*$B$15)*K29,0)+IFERROR((calculations!T105/calculations!T104)*((calculations!T125+calculations!T259)*$B$11+calculations!T126*$B$12+calculations!T127*$B$13+calculations!T128*$B$14+calculations!T129*$B$15)*K29,0)+IFERROR((calculations!T133/calculations!T132)*((calculations!T153+calculations!T264)*$B$11+calculations!T154*$B$12+calculations!T155*$B$13+calculations!T156*$B$14+calculations!T157*$B$15)*K29,0)+IFERROR((calculations!T161/calculations!T160)*((calculations!T181+calculations!T269)*$B$11+calculations!T182*$B$12+calculations!T183*$B$13+calculations!T184*$B$14+calculations!T185*$B$15)*K29,0)+IFERROR((calculations!T189/calculations!T188)*((calculations!T209+calculations!T274)*$B$11+calculations!T210*$B$12+calculations!T211*$B$13+calculations!T212*$B$14+calculations!T213*$B$15)*K29,0)+IFERROR((calculations!T217/calculations!T216)*((calculations!T237+calculations!T279)*$B$11+calculations!T238*$B$12+calculations!T239*$B$13+calculations!T240*$B$14+calculations!T241*$B$15)*K29,0) -> 571.56404 | ... O34: =IFERROR((calculations!X21/calculations!X20)*((calculations!X41+calculations!X244)*$B$11+calculations!X42*$B$12+calculations!X43*$B$13+calculations!X44*$B$14+calculations!X45*$B$15)*O29,0)+IFERROR((calculations!X49/calculations!X48)*((calculations!X69+calculations!X249)*$B$11+calculations!X70*$B$12+calculations!X71*$B$13+calculations!X72*$B$14+calculations!X73*$B$15)*O29,0)+IFERROR((calculations!X77/calculations!X76)*((calculations!X97+calculations!X254)*$B$11+calculations!X98*$B$12+calculations!X99*$B$13+calculations!X100*$B$14+calculations!X101*$B$15)*O29,0)+IFERROR((calculations!X105/calculations!X104)*((calculations!X125+calculations!X259)*$B$11+calculations!X126*$B$12+calculations!X127*$B$13+calculations!X128*$B$14+calculations!X129*$B$15)*O29,0)+IFERROR((calculations!X133/calculations!X132)*((calculations!X153+calculations!X264)*$B$11+calculations!X154*$B$12+calculations!X155*$B$13+calculations!X156*$B$14+calculations!X157*$B$15)*O29,0)+IFERROR((calculations!X161/calculations!X160)*((calculations!X181+calculations!X269)*$B$11+calculations!X182*$B$12+calculations!X183*$B$13+calculations!X184*$B$14+calculations!X185*$B$15)*O29,0)+IFERROR((calculations!X189/calculations!X188)*((calculations!X209+calculations!X274)*$B$11+calculations!X210*$B$12+calculations!X211*$B$13+calculations!X212*$B$14+calculations!X213*$B$15)*O29,0)+IFERROR((calculations!X217/calculations!X216)*((calculations!X237+calculations!X279)*$B$11+calculations!X238*$B$12+calculations!X239*$B$13+calculations!X240*$B$14+calculations!X241*$B$15)*O29,0) -> 968.81424
