Workbook

Sheet Dashboard
A1: CES Energy Demand Model with TECP
A2: Unified policy interface: same inputs drive both dynamic simulation and TECP
A4: POLICY INSTRUMENTS | D4: (Zero)
B5: Level | C5: Unit | D5: Intro year | E5: Target year
A6: Economy-wide carbon tax | B6: 50 | C6: $/tCO2 | D6: 2025 | E6: 2028
A7: Road Transport feebate | B7: 20 | C7: $/tCO2 | D7: 2026 | E7: 2030
A8: Electricity Gen. feebate | B8: 15 | C8: $/tCO2 | D8: 2026 | E8: 2030
A10: FUEL EXCISES ($/GJ) — by sector | D10: (Zero)
A11: Fuel | B11: RT excise ($/GJ) | C11: EG excise ($/GJ) | D11: Intro year | E11: Target year
A12: Coal | B12: 0 | C12: 0 | D12: 2025 | E12: 2028
A13: Natural gas | B13: 0 | C13: 0 | D13: 2025 | E13: 2028
A14: Gasoline | B14: 5 | C14: 0 | D14: 2025 | E14: 2028
A15: Diesel | B15: 4 | C15: 0 | D15: 2025 | E15: 2028
A16: Electricity | B16: 0 | C16: 0 | D16: 2025 | E16: 2028
A17: RE generation | B17: 0 | C17: 0 | D17: 2025 | E17: 2028
A19: COMPUTED POLICY TRAJECTORIES
B20: 2024 | C20: 2025 | D20: 2026 | E20: 2027 | F20: 2028 | G20: 2029 | H20: 2030 | I20: 2031 | J20: 2032 | K20: 2033 | L20: 2034 | M20: 2035
A21: Carbon tax ($/tCO2) | B21: =IF(2024<=$D$6,0,IF(2024>=$E$6,$B$6,$B$6*(2024-$D$6)/($E$6-$D$6))) -> 0 | C21: =IF(2025<=$D$6,0,IF(2025>=$E$6,$B$6,$B$6*(2025-$D$6)/($E$6-$D$6))) -> 0 | D21: =IF(2026<=$D$6,0,IF(2026>=$E$6,$B$6,$B$6*(2026-$D$6)/($E$6-$D$6))) -> 16.666667 | E21: =IF(2027<=$D$6,0,IF(2027>=$E$6,$B$6,$B$6*(2027-$D$6)/($E$6-$D$6))) -> 33.333333 | F21: =IF(2028<=$D$6,0,IF(2028>=$E$6,$B$6,$B$6*(2028-$D$6)/($E$6-$D$6))) -> 50 | G21: =IF(2029<=$D$6,0,IF(2029>=$E$6,$B$6,$B$6*(2029-$D$6)/($E$6-$D$6))) -> 50 | H21: =IF(2030<=$D$6,0,IF(2030>=$E$6,$B$6,$B$6*(2030-$D$6)/($E$6-$D$6))) -> 50 | I21: =IF(2031<=$D$6,0,IF(2031>=$E$6,$B$6,$B$6*(2031-$D$6)/($E$6-$D$6))) -> 50 | J21: =IF(2032<=$D$6,0,IF(2032>=$E$6,$B$6,$B$6*(2032-$D$6)/($E$6-$D$6))) -> 50 | K21: =IF(2033<=$D$6,0,IF(2033>=$E$6,$B$6,$B$6*(2033-$D$6)/($E$6-$D$6))) -> 50 | L21: =IF(2034<=$D$6,0,IF(2034>=$E$6,$B$6,$B$6*(2034-$D$6)/($E$6-$D$6))) -> 50 | M21: =IF(2035<=$D$6,0,IF(2035>=$E$6,$B$6,$B$6*(2035-$D$6)/($E$6-$D$6))) -> 50
A22: RT feebate ($/tCO2) | B22: =IF(2024<=$D$7,0,IF(2024>=$E$7,$B$7,$B$7*(2024-$D$7)/($E$7-$D$7))) -> 0 | C22: =IF(2025<=$D$7,0,IF(2025>=$E$7,$B$7,$B$7*(2025-$D$7)/($E$7-$D$7))) -> 0 | D22: =IF(2026<=$D$7,0,IF(2026>=$E$7,$B$7,$B$7*(2026-$D$7)/($E$7-$D$7))) -> 0 | E22: =IF(2027<=$D$7,0,IF(2027>=$E$7,$B$7,$B$7*(2027-$D$7)/($E$7-$D$7))) -> 5 | F22: =IF(2028<=$D$7,0,IF(2028>=$E$7,$B$7,$B$7*(2028-$D$7)/($E$7-$D$7))) -> 10 | G22: =IF(2029<=$D$7,0,IF(2029>=$E$7,$B$7,$B$7*(2029-$D$7)/($E$7-$D$7))) -> 15 | H22: =IF(2030<=$D$7,0,IF(2030>=$E$7,$B$7,$B$7*(2030-$D$7)/($E$7-$D$7))) -> 20 | I22: =IF(2031<=$D$7,0,IF(2031>=$E$7,$B$7,$B$7*(2031-$D$7)/($E$7-$D$7))) -> 20 | J22: =IF(2032<=$D$7,0,IF(2032>=$E$7,$B$7,$B$7*(2032-$D$7)/($E$7-$D$7))) -> 20 | K22: =IF(2033<=$D$7,0,IF(2033>=$E$7,$B$7,$B$7*(2033-$D$7)/($E$7-$D$7))) -> 20 | L22: =IF(2034<=$D$7,0,IF(2034>=$E$7,$B$7,$B$7*(2034-$D$7)/($E$7-$D$7))) -> 20 | M22: =IF(2035<=$D$7,0,IF(2035>=$E$7,$B$7,$B$7*(2035-$D$7)/($E$7-$D$7))) -> 20
A23: EG feebate ($/tCO2) | B23: =IF(2024<=$D$8,0,IF(2024>=$E$8,$B$8,$B$8*(2024-$D$8)/($E$8-$D$8))) -> 0 | C23: =IF(2025<=$D$8,0,IF(2025>=$E$8,$B$8,$B$8*(2025-$D$8)/($E$8-$D$8))) -> 0 | D23: =IF(2026<=$D$8,0,IF(2026>=$E$8,$B$8,$B$8*(2026-$D$8)/($E$8-$D$8))) -> 0 | E23: =IF(2027<=$D$8,0,IF(2027>=$E$8,$B$8,$B$8*(2027-$D$8)/($E$8-$D$8))) -> 3.75 | F23: =IF(2028<=$D$8,0,IF(2028>=$E$8,$B$8,$B$8*(2028-$D$8)/($E$8-$D$8))) -> 7.5 | G23: =IF(2029<=$D$8,0,IF(2029>=$E$8,$B$8,$B$8*(2029-$D$8)/($E$8-$D$8))) -> 11.25 | H23: =IF(2030<=$D$8,0,IF(2030>=$E$8,$B$8,$B$8*(2030-$D$8)/($E$8-$D$8))) -> 15 | I23: =IF(2031<=$D$8,0,IF(2031>=$E$8,$B$8,$B$8*(2031-$D$8)/($E$8-$D$8))) -> 15 | J23: =IF(2032<=$D$8,0,IF(2032>=$E$8,$B$8,$B$8*(2032-$D$8)/($E$8-$D$8))) -> 15 | K23: =IF(2033<=$D$8,0,IF(2033>=$E$8,$B$8,$B$8*(2033-$D$8)/($E$8-$D$8))) -> 15 | L23: =IF(2034<=$D$8,0,IF(2034>=$E$8,$B$8,$B$8*(2034-$D$8)/($E$8-$D$8))) -> 15 | M23: =IF(2035<=$D$8,0,IF(2035>=$E$8,$B$8,$B$8*(2035-$D$8)/($E$8-$D$8))) -> 15
A24: RT excises ($/GJ) by fuel:
A25: Coal | B25: =IF(2024<=$D$12,0,IF(2024>=$E$12,$B$12,$B$12*(2024-$D$12)/($E$12-$D$12))) -> 0 | C25: =IF(2025<=$D$12,0,IF(2025>=$E$12,$B$12,$B$12*(2025-$D$12)/($E$12-$D$12))) -> 0 | D25: =IF(2026<=$D$12,0,IF(2026>=$E$12,$B$12,$B$12*(2026-$D$12)/($E$12-$D$12))) -> 0 | E25: =IF(2027<=$D$12,0,IF(2027>=$E$12,$B$12,$B$12*(2027-$D$12)/($E$12-$D$12))) -> 0 | F25: =IF(2028<=$D$12,0,IF(2028>=$E$12,$B$12,$B$12*(2028-$D$12)/($E$12-$D$12))) -> 0 | G25: =IF(2029<=$D$12,0,IF(2029>=$E$12,$B$12,$B$12*(2029-$D$12)/($E$12-$D$12))) -> 0 | H25: =IF(2030<=$D$12,0,IF(2030>=$E$12,$B$12,$B$12*(2030-$D$12)/($E$12-$D$12))) -> 0 | I25: =IF(2031<=$D$12,0,IF(2031>=$E$12,$B$12,$B$12*(2031-$D$12)/($E$12-$D$12))) -> 0 | J25: =IF(2032<=$D$12,0,IF(2032>=$E$12,$B$12,$B$12*(2032-$D$12)/($E$12-$D$12))) -> 0 | K25: =IF(2033<=$D$12,0,IF(2033>=$E$12,$B$12,$B$12*(2033-$D$12)/($E$12-$D$12))) -> 0 | L25: =IF(2034<=$D$12,0,IF(2034>=$E$12,$B$12,$B$12*(2034-$D$12)/($E$12-$D$12))) -> 0 | M25: =IF(2035<=$D$12,0,IF(2035>=$E$12,$B$12,$B$12*(2035-$D$12)/($E$12-$D$12))) -> 0
A26: Natural gas | B26: =IF(2024<=$D$13,0,IF(2024>=$E$13,$B$13,$B$13*(2024-$D$13)/($E$13-$D$13))) -> 0 | C26: =IF(2025<=$D$13,0,IF(2025>=$E$13,$B$13,$B$13*(2025-$D$13)/($E$13-$D$13))) -> 0 | D26: =IF(2026<=$D$13,0,IF(2026>=$E$13,$B$13,$B$13*(2026-$D$13)/($E$13-$D$13))) -> 0 | E26: =IF(2027<=$D$13,0,IF(2027>=$E$13,$B$13,$B$13*(2027-$D$13)/($E$13-$D$13))) -> 0 | F26: =IF(2028<=$D$13,0,IF(2028>=$E$13,$B$13,$B$13*(2028-$D$13)/($E$13-$D$13))) -> 0 | G26: =IF(2029<=$D$13,0,IF(2029>=$E$13,$B$13,$B$13*(2029-$D$13)/($E$13-$D$13))) -> 0 | H26: =IF(2030<=$D$13,0,IF(2030>=$E$13,$B$13,$B$13*(2030-$D$13)/($E$13-$D$13))) -> 0 | I26: =IF(2031<=$D$13,0,IF(2031>=$E$13,$B$13,$B$13*(2031-$D$13)/($E$13-$D$13))) -> 0 | J26: =IF(2032<=$D$13,0,IF(2032>=$E$13,$B$13,$B$13*(2032-$D$13)/($E$13-$D$13))) -> 0 | K26: =IF(2033<=$D$13,0,IF(2033>=$E$13,$B$13,$B$13*(2033-$D$13)/($E$13-$D$13))) -> 0 | L26: =IF(2034<=$D$13,0,IF(2034>=$E$13,$B$13,$B$13*(2034-$D$13)/($E$13-$D$13))) -> 0 | M26: =IF(2035<=$D$13,0,IF(2035>=$E$13,$B$13,$B$13*(2035-$D$13)/($E$13-$D$13))) -> 0
A27: Gasoline | B27: =IF(2024<=$D$14,0,IF(2024>=$E$14,$B$14,$B$14*(2024-$D$14)/($E$14-$D$14))) -> 0 | C27: =IF(2025<=$D$14,0,IF(2025>=$E$14,$B$14,$B$14*(2025-$D$14)/($E$14-$D$14))) -> 0 | D27: =IF(2026<=$D$14,0,IF(2026>=$E$14,$B$14,$B$14*(2026-$D$14)/($E$14-$D$14))) -> 1.6666667 | E27: =IF(2027<=$D$14,0,IF(2027>=$E$14,$B$14,$B$14*(2027-$D$14)/($E$14-$D$14))) -> 3.3333333 | F27: =IF(2028<=$D$14,0,IF(2028>=$E$14,$B$14,$B$14*(2028-$D$14)/($E$14-$D$14))) -> 5 | G27: =IF(2029<=$D$14,0,IF(2029>=$E$14,$B$14,$B$14*(2029-$D$14)/($E$14-$D$14))) -> 5 | H27: =IF(2030<=$D$14,0,IF(2030>=$E$14,$B$14,$B$14*(2030-$D$14)/($E$14-$D$14))) -> 5 | I27: =IF(2031<=$D$14,0,IF(2031>=$E$14,$B$14,$B$14*(2031-$D$14)/($E$14-$D$14))) -> 5 | J27: =IF(2032<=$D$14,0,IF(2032>=$E$14,$B$14,$B$14*(2032-$D$14)/($E$14-$D$14))) -> 5 | K27: =IF(2033<=$D$14,0,IF(2033>=$E$14,$B$14,$B$14*(2033-$D$14)/($E$14-$D$14))) -> 5 | L27: =IF(2034<=$D$14,0,IF(2034>=$E$14,$B$14,$B$14*(2034-$D$14)/($E$14-$D$14))) -> 5 | M27: =IF(2035<=$D$14,0,IF(2035>=$E$14,$B$14,$B$14*(2035-$D$14)/($E$14-$D$14))) -> 5
A28: Diesel | B28: =IF(2024<=$D$15,0,IF(2024>=$E$15,$B$15,$B$15*(2024-$D$15)/($E$15-$D$15))) -> 0 | C28: =IF(2025<=$D$15,0,IF(2025>=$E$15,$B$15,$B$15*(2025-$D$15)/($E$15-$D$15))) -> 0 | D28: =IF(2026<=$D$15,0,IF(2026>=$E$15,$B$15,$B$15*(2026-$D$15)/($E$15-$D$15))) -> 1.3333333 | E28: =IF(2027<=$D$15,0,IF(2027>=$E$15,$B$15,$B$15*(2027-$D$15)/($E$15-$D$15))) -> 2.6666667 | F28: =IF(2028<=$D$15,0,IF(2028>=$E$15,$B$15,$B$15*(2028-$D$15)/($E$15-$D$15))) -> 4 | G28: =IF(2029<=$D$15,0,IF(2029>=$E$15,$B$15,$B$15*(2029-$D$15)/($E$15-$D$15))) -> 4 | H28: =IF(2030<=$D$15,0,IF(2030>=$E$15,$B$15,$B$15*(2030-$D$15)/($E$15-$D$15))) -> 4 | I28: =IF(2031<=$D$15,0,IF(2031>=$E$15,$B$15,$B$15*(2031-$D$15)/($E$15-$D$15))) -> 4 | J28: =IF(2032<=$D$15,0,IF(2032>=$E$15,$B$15,$B$15*(2032-$D$15)/($E$15-$D$15))) -> 4 | K28: =IF(2033<=$D$15,0,IF(2033>=$E$15,$B$15,$B$15*(2033-$D$15)/($E$15-$D$15))) -> 4 | L28: =IF(2034<=$D$15,0,IF(2034>=$E$15,$B$15,$B$15*(2034-$D$15)/($E$15-$D$15))) -> 4 | M28: =IF(2035<=$D$15,0,IF(2035>=$E$15,$B$15,$B$15*(2035-$D$15)/($E$15-$D$15))) -> 4
A29: Electricity | B29: =IF(2024<=$D$16,0,IF(2024>=$E$16,$B$16,$B$16*(2024-$D$16)/($E$16-$D$16))) -> 0 | C29: =IF(2025<=$D$16,0,IF(2025>=$E$16,$B$16,$B$16*(2025-$D$16)/($E$16-$D$16))) -> 0 | D29: =IF(2026<=$D$16,0,IF(2026>=$E$16,$B$16,$B$16*(2026-$D$16)/($E$16-$D$16))) -> 0 | E29: =IF(2027<=$D$16,0,IF(2027>=$E$16,$B$16,$B$16*(2027-$D$16)/($E$16-$D$16))) -> 0 | F29: =IF(2028<=$D$16,0,IF(2028>=$E$16,$B$16,$B$16*(2028-$D$16)/($E$16-$D$16))) -> 0 | G29: =IF(2029<=$D$16,0,IF(2029>=$E$16,$B$16,$B$16*(2029-$D$16)/($E$16-$D$16))) -> 0 | H29: =IF(2030<=$D$16,0,IF(2030>=$E$16,$B$16,$B$16*(2030-$D$16)/($E$16-$D$16))) -> 0 | I29: =IF(2031<=$D$16,0,IF(2031>=$E$16,$B$16,$B$16*(2031-$D$16)/($E$16-$D$16))) -> 0 | J29: =IF(2032<=$D$16,0,IF(2032>=$E$16,$B$16,$B$16*(2032-$D$16)/($E$16-$D$16))) -> 0 | K29: =IF(2033<=$D$16,0,IF(2033>=$E$16,$B$16,$B$16*(2033-$D$16)/($E$16-$D$16))) -> 0 | L29: =IF(2034<=$D$16,0,IF(2034>=$E$16,$B$16,$B$16*(2034-$D$16)/($E$16-$D$16))) -> 0 | M29: =IF(2035<=$D$16,0,IF(2035>=$E$16,$B$16,$B$16*(2035-$D$16)/($E$16-$D$16))) -> 0
A30: RE generation | B30: =IF(2024<=$D$17,0,IF(2024>=$E$17,$B$17,$B$17*(2024-$D$17)/($E$17-$D$17))) -> 0 | C30: =IF(2025<=$D$17,0,IF(2025>=$E$17,$B$17,$B$17*(2025-$D$17)/($E$17-$D$17))) -> 0 | D30: =IF(2026<=$D$17,0,IF(2026>=$E$17,$B$17,$B$17*(2026-$D$17)/($E$17-$D$17))) -> 0 | E30: =IF(2027<=$D$17,0,IF(2027>=$E$17,$B$17,$B$17*(2027-$D$17)/($E$17-$D$17))) -> 0 | F30: =IF(2028<=$D$17,0,IF(2028>=$E$17,$B$17,$B$17*(2028-$D$17)/($E$17-$D$17))) -> 0 | G30: =IF(2029<=$D$17,0,IF(2029>=$E$17,$B$17,$B$17*(2029-$D$17)/($E$17-$D$17))) -> 0 | H30: =IF(2030<=$D$17,0,IF(2030>=$E$17,$B$17,$B$17*(2030-$D$17)/($E$17-$D$17))) -> 0 | I30: =IF(2031<=$D$17,0,IF(2031>=$E$17,$B$17,$B$17*(2031-$D$17)/($E$17-$D$17))) -> 0 | J30: =IF(2032<=$D$17,0,IF(2032>=$E$17,$B$17,$B$17*(2032-$D$17)/($E$17-$D$17))) -> 0 | K30: =IF(2033<=$D$17,0,IF(2033>=$E$17,$B$17,$B$17*(2033-$D$17)/($E$17-$D$17))) -> 0 | L30: =IF(2034<=$D$17,0,IF(2034>=$E$17,$B$17,$B$17*(2034-$D$17)/($E$17-$D$17))) -> 0 | M30: =IF(2035<=$D$17,0,IF(2035>=$E$17,$B$17,$B$17*(2035-$D$17)/($E$17-$D$17))) -> 0
A31: EG excises ($/GJ) by fuel:
A32: Coal | B32: =IF(2024<=$D$12,0,IF(2024>=$E$12,$C$12,$C$12*(2024-$D$12)/($E$12-$D$12))) -> 0 | C32: =IF(2025<=$D$12,0,IF(2025>=$E$12,$C$12,$C$12*(2025-$D$12)/($E$12-$D$12))) -> 0 | D32: =IF(2026<=$D$12,0,IF(2026>=$E$12,$C$12,$C$12*(2026-$D$12)/($E$12-$D$12))) -> 0 | E32: =IF(2027<=$D$12,0,IF(2027>=$E$12,$C$12,$C$12*(2027-$D$12)/($E$12-$D$12))) -> 0 | F32: =IF(2028<=$D$12,0,IF(2028>=$E$12,$C$12,$C$12*(2028-$D$12)/($E$12-$D$12))) -> 0 | G32: =IF(2029<=$D$12,0,IF(2029>=$E$12,$C$12,$C$12*(2029-$D$12)/($E$12-$D$12))) -> 0 | H32: =IF(2030<=$D$12,0,IF(2030>=$E$12,$C$12,$C$12*(2030-$D$12)/($E$12-$D$12))) -> 0 | I32: =IF(2031<=$D$12,0,IF(2031>=$E$12,$C$12,$C$12*(2031-$D$12)/($E$12-$D$12))) -> 0 | J32: =IF(2032<=$D$12,0,IF(2032>=$E$12,$C$12,$C$12*(2032-$D$12)/($E$12-$D$12))) -> 0 | K32: =IF(2033<=$D$12,0,IF(2033>=$E$12,$C$12,$C$12*(2033-$D$12)/($E$12-$D$12))) -> 0 | L32: =IF(2034<=$D$12,0,IF(2034>=$E$12,$C$12,$C$12*(2034-$D$12)/($E$12-$D$12))) -> 0 | M32: =IF(2035<=$D$12,0,IF(2035>=$E$12,$C$12,$C$12*(2035-$D$12)/($E$12-$D$12))) -> 0
A33: Natural gas | B33: =IF(2024<=$D$13,0,IF(2024>=$E$13,$C$13,$C$13*(2024-$D$13)/($E$13-$D$13))) -> 0 | C33: =IF(2025<=$D$13,0,IF(2025>=$E$13,$C$13,$C$13*(2025-$D$13)/($E$13-$D$13))) -> 0 | D33: =IF(2026<=$D$13,0,IF(2026>=$E$13,$C$13,$C$13*(2026-$D$13)/($E$13-$D$13))) -> 0 | E33: =IF(2027<=$D$13,0,IF(2027>=$E$13,$C$13,$C$13*(2027-$D$13)/($E$13-$D$13))) -> 0 | F33: =IF(2028<=$D$13,0,IF(2028>=$E$13,$C$13,$C$13*(2028-$D$13)/($E$13-$D$13))) -> 0 | G33: =IF(2029<=$D$13,0,IF(2029>=$E$13,$C$13,$C$13*(2029-$D$13)/($E$13-$D$13))) -> 0 | H33: =IF(2030<=$D$13,0,IF(2030>=$E$13,$C$13,$C$13*(2030-$D$13)/($E$13-$D$13))) -> 0 | I33: =IF(2031<=$D$13,0,IF(2031>=$E$13,$C$13,$C$13*(2031-$D$13)/($E$13-$D$13))) -> 0 | J33: =IF(2032<=$D$13,0,IF(2032>=$E$13,$C$13,$C$13*(2032-$D$13)/($E$13-$D$13))) -> 0 | K33: =IF(2033<=$D$13,0,IF(2033>=$E$13,$C$13,$C$13*(2033-$D$13)/($E$13-$D$13))) -> 0 | L33: =IF(2034<=$D$13,0,IF(2034>=$E$13,$C$13,$C$13*(2034-$D$13)/($E$13-$D$13))) -> 0 | M33: =IF(2035<=$D$13,0,IF(2035>=$E$13,$C$13,$C$13*(2035-$D$13)/($E$13-$D$13))) -> 0
A34: Gasoline | B34: =IF(2024<=$D$14,0,IF(2024>=$E$14,$C$14,$C$14*(2024-$D$14)/($E$14-$D$14))) -> 0 | C34: =IF(2025<=$D$14,0,IF(2025>=$E$14,$C$14,$C$14*(2025-$D$14)/($E$14-$D$14))) -> 0 | D34: =IF(2026<=$D$14,0,IF(2026>=$E$14,$C$14,$C$14*(2026-$D$14)/($E$14-$D$14))) -> 0 | E34: =IF(2027<=$D$14,0,IF(2027>=$E$14,$C$14,$C$14*(2027-$D$14)/($E$14-$D$14))) -> 0 | F34: =IF(2028<=$D$14,0,IF(2028>=$E$14,$C$14,$C$14*(2028-$D$14)/($E$14-$D$14))) -> 0 | G34: =IF(2029<=$D$14,0,IF(2029>=$E$14,$C$14,$C$14*(2029-$D$14)/($E$14-$D$14))) -> 0 | H34: =IF(2030<=$D$14,0,IF(2030>=$E$14,$C$14,$C$14*(2030-$D$14)/($E$14-$D$14))) -> 0 | I34: =IF(2031<=$D$14,0,IF(2031>=$E$14,$C$14,$C$14*(2031-$D$14)/($E$14-$D$14))) -> 0 | J34: =IF(2032<=$D$14,0,IF(2032>=$E$14,$C$14,$C$14*(2032-$D$14)/($E$14-$D$14))) -> 0 | K34: =IF(2033<=$D$14,0,IF(2033>=$E$14,$C$14,$C$14*(2033-$D$14)/($E$14-$D$14))) -> 0 | L34: =IF(2034<=$D$14,0,IF(2034>=$E$14,$C$14,$C$14*(2034-$D$14)/($E$14-$D$14))) -> 0 | M34: =IF(2035<=$D$14,0,IF(2035>=$E$14,$C$14,$C$14*(2035-$D$14)/($E$14-$D$14))) -> 0
A35: Diesel | B35: =IF(2024<=$D$15,0,IF(2024>=$E$15,$C$15,$C$15*(2024-$D$15)/($E$15-$D$15))) -> 0 | C35: =IF(2025<=$D$15,0,IF(2025>=$E$15,$C$15,$C$15*(2025-$D$15)/($E$15-$D$15))) -> 0 | D35: =IF(2026<=$D$15,0,IF(2026>=$E$15,$C$15,$C$15*(2026-$D$15)/($E$15-$D$15))) -> 0 | E35: =IF(2027<=$D$15,0,IF(2027>=$E$15,$C$15,$C$15*(2027-$D$15)/($E$15-$D$15))) -> 0 | F35: =IF(2028<=$D$15,0,IF(2028>=$E$15,$C$15,$C$15*(2028-$D$15)/($E$15-$D$15))) -> 0 | G35: =IF(2029<=$D$15,0,IF(2029>=$E$15,$C$15,$C$15*(2029-$D$15)/($E$15-$D$15))) -> 0 | H35: =IF(2030<=$D$15,0,IF(2030>=$E$15,$C$15,$C$15*(2030-$D$15)/($E$15-$D$15))) -> 0 | I35: =IF(2031<=$D$15,0,IF(2031>=$E$15,$C$15,$C$15*(2031-$D$15)/($E$15-$D$15))) -> 0 | J35: =IF(2032<=$D$15,0,IF(2032>=$E$15,$C$15,$C$15*(2032-$D$15)/($E$15-$D$15))) -> 0 | K35: =IF(2033<=$D$15,0,IF(2033>=$E$15,$C$15,$C$15*(2033-$D$15)/($E$15-$D$15))) -> 0 | L35: =IF(2034<=$D$15,0,IF(2034>=$E$15,$C$15,$C$15*(2034-$D$15)/($E$15-$D$15))) -> 0 | M35: =IF(2035<=$D$15,0,IF(2035>=$E$15,$C$15,$C$15*(2035-$D$15)/($E$15-$D$15))) -> 0
A36: Electricity | B36: =IF(2024<=$D$16,0,IF(2024>=$E$16,$C$16,$C$16*(2024-$D$16)/($E$16-$D$16))) -> 0 | C36: =IF(2025<=$D$16,0,IF(2025>=$E$16,$C$16,$C$16*(2025-$D$16)/($E$16-$D$16))) -> 0 | D36: =IF(2026<=$D$16,0,IF(2026>=$E$16,$C$16,$C$16*(2026-$D$16)/($E$16-$D$16))) -> 0 | E36: =IF(2027<=$D$16,0,IF(2027>=$E$16,$C$16,$C$16*(2027-$D$16)/($E$16-$D$16))) -> 0 | F36: =IF(2028<=$D$16,0,IF(2028>=$E$16,$C$16,$C$16*(2028-$D$16)/($E$16-$D$16))) -> 0 | G36: =IF(2029<=$D$16,0,IF(2029>=$E$16,$C$16,$C$16*(2029-$D$16)/($E$16-$D$16))) -> 0 | H36: =IF(2030<=$D$16,0,IF(2030>=$E$16,$C$16,$C$16*(2030-$D$16)/($E$16-$D$16))) -> 0 | I36: =IF(2031<=$D$16,0,IF(2031>=$E$16,$C$16,$C$16*(2031-$D$16)/($E$16-$D$16))) -> 0 | J36: =IF(2032<=$D$16,0,IF(2032>=$E$16,$C$16,$C$16*(2032-$D$16)/($E$16-$D$16))) -> 0 | K36: =IF(2033<=$D$16,0,IF(2033>=$E$16,$C$16,$C$16*(2033-$D$16)/($E$16-$D$16))) -> 0 | L36: =IF(2034<=$D$16,0,IF(2034>=$E$16,$C$16,$C$16*(2034-$D$16)/($E$16-$D$16))) -> 0 | M36: =IF(2035<=$D$16,0,IF(2035>=$E$16,$C$16,$C$16*(2035-$D$16)/($E$16-$D$16))) -> 0
A37: RE generation | B37: =IF(2024<=$D$17,0,IF(2024>=$E$17,$C$17,$C$17*(2024-$D$17)/($E$17-$D$17))) -> 0 | C37: =IF(2025<=$D$17,0,IF(2025>=$E$17,$C$17,$C$17*(2025-$D$17)/($E$17-$D$17))) -> 0 | D37: =IF(2026<=$D$17,0,IF(2026>=$E$17,$C$17,$C$17*(2026-$D$17)/($E$17-$D$17))) -> 0 | E37: =IF(2027<=$D$17,0,IF(2027>=$E$17,$C$17,$C$17*(2027-$D$17)/($E$17-$D$17))) -> 0 | F37: =IF(2028<=$D$17,0,IF(2028>=$E$17,$C$17,$C$17*(2028-$D$17)/($E$17-$D$17))) -> 0 | G37: =IF(2029<=$D$17,0,IF(2029>=$E$17,$C$17,$C$17*(2029-$D$17)/($E$17-$D$17))) -> 0 | H37: =IF(2030<=$D$17,0,IF(2030>=$E$17,$C$17,$C$17*(2030-$D$17)/($E$17-$D$17))) -> 0 | I37: =IF(2031<=$D$17,0,IF(2031>=$E$17,$C$17,$C$17*(2031-$D$17)/($E$17-$D$17))) -> 0 | J37: =IF(2032<=$D$17,0,IF(2032>=$E$17,$C$17,$C$17*(2032-$D$17)/($E$17-$D$17))) -> 0 | K37: =IF(2033<=$D$17,0,IF(2033>=$E$17,$C$17,$C$17*(2033-$D$17)/($E$17-$D$17))) -> 0 | L37: =IF(2034<=$D$17,0,IF(2034>=$E$17,$C$17,$C$17*(2034-$D$17)/($E$17-$D$17))) -> 0 | M37: =IF(2035<=$D$17,0,IF(2035>=$E$17,$C$17,$C$17*(2035-$D$17)/($E$17-$D$17))) -> 0
A40: TOTAL EFFECTIVE CARBON PRICE
A41: TECP at target year | B41: ='TECP Calcs'!B28 -> 61.859332 | C41: $/tCO2
A43: Decomposition:
A44: Intensive margin | B44: ='TECP Calcs'!B31 -> 41.973925
A45: Extensive margin | B45: ='TECP Calcs'!B32 -> 19.885407
A47: Sector breakdown:
...

Sheet Tech Parameters
A1: Technical Parameters
A3: CES Elasticities
B4: Road Transport | C4: Electricity Gen.
A5: Substitution elasticity (sigma) | B5: 1.5 | C5: 0.8
A6: Demand elasticity (eta) | B6: -0.3 | C6: -0.15
A7: Adjustment speed (lambda) | B7: 0.15 | C7: 0.08
A9: Road Transport — Fuel Parameters
A10: Fuel | B10: Base price ($/GJ) | C10: Emission factor (tCO2/GJ) | D10: Base quantity (PJ) | E10: Efficiency (phi) | F10: Effective price ($/GJ svc) | G10: Effective EF (tCO2/GJ svc) | H10: Energy share (w) | I10: Service share (w_hat) | J10: Cost share (s)
A11: Coal | B11: 0 | C11: 0.095 | D11: 0 | E11: 0 | F11: =IF(E11=0,0,B11/E11) -> 0 | G11: =IF(E11=0,0,C11/E11) -> 0 | H11: =IF(SUM($D$11:$D$16)=0,0,D11/SUM($D$11:$D$16)) -> 0 | I11: =IF(SUMPRODUCT($D$11:$D$16,$E$11:$E$16)=0,0,D11*E11/SUMPRODUCT($D$11:$D$16,$E$11:$E$16)) -> 0 | J11: =IF(SUMPRODUCT($B$11:$B$16,$D$11:$D$16)=0,0,B11*D11/SUMPRODUCT($B$11:$B$16,$D$11:$D$16)) -> 0
A12: Natural gas | B12: 8 | C12: 0.056 | D12: 15 | E12: 0.25 | F12: =IF(E12=0,0,B12/E12) -> 32 | G12: =IF(E12=0,0,C12/E12) -> 0.224 | H12: =IF(SUM($D$11:$D$16)=0,0,D12/SUM($D$11:$D$16)) -> 0.012244898 | I12: =IF(SUMPRODUCT($D$11:$D$16,$E$11:$E$16)=0,0,D12*E12/SUMPRODUCT($D$11:$D$16,$E$11:$E$16)) -> 0.010211028 | J12: =IF(SUMPRODUCT($B$11:$B$16,$D$11:$D$16)=0,0,B12*D12/SUMPRODUCT($B$11:$B$16,$D$11:$D$16)) -> 0.0055452865
A13: Gasoline | B13: 18 | C13: 0.069 | D13: 650 | E13: 0.25 | F13: =IF(E13=0,0,B13/E13) -> 72 | G13: =IF(E13=0,0,C13/E13) -> 0.276 | H13: =IF(SUM($D$11:$D$16)=0,0,D13/SUM($D$11:$D$16)) -> 0.53061224 | I13: =IF(SUMPRODUCT($D$11:$D$16,$E$11:$E$16)=0,0,D13*E13/SUMPRODUCT($D$11:$D$16,$E$11:$E$16)) -> 0.44247788 | J13: =IF(SUMPRODUCT($B$11:$B$16,$D$11:$D$16)=0,0,B13*D13/SUMPRODUCT($B$11:$B$16,$D$11:$D$16)) -> 0.54066543
A14: Diesel | B14: 17 | C14: 0.074 | D14: 500 | E14: 0.3 | F14: =IF(E14=0,0,B14/E14) -> 56.666667 | G14: =IF(E14=0,0,C14/E14) -> 0.24666667 | H14: =IF(SUM($D$11:$D$16)=0,0,D14/SUM($D$11:$D$16)) -> 0.40816327 | I14: =IF(SUMPRODUCT($D$11:$D$16,$E$11:$E$16)=0,0,D14*E14/SUMPRODUCT($D$11:$D$16,$E$11:$E$16)) -> 0.40844112 | J14: =IF(SUMPRODUCT($B$11:$B$16,$D$11:$D$16)=0,0,B14*D14/SUMPRODUCT($B$11:$B$16,$D$11:$D$16)) -> 0.39279113
A15: Electricity | B15: 22 | C15: 0 | D15: 60 | E15: 0.85 | F15: =IF(E15=0,0,B15/E15) -> 25.882353 | G15: =IF(E15=0,0,C15/E15) -> 0 | H15: =IF(SUM($D$11:$D$16)=0,0,D15/SUM($D$11:$D$16)) -> 0.048979592 | I15: =IF(SUMPRODUCT($D$11:$D$16,$E$11:$E$16)=0,0,D15*E15/SUMPRODUCT($D$11:$D$16,$E$11:$E$16)) -> 0.13886998 | J15: =IF(SUMPRODUCT($B$11:$B$16,$D$11:$D$16)=0,0,B15*D15/SUMPRODUCT($B$11:$B$16,$D$11:$D$16)) -> 0.060998152
A16: RE generation | B16: 0 | C16: 0 | D16: 0 | E16: 0 | F16: =IF(E16=0,0,B16/E16) -> 0 | G16: =IF(E16=0,0,C16/E16) -> 0 | H16: =IF(SUM($D$11:$D$16)=0,0,D16/SUM($D$11:$D$16)) -> 0 | I16: =IF(SUMPRODUCT($D$11:$D$16,$E$11:$E$16)=0,0,D16*E16/SUMPRODUCT($D$11:$D$16,$E$11:$E$16)) -> 0 | J16: =IF(SUMPRODUCT($B$11:$B$16,$D$11:$D$16)=0,0,B16*D16/SUMPRODUCT($B$11:$B$16,$D$11:$D$16)) -> 0
A17: TOTALS | D17: =SUM(D11:D16) -> 1225
A18: Mean eff. EF (svc-wtd) | B18: =SUMPRODUCT(I11:I16,G11:G16) -> 0.22515997
A19: Total emissions (MtCO2) | B19: =SUMPRODUCT(D11:D16,C11:C16) -> 82.69
A22: Electricity Generation — Fuel Parameters
A23: Fuel | B23: Base price ($/GJ) | C23: Emission factor (tCO2/GJ) | D23: Base quantity (PJ) | E23: Efficiency (phi) | F23: Effective price ($/GJ svc) | G23: Effective EF (tCO2/GJ svc) | H23: Energy share (w) | I23: Service share (w_hat) | J23: Cost share (s)
A24: Coal | B24: 3 | C24: 0.095 | D24: 1200 | E24: 0.38 | F24: =IF(E24=0,0,B24/E24) -> 7.8947368 | G24: =IF(E24=0,0,C24/E24) -> 0.25 | H24: =IF(SUM($D$24:$D$29)=0,0,D24/SUM($D$24:$D$29)) -> 0.49382716 | I24: =IF(SUMPRODUCT($D$24:$D$29,$E$24:$E$29)=0,0,D24*E24/SUMPRODUCT($D$24:$D$29,$E$24:$E$29)) -> 0.36004737 | J24: =IF(SUMPRODUCT($B$24:$B$29,$D$24:$D$29)=0,0,B24*D24/SUMPRODUCT($B$24:$B$29,$D$24:$D$29)) -> 0.37422037
A25: Natural gas | B25: 6 | C25: 0.056 | D25: 800 | E25: 0.5 | F25: =IF(E25=0,0,B25/E25) -> 12 | G25: =IF(E25=0,0,C25/E25) -> 0.112 | H25: =IF(SUM($D$24:$D$29)=0,0,D25/SUM($D$24:$D$29)) -> 0.32921811 | I25: =IF(SUMPRODUCT($D$24:$D$29,$E$24:$E$29)=0,0,D25*E25/SUMPRODUCT($D$24:$D$29,$E$24:$E$29)) -> 0.31583103 | J25: =IF(SUMPRODUCT($B$24:$B$29,$D$24:$D$29)=0,0,B25*D25/SUMPRODUCT($B$24:$B$29,$D$24:$D$29)) -> 0.4989605
A26: Gasoline | B26: 0 | C26: 0.069 | D26: 0 | E26: 0 | F26: =IF(E26=0,0,B26/E26) -> 0 | G26: =IF(E26=0,0,C26/E26) -> 0 | H26: =IF(SUM($D$24:$D$29)=0,0,D26/SUM($D$24:$D$29)) -> 0 | I26: =IF(SUMPRODUCT($D$24:$D$29,$E$24:$E$29)=0,0,D26*E26/SUMPRODUCT($D$24:$D$29,$E$24:$E$29)) -> 0 | J26: =IF(SUMPRODUCT($B$24:$B$29,$D$24:$D$29)=0,0,B26*D26/SUMPRODUCT($B$24:$B$29,$D$24:$D$29)) -> 0
A27: Diesel | B27: 14 | C27: 0.074 | D27: 30 | E27: 0.35 | F27: =IF(E27=0,0,B27/E27) -> 40 | G27: =IF(E27=0,0,C27/E27) -> 0.21142857 | H27: =IF(SUM($D$24:$D$29)=0,0,D27/SUM($D$24:$D$29)) -> 0.012345679 | I27: =IF(SUMPRODUCT($D$24:$D$29,$E$24:$E$29)=0,0,D27*E27/SUMPRODUCT($D$24:$D$29,$E$24:$E$29)) -> 0.0082905645 | J27: =IF(SUMPRODUCT($B$24:$B$29,$D$24:$D$29)=0,0,B27*D27/SUMPRODUCT($B$24:$B$29,$D$24:$D$29)) -> 0.043659044
A28: Electricity | B28: 0 | C28: 0 | D28: 0 | E28: 0 | F28: =IF(E28=0,0,B28/E28) -> 0 | G28: =IF(E28=0,0,C28/E28) -> 0 | H28: =IF(SUM($D$24:$D$29)=0,0,D28/SUM($D$24:$D$29)) -> 0 | I28: =IF(SUMPRODUCT($D$24:$D$29,$E$24:$E$29)=0,0,D28*E28/SUMPRODUCT($D$24:$D$29,$E$24:$E$29)) -> 0 | J28: =IF(SUMPRODUCT($B$24:$B$29,$D$24:$D$29)=0,0,B28*D28/SUMPRODUCT($B$24:$B$29,$D$24:$D$29)) -> 0
A29: RE generation | B29: 2 | C29: 0 | D29: 400 | E29: 1 | F29: =IF(E29=0,0,B29/E29) -> 2 | G29: =IF(E29=0,0,C29/E29) -> 0 | H29: =IF(SUM($D$24:$D$29)=0,0,D29/SUM($D$24:$D$29)) -> 0.16460905 | I29: =IF(SUMPRODUCT($D$24:$D$29,$E$24:$E$29)=0,0,D29*E29/SUMPRODUCT($D$24:$D$29,$E$24:$E$29)) -> 0.31583103 | J29: =IF(SUMPRODUCT($B$24:$B$29,$D$24:$D$29)=0,0,B29*D29/SUMPRODUCT($B$24:$B$29,$D$24:$D$29)) -> 0.083160083
A30: TOTALS | D30: =SUM(D24:D29) -> 2430
A31: Mean eff. EF (svc-wtd) | B31: =SUMPRODUCT(I24:I29,G24:G29) -> 0.12713778
A32: Total emissions (MtCO2) | B32: =SUMPRODUCT(D24:D29,C24:C29) -> 161.02

Sheet TECP Calcs
A1: Total Effective Carbon Price (TECP)
A2: Static long-run equilibrium. Elasticities derived from CES, applied in isoelastic form.
A4: ROAD TRANSPORT
A5: Fuel | B5: E_fs (MtCO2) | C5: w_hat (svc share) | D5: e/phi (tCO2/GJ svc) | E5: mean e/phi | F5: p/phi ($/GJ svc) | G5: C_s ($/GJ svc) | H5: eps_int (isoelastic) | I5: eps_ext (isoelastic) | J5: eps_int_tilde (semi-elast) | K5: eps_ext_tilde (semi-elast) | L5: tau_int ($/tCO2) | M5: tau_ext ($/tCO2) | N5: Omega_int | O5: Omega_ext | P5: Dp_eff ($/GJ svc) | Q5: mean_Dp_eff ($/GJ svc)
A6: ='Tech Parameters'!A11 -> Coal | B6: ='Tech Parameters'!D11*'Tech Parameters'!C11 -> 0 | C6: ='Tech Parameters'!I11 -> 0 | D6: ='Tech Parameters'!G11 -> 0 | E6: ='Tech Parameters'!B18 -> 0.22515997 | F6: ='Tech Parameters'!F11 -> 0 | G6: =('Tech Parameters'!J11*IF('Tech Parameters'!F11=0,0,'Tech Parameters'!F11^(1-'Tech Parameters'!$B$5))+'Tech Parameters'!J12*IF('Tech Parameters'!F12=0,0,'Tech Parameters'!F12^(1-'Tech Parameters'!$B$5))+'Tech Parameters'!J13*IF('Tech Parameters'!F13=0,0,'Tech Parameters'!F13^(1-'Tech Parameters'!$B$5))+'Tech Parameters'!J14*IF('Tech Parameters'!F14=0,0,'Tech Parameters'!F14^(1-'Tech Parameters'!$B$5))+'Tech Parameters'!J15*IF('Tech Parameters'!F15=0,0,'Tech Parameters'!F15^(1-'Tech Parameters'!$B$5))+'Tech Parameters'!J16*IF('Tech Parameters'!F16=0,0,'Tech Parameters'!F16^(1-'Tech Parameters'!$B$5)))^(1/(1-'Tech Parameters'!$B$5)) -> 60.216236 | H6: =IF(C6=0,0,-'Tech Parameters'!$B$5*(1-C6)) -> 0 | I6: ='Tech Parameters'!$B$6 -> -0.3 | J6: =IF(F6=0,0,'Tech Parameters'!$B$5*(1-C6)*(D6-E6)/F6) -> 0 | K6: =IF(G6=0,0,ABS('Tech Parameters'!$B$6)*E6/G6) -> 0.0011217571 | L6: =IF(ABS(D6-E6)<0.00001,0,(P6-Q6)/(D6-E6)) -> 113.49014 | M6: =IF(E6=0,0,Q6/E6) -> 113.49014 | N6: =B6*J6 -> 0 | O6: =B6*K6 -> 0 | P6: =IF('Tech Parameters'!E11=0,0,(Dashboard!$B$6*'Tech Parameters'!C11+Dashboard!$B$7*('Tech Parameters'!C11-('Tech Parameters'!H11*'Tech Parameters'!C11+'Tech Parameters'!H12*'Tech Parameters'!C12+'Tech Parameters'!H13*'Tech Parameters'!C13+'Tech Parameters'!H14*'Tech Parameters'!C14+'Tech Parameters'!H15*'Tech Parameters'!C15+'Tech Parameters'!H16*'Tech Parameters'!C16))+Dashboard!$B$12)/'Tech Parameters'!E11) -> 0 | Q6: =SUMPRODUCT($C$6:$C$11,$P$6:$P$11) -> 25.553438
A7: ='Tech Parameters'!A12 -> Natural gas | B7: ='Tech Parameters'!D12*'Tech Parameters'!C12 -> 0.84 | C7: ='Tech Parameters'!I12 -> 0.010211028 | D7: ='Tech Parameters'!G12 -> 0.224 | E7: ='Tech Parameters'!B18 -> 0.22515997 | F7: ='Tech Parameters'!F12 -> 32 | G7: =$G$6 -> 60.216236 | H7: =IF(C7=0,0,-'Tech Parameters'!$B$5*(1-C7)) -> -1.4846835 | I7: ='Tech Parameters'!$B$6 -> -0.3 | J7: =IF(F7=0,0,'Tech Parameters'!$B$5*(1-C7)*(D7-E7)/F7) -> -5.3818512e-05 | K7: =IF(G7=0,0,ABS('Tech Parameters'!$B$6)*E7/G7) -> 0.0011217571 | L7: =IF(ABS(D7-E7)<0.00001,0,(P7-Q7)/(D7-E7)) -> 13167.206 | M7: =IF(E7=0,0,Q7/E7) -> 113.49014 | N7: =B7*J7 -> -4.520755e-05 | O7: =B7*K7 -> 0.00094227599 | P7: =IF('Tech Parameters'!E12=0,0,(Dashboard!$B$6*'Tech Parameters'!C12+Dashboard!$B$7*('Tech Parameters'!C12-('Tech Parameters'!H11*'Tech Parameters'!C11+'Tech Parameters'!H12*'Tech Parameters'!C12+'Tech Parameters'!H13*'Tech Parameters'!C13+'Tech Parameters'!H14*'Tech Parameters'!C14+'Tech Parameters'!H15*'Tech Parameters'!C15+'Tech Parameters'!H16*'Tech Parameters'!C16))+Dashboard!$B$13)/'Tech Parameters'!E12) -> 10.279837 | Q7: =SUMPRODUCT($C$6:$C$11,$P$6:$P$11) -> 25.553438
A8: ='Tech Parameters'!A13 -> Gasoline | B8: ='Tech Parameters'!D13*'Tech Parameters'!C13 -> 44.85 | C8: ='Tech Parameters'!I13 -> 0.44247788 | D8: ='Tech Parameters'!G13 -> 0.276 | E8: ='Tech Parameters'!B18 -> 0.22515997 | F8: ='Tech Parameters'!F13 -> 72 | G8: =$G$6 -> 60.216236 | H8: =IF(C8=0,0,-'Tech Parameters'!$B$5*(1-C8)) -> -0.83628319 | I8: ='Tech Parameters'!$B$6 -> -0.3 | J8: =IF(F8=0,0,'Tech Parameters'!$B$5*(1-C8)*(D8-E8)/F8) -> 0.00059050917 | K8: =IF(G8=0,0,ABS('Tech Parameters'!$B$6)*E8/G8) -> 0.0011217571 | L8: =IF(ABS(D8-E8)<0.00001,0,(P8-Q8)/(D8-E8)) -> 164.56323 | M8: =IF(E8=0,0,Q8/E8) -> 113.49014 | N8: =B8*J8 -> 0.026484336 | O8: =B8*K8 -> 0.050310807 | P8: =IF('Tech Parameters'!E13=0,0,(Dashboard!$B$6*'Tech Parameters'!C13+Dashboard!$B$7*('Tech Parameters'!C13-('Tech Parameters'!H11*'Tech Parameters'!C11+'Tech Parameters'!H12*'Tech Parameters'!C12+'Tech Parameters'!H13*'Tech Parameters'!C13+'Tech Parameters'!H14*'Tech Parameters'!C14+'Tech Parameters'!H15*'Tech Parameters'!C15+'Tech Parameters'!H16*'Tech Parameters'!C16))+Dashboard!$B$14)/'Tech Parameters'!E13) -> 33.919837 | Q8: =SUMPRODUCT($C$6:$C$11,$P$6:$P$11) -> 25.553438
A9: ='Tech Parameters'!A14 -> Diesel | B9: ='Tech Parameters'!D14*'Tech Parameters'!C14 -> 37 | C9: ='Tech Parameters'!I14 -> 0.40844112 | D9: ='Tech Parameters'!G14 -> 0.24666667 | E9: ='Tech Parameters'!B18 -> 0.22515997 | F9: ='Tech Parameters'!F14 -> 56.666667 | G9: =$G$6 -> 60.216236 | H9: =IF(C9=0,0,-'Tech Parameters'!$B$5*(1-C9)) -> -0.88733833 | I9: ='Tech Parameters'!$B$6 -> -0.3 | J9: =IF(F9=0,0,'Tech Parameters'!$B$5*(1-C9)*(D9-E9)/F9) -> 0.00033677142 | K9: =IF(G9=0,0,ABS('Tech Parameters'!$B$6)*E9/G9) -> 0.0011217571 | L9: =IF(ABS(D9-E9)<0.00001,0,(P9-Q9)/(D9-E9)) -> 25.407263 | M9: =IF(E9=0,0,Q9/E9) -> 113.49014 | N9: =B9*J9 -> 0.012460543 | O9: =B9*K9 -> 0.041505014 | P9: =IF('Tech Parameters'!E14=0,0,(Dashboard!$B$6*'Tech Parameters'!C14+Dashboard!$B$7*('Tech Parameters'!C14-('Tech Parameters'!H11*'Tech Parameters'!C11+'Tech Parameters'!H12*'Tech Parameters'!C12+'Tech Parameters'!H13*'Tech Parameters'!C13+'Tech Parameters'!H14*'Tech Parameters'!C14+'Tech Parameters'!H15*'Tech Parameters'!C15+'Tech Parameters'!H16*'Tech Parameters'!C16))+Dashboard!$B$15)/'Tech Parameters'!E14) -> 26.099864 | Q9: =SUMPRODUCT($C$6:$C$11,$P$6:$P$11) -> 25.553438
A10: ='Tech Parameters'!A15 -> Electricity | B10: ='Tech Parameters'!D15*'Tech Parameters'!C15 -> 0 | C10: ='Tech Parameters'!I15 -> 0.13886998 | D10: ='Tech Parameters'!G15 -> 0 | E10: ='Tech Parameters'!B18 -> 0.22515997 | F10: ='Tech Parameters'!F15 -> 25.882353 | G10: =$G$6 -> 60.216236 | H10: =IF(C10=0,0,-'Tech Parameters'!$B$5*(1-C10)) -> -1.291695 | I10: ='Tech Parameters'!$B$6 -> -0.3 | J10: =IF(F10=0,0,'Tech Parameters'!$B$5*(1-C10)*(D10-E10)/F10) -> -0.011236923 | K10: =IF(G10=0,0,ABS('Tech Parameters'!$B$6)*E10/G10) -> 0.0011217571 | L10: =IF(ABS(D10-E10)<0.00001,0,(P10-Q10)/(D10-E10)) -> 120.54417 | M10: =IF(E10=0,0,Q10/E10) -> 113.49014 | N10: =B10*J10 -> 0 | O10: =B10*K10 -> 0 | P10: =IF('Tech Parameters'!E15=0,0,(Dashboard!$B$6*'Tech Parameters'!C15+Dashboard!$B$7*('Tech Parameters'!C15-('Tech Parameters'!H11*'Tech Parameters'!C11+'Tech Parameters'!H12*'Tech Parameters'!C12+'Tech Parameters'!H13*'Tech Parameters'!C13+'Tech Parameters'!H14*'Tech Parameters'!C14+'Tech Parameters'!H15*'Tech Parameters'!C15+'Tech Parameters'!H16*'Tech Parameters'!C16))+Dashboard!$B$16)/'Tech Parameters'!E15) -> -1.5882833 | Q10: =SUMPRODUCT($C$6:$C$11,$P$6:$P$11) -> 25.553438
A11: ='Tech Parameters'!A16 -> RE generation | B11: ='Tech Parameters'!D16*'Tech Parameters'!C16 -> 0 | C11: ='Tech Parameters'!I16 -> 0 | D11: ='Tech Parameters'!G16 -> 0 | E11: ='Tech Parameters'!B18 -> 0.22515997 | F11: ='Tech Parameters'!F16 -> 0 | G11: =$G$6 -> 60.216236 | H11: =IF(C11=0,0,-'Tech Parameters'!$B$5*(1-C11)) -> 0 | I11: ='Tech Parameters'!$B$6 -> -0.3 | J11: =IF(F11=0,0,'Tech Parameters'!$B$5*(1-C11)*(D11-E11)/F11) -> 0 | K11: =IF(G11=0,0,ABS('Tech Parameters'!$B$6)*E11/G11) -> 0.0011217571 | L11: =IF(ABS(D11-E11)<0.00001,0,(P11-Q11)/(D11-E11)) -> 113.49014 | M11: =IF(E11=0,0,Q11/E11) -> 113.49014 | N11: =B11*J11 -> 0 | O11: =B11*K11 -> 0 | P11: =IF('Tech Parameters'!E16=0,0,(Dashboard!$B$6*'Tech Parameters'!C16+Dashboard!$B$7*('Tech Parameters'!C16-('Tech Parameters'!H11*'Tech Parameters'!C11+'Tech Parameters'!H12*'Tech Parameters'!C12+'Tech Parameters'!H13*'Tech Parameters'!C13+'Tech Parameters'!H14*'Tech Parameters'!C14+'Tech Parameters'!H15*'Tech Parameters'!C15+'Tech Parameters'!H16*'Tech Parameters'!C16))+Dashboard!$B$17)/'Tech Parameters'!E16) -> 0 | Q11: =SUMPRODUCT($C$6:$C$11,$P$6:$P$11) -> 25.553438
A14: ELECTRICITY GENERATION
A15: Fuel | B15: E_fs (MtCO2) | C15: w_hat (svc share) | D15: e/phi (tCO2/GJ svc) | E15: mean e/phi | F15: p/phi ($/GJ svc) | G15: C_s ($/GJ svc) | H15: eps_int (isoelastic) | I15: eps_ext (isoelastic) | J15: eps_int_tilde (semi-elast) | K15: eps_ext_tilde (semi-elast) | L15: tau_int ($/tCO2) | M15: tau_ext ($/tCO2) | N15: Omega_int | O15: Omega_ext | P15: Dp_eff ($/GJ svc) | Q15: mean_Dp_eff ($/GJ svc)
A16: ='Tech Parameters'!A24 -> Coal | B16: ='Tech Parameters'!D24*'Tech Parameters'!C24 -> 114 | C16: ='Tech Parameters'!I24 -> 0.36004737 | D16: ='Tech Parameters'!G24 -> 0.25 | E16: ='Tech Parameters'!B31 -> 0.12713778 | F16: ='Tech Parameters'!F24 -> 7.8947368 | G16: =('Tech Parameters'!J24*IF('Tech Parameters'!F24=0,0,'Tech Parameters'!F24^(1-'Tech Parameters'!$C$5))+'Tech Parameters'!J25*IF('Tech Parameters'!F25=0,0,'Tech Parameters'!F25^(1-'Tech Parameters'!$C$5))+'Tech Parameters'!J26*IF('Tech Parameters'!F26=0,0,'Tech Parameters'!F26^(1-'Tech Parameters'!$C$5))+'Tech Parameters'!J27*IF('Tech Parameters'!F27=0,0,'Tech Parameters'!F27^(1-'Tech Parameters'!$C$5))+'Tech Parameters'!J28*IF('Tech Parameters'!F28=0,0,'Tech Parameters'!F28^(1-'Tech Parameters'!$C$5))+'Tech Parameters'!J29*IF('Tech Parameters'!F29=0,0,'Tech Parameters'!F29^(1-'Tech Parameters'!$C$5)))^(1/(1-'Tech Parameters'!$C$5)) -> 9.6214419 | H16: =IF(C16=0,0,-'Tech Parameters'!$C$5*(1-C16)) -> -0.5119621 | I16: ='Tech Parameters'!$C$6 -> -0.15 | J16: =IF(F16=0,0,'Tech Parameters'!$C$5*(1-C16)*(D16-E16)/F16) -> 0.0079674346 | K16: =IF(G16=0,0,ABS('Tech Parameters'!$C$6)*E16/G16) -> 0.0019821008 | L16: =IF(ABS(D16-E16)<0.00001,0,(P16-Q16)/(D16-E16)) -> 59.232622 | M16: =IF(E16=0,0,Q16/E16) -> 50 | N16: =B16*J16 -> 0.90828755 | O16: =B16*K16 -> 0.22595949 | P16: =IF('Tech Parameters'!E24=0,0,(Dashboard!$B$6*'Tech Parameters'!C24+Dashboard!$B$8*('Tech Parameters'!C24-('Tech Parameters'!H24*'Tech Parameters'!C24+'Tech Parameters'!H25*'Tech Parameters'!C25+'Tech Parameters'!H26*'Tech Parameters'!C26+'Tech Parameters'!H27*'Tech Parameters'!C27+'Tech Parameters'!H28*'Tech Parameters'!C28+'Tech Parameters'!H29*'Tech Parameters'!C29))+Dashboard!$C$12)/'Tech Parameters'!E24) -> 13.63434 | Q16: =SUMPRODUCT($C$16:$C$21,$P$16:$P$21) -> 6.3568891
A17: ='Tech Parameters'!A25 -> Natural gas | B17: ='Tech Parameters'!D25*'Tech Parameters'!C25 -> 44.8 | C17: ='Tech Parameters'!I25 -> 0.31583103 | D17: ='Tech Parameters'!G25 -> 0.112 | E17: ='Tech Parameters'!B31 -> 0.12713778 | F17: ='Tech Parameters'!F25 -> 12 | G17: =$G$16 -> 9.6214419 | H17: =IF(C17=0,0,-'Tech Parameters'!$C$5*(1-C17)) -> -0.54733518 | I17: ='Tech Parameters'!$C$6 -> -0.15 | J17: =IF(F17=0,0,'Tech Parameters'!$C$5*(1-C17)*(D17-E17)/F17) -> -0.00069045335 | K17: =IF(G17=0,0,ABS('Tech Parameters'!$C$6)*E17/G17) -> 0.0019821008 | L17: =IF(ABS(D17-E17)<0.00001,0,(P17-Q17)/(D17-E17)) -> 70.339918 | M17: =IF(E17=0,0,Q17/E17) -> 50 | N17: =B17*J17 -> -0.03093231 | O17: =B17*K17 -> 0.088798114 | P17: =IF('Tech Parameters'!E25=0,0,(Dashboard!$B$6*'Tech Parameters'!C25+Dashboard!$B$8*('Tech Parameters'!C25-('Tech Parameters'!H24*'Tech Parameters'!C24+'Tech Parameters'!H25*'Tech Parameters'!C25+'Tech Parameters'!H26*'Tech Parameters'!C26+'Tech Parameters'!H27*'Tech Parameters'!C27+'Tech Parameters'!H28*'Tech Parameters'!C28+'Tech Parameters'!H29*'Tech Parameters'!C29))+Dashboard!$C$13)/'Tech Parameters'!E25) -> 5.2920988 | Q17: =SUMPRODUCT($C$16:$C$21,$P$16:$P$21) -> 6.3568891
A18: ='Tech Parameters'!A26 -> Gasoline | B18: ='Tech Parameters'!D26*'Tech Parameters'!C26 -> 0 | C18: ='Tech Parameters'!I26 -> 0 | D18: ='Tech Parameters'!G26 -> 0 | E18: ='Tech Parameters'!B31 -> 0.12713778 | F18: ='Tech Parameters'!F26 -> 0 | G18: =$G$16 -> 9.6214419 | H18: =IF(C18=0,0,-'Tech Parameters'!$C$5*(1-C18)) -> 0 | I18: ='Tech Parameters'!$C$6 -> -0.15 | J18: =IF(F18=0,0,'Tech Parameters'!$C$5*(1-C18)*(D18-E18)/F18) -> 0 | K18: =IF(G18=0,0,ABS('Tech Parameters'!$C$6)*E18/G18) -> 0.0019821008 | L18: =IF(ABS(D18-E18)<0.00001,0,(P18-Q18)/(D18-E18)) -> 50 | M18: =IF(E18=0,0,Q18/E18) -> 50 | N18: =B18*J18 -> 0 | O18: =B18*K18 -> 0 | P18: =IF('Tech Parameters'!E26=0,0,(Dashboard!$B$6*'Tech Parameters'!C26+Dashboard!$B$8*('Tech Parameters'!C26-('Tech Parameters'!H24*'Tech Parameters'!C24+'Tech Parameters'!H25*'Tech Parameters'!C25+'Tech Parameters'!H26*'Tech Parameters'!C26+'Tech Parameters'!H27*'Tech Parameters'!C27+'Tech Parameters'!H28*'Tech Parameters'!C28+'Tech Parameters'!H29*'Tech Parameters'!C29))+Dashboard!$C$14)/'Tech Parameters'!E26) -> 0 | Q18: =SUMPRODUCT($C$16:$C$21,$P$16:$P$21) -> 6.3568891
A19: ='Tech Parameters'!A27 -> Diesel | B19: ='Tech Parameters'!D27*'Tech Parameters'!C27 -> 2.22 | C19: ='Tech Parameters'!I27 -> 0.0082905645 | D19: ='Tech Parameters'!G27 -> 0.21142857 | E19: ='Tech Parameters'!B31 -> 0.12713778 | F19: ='Tech Parameters'!F27 -> 40 | G19: =$G$16 -> 9.6214419 | H19: =IF(C19=0,0,-'Tech Parameters'!$C$5*(1-C19)) -> -0.79336755 | I19: ='Tech Parameters'!$C$6 -> -0.15 | J19: =IF(F19=0,0,'Tech Parameters'!$C$5*(1-C19)*(D19-E19)/F19) -> 0.0016718394 | K19: =IF(G19=0,0,ABS('Tech Parameters'!$C$6)*E19/G19) -> 0.0019821008 | L19: =IF(ABS(D19-E19)<0.00001,0,(P19-Q19)/(D19-E19)) -> 53.93364 | M19: =IF(E19=0,0,Q19/E19) -> 50 | N19: =B19*J19 -> 0.0037114836 | O19: =B19*K19 -> 0.0044002637 | P19: =IF('Tech Parameters'!E27=0,0,(Dashboard!$B$6*'Tech Parameters'!C27+Dashboard!$B$8*('Tech Parameters'!C27-('Tech Parameters'!H24*'Tech Parameters'!C24+'Tech Parameters'!H25*'Tech Parameters'!C25+'Tech Parameters'!H26*'Tech Parameters'!C26+'Tech Parameters'!H27*'Tech Parameters'!C27+'Tech Parameters'!H28*'Tech Parameters'!C28+'Tech Parameters'!H29*'Tech Parameters'!C29))+Dashboard!$C$15)/'Tech Parameters'!E27) -> 10.902998 | Q19: =SUMPRODUCT($C$16:$C$21,$P$16:$P$21) -> 6.3568891
A20: ='Tech Parameters'!A28 -> Electricity | B20: ='Tech Parameters'!D28*'Tech Parameters'!C28 -> 0 | C20: ='Tech Parameters'!I28 -> 0 | D20: ='Tech Parameters'!G28 -> 0 | E20: ='Tech Parameters'!B31 -> 0.12713778 | F20: ='Tech Parameters'!F28 -> 0 | G20: =$G$16 -> 9.6214419 | H20: =IF(C20=0,0,-'Tech Parameters'!$C$5*(1-C20)) -> 0 | I20: ='Tech Parameters'!$C$6 -> -0.15 | J20: =IF(F20=0,0,'Tech Parameters'!$C$5*(1-C20)*(D20-E20)/F20) -> 0 | K20: =IF(G20=0,0,ABS('Tech Parameters'!$C$6)*E20/G20) -> 0.0019821008 | L20: =IF(ABS(D20-E20)<0.00001,0,(P20-Q20)/(D20-E20)) -> 50 | M20: =IF(E20=0,0,Q20/E20) -> 50 | N20: =B20*J20 -> 0 | O20: =B20*K20 -> 0 | P20: =IF('Tech Parameters'!E28=0,0,(Dashboard!$B$6*'Tech Parameters'!C28+Dashboard!$B$8*('Tech Parameters'!C28-('Tech Parameters'!H24*'Tech Parameters'!C24+'Tech Parameters'!H25*'Tech Parameters'!C25+'Tech Parameters'!H26*'Tech Parameters'!C26+'Tech Parameters'!H27*'Tech Parameters'!C27+'Tech Parameters'!H28*'Tech Parameters'!C28+'Tech Parameters'!H29*'Tech Parameters'!C29))+Dashboard!$C$16)/'Tech Parameters'!E28) -> 0 | Q20: =SUMPRODUCT($C$16:$C$21,$P$16:$P$21) -> 6.3568891
A21: ='Tech Parameters'!A29 -> RE generation | B21: ='Tech Parameters'!D29*'Tech Parameters'!C29 -> 0 | C21: ='Tech Parameters'!I29 -> 0.31583103 | D21: ='Tech Parameters'!G29 -> 0 | E21: ='Tech Parameters'!B31 -> 0.12713778 | F21: ='Tech Parameters'!F29 -> 2 | G21: =$G$16 -> 9.6214419 | H21: =IF(C21=0,0,-'Tech Parameters'!$C$5*(1-C21)) -> -0.54733518 | I21: ='Tech Parameters'!$C$6 -> -0.15 | J21: =IF(F21=0,0,'Tech Parameters'!$C$5*(1-C21)*(D21-E21)/F21) -> -0.03479349 | K21: =IF(G21=0,0,ABS('Tech Parameters'!$C$6)*E21/G21) -> 0.0019821008 | L21: =IF(ABS(D21-E21)<0.00001,0,(P21-Q21)/(D21-E21)) -> 57.817901 | M21: =IF(E21=0,0,Q21/E21) -> 50 | N21: =B21*J21 -> 0 | O21: =B21*K21 -> 0 | P21: =IF('Tech Parameters'!E29=0,0,(Dashboard!$B$6*'Tech Parameters'!C29+Dashboard!$B$8*('Tech Parameters'!C29-('Tech Parameters'!H24*'Tech Parameters'!C24+'Tech Parameters'!H25*'Tech Parameters'!C25+'Tech Parameters'!H26*'Tech Parameters'!C26+'Tech Parameters'!H27*'Tech Parameters'!C27+'Tech Parameters'!H28*'Tech Parameters'!C28+'Tech Parameters'!H29*'Tech Parameters'!C29))+Dashboard!$C$17)/'Tech Parameters'!E29) -> -0.99395062 | Q21: =SUMPRODUCT($C$16:$C$21,$P$16:$P$21) -> 6.3568891
A24: TECP CALCULATION
A25: Lambda (normalisation) | B25: =SUM(N6:N11)+SUM(O6:O11)+SUM(N16:N21)+SUM(O16:O21) -> 1.3318824
A26: Numerator (policy reduction) | B26: =SUMPRODUCT(N6:N11,L6:L11)+SUMPRODUCT(O6:O11,M6:M11)+SUMPRODUCT(N16:N21,L16:L21)+SUMPRODUCT(O16:O21,M16:M21) -> 82.389353
A28: TOTAL EFFECTIVE CARBON PRICE | B28: =$B$26/$B$25 -> 61.859332 | C28: $/tCO2
A30: Decomposition:
A31: Intensive margin | B31: =(SUMPRODUCT(N6:N11,L6:L11)+SUMPRODUCT(N16:N21,L16:L21))/$B$25 -> 41.973925
A32: Extensive margin | B32: =(SUMPRODUCT(O6:O11,M6:M11)+SUMPRODUCT(O16:O21,M16:M21))/$B$25 -> 19.885407
A34: Sector breakdown:
A35: Road Transport | B35: =(SUMPRODUCT(N6:N11,L6:L11)+SUMPRODUCT(O6:O11,M6:M11))/$B$25 -> 10.967041
A36: Electricity Generation | B36: =(SUMPRODUCT(N16:N21,L16:L21)+SUMPRODUCT(O16:O21,M16:M21))/$B$25 -> 50.892291
A38: Carbon tax (reference) | B38: =Dashboard!$B$6 -> 50
A39: TECP / Carbon tax ratio | B39: =IF(Dashboard!$B$6=0,0,$B$28/Dashboard!$B$6) -> 1.2371866
A41: Note: Isoelastic elasticities (cols H-I) derived from CES. Semi-elasticities (cols J-K) = isoelastic / price.
A42: Feebate input in $/tCO2: converted to $/GJ per fuel via feebate*(ef - e_bar), making it revenue-neutral.

Sheet Baseline
A1: Partial Adjustment Model — Baseline
B3: Unit | C3: 2024 | D3: 2025 | E3: 2026 | F3: 2027 | G3: 2028 | H3: 2029 | I3: 2030 | J3: 2031 | K3: 2032 | L3: 2033 | M3: 2034 | N3: 2035
A4: ROAD TRANSPORT — Fuel Prices ($/GJ)
A5: Coal | B5: $/GJ | C5: ='Tech Parameters'!B11 -> 0 | D5: ='Tech Parameters'!B11 -> 0 | E5: ='Tech Parameters'!B11 -> 0 | F5: ='Tech Parameters'!B11 -> 0 | G5: ='Tech Parameters'!B11 -> 0 | H5: ='Tech Parameters'!B11 -> 0 | I5: ='Tech Parameters'!B11 -> 0 | J5: ='Tech Parameters'!B11 -> 0 | K5: ='Tech Parameters'!B11 -> 0 | L5: ='Tech Parameters'!B11 -> 0 | M5: ='Tech Parameters'!B11 -> 0 | N5: ='Tech Parameters'!B11 -> 0
A6: Natural gas | B6: $/GJ | C6: ='Tech Parameters'!B12 -> 8 | D6: ='Tech Parameters'!B12 -> 8 | E6: ='Tech Parameters'!B12 -> 8 | F6: ='Tech Parameters'!B12 -> 8 | G6: ='Tech Parameters'!B12 -> 8 | H6: ='Tech Parameters'!B12 -> 8 | I6: ='Tech Parameters'!B12 -> 8 | J6: ='Tech Parameters'!B12 -> 8 | K6: ='Tech Parameters'!B12 -> 8 | L6: ='Tech Parameters'!B12 -> 8 | M6: ='Tech Parameters'!B12 -> 8 | N6: ='Tech Parameters'!B12 -> 8
A7: Gasoline | B7: $/GJ | C7: ='Tech Parameters'!B13 -> 18 | D7: ='Tech Parameters'!B13 -> 18 | E7: ='Tech Parameters'!B13 -> 18 | F7: ='Tech Parameters'!B13 -> 18 | G7: ='Tech Parameters'!B13 -> 18 | H7: ='Tech Parameters'!B13 -> 18 | I7: ='Tech Parameters'!B13 -> 18 | J7: ='Tech Parameters'!B13 -> 18 | K7: ='Tech Parameters'!B13 -> 18 | L7: ='Tech Parameters'!B13 -> 18 | M7: ='Tech Parameters'!B13 -> 18 | N7: ='Tech Parameters'!B13 -> 18
A8: Diesel | B8: $/GJ | C8: ='Tech Parameters'!B14 -> 17 | D8: ='Tech Parameters'!B14 -> 17 | E8: ='Tech Parameters'!B14 -> 17 | F8: ='Tech Parameters'!B14 -> 17 | G8: ='Tech Parameters'!B14 -> 17 | H8: ='Tech Parameters'!B14 -> 17 | I8: ='Tech Parameters'!B14 -> 17 | J8: ='Tech Parameters'!B14 -> 17 | K8: ='Tech Parameters'!B14 -> 17 | L8: ='Tech Parameters'!B14 -> 17 | M8: ='Tech Parameters'!B14 -> 17 | N8: ='Tech Parameters'!B14 -> 17
A9: Electricity | B9: $/GJ | C9: ='Tech Parameters'!B15 -> 22 | D9: ='Tech Parameters'!B15 -> 22 | E9: ='Tech Parameters'!B15 -> 22 | F9: ='Tech Parameters'!B15 -> 22 | G9: ='Tech Parameters'!B15 -> 22 | H9: ='Tech Parameters'!B15 -> 22 | I9: ='Tech Parameters'!B15 -> 22 | J9: ='Tech Parameters'!B15 -> 22 | K9: ='Tech Parameters'!B15 -> 22 | L9: ='Tech Parameters'!B15 -> 22 | M9: ='Tech Parameters'!B15 -> 22 | N9: ='Tech Parameters'!B15 -> 22
A10: RE generation | B10: $/GJ | C10: ='Tech Parameters'!B16 -> 0 | D10: ='Tech Parameters'!B16 -> 0 | E10: ='Tech Parameters'!B16 -> 0 | F10: ='Tech Parameters'!B16 -> 0 | G10: ='Tech Parameters'!B16 -> 0 | H10: ='Tech Parameters'!B16 -> 0 | I10: ='Tech Parameters'!B16 -> 0 | J10: ='Tech Parameters'!B16 -> 0 | K10: ='Tech Parameters'!B16 -> 0 | L10: ='Tech Parameters'!B16 -> 0 | M10: ='Tech Parameters'!B16 -> 0 | N10: ='Tech Parameters'!B16 -> 0
A12: ROAD TRANSPORT — Effective Prices ($/GJ svc)
A13: Coal | B13: $/GJ svc | C13: =IF('Tech Parameters'!E11=0,0,C5/'Tech Parameters'!E11) -> 0 | D13: =IF('Tech Parameters'!E11=0,0,D5/'Tech Parameters'!E11) -> 0 | E13: =IF('Tech Parameters'!E11=0,0,E5/'Tech Parameters'!E11) -> 0 | F13: =IF('Tech Parameters'!E11=0,0,F5/'Tech Parameters'!E11) -> 0 | G13: =IF('Tech Parameters'!E11=0,0,G5/'Tech Parameters'!E11) -> 0 | H13: =IF('Tech Parameters'!E11=0,0,H5/'Tech Parameters'!E11) -> 0 | I13: =IF('Tech Parameters'!E11=0,0,I5/'Tech Parameters'!E11) -> 0 | J13: =IF('Tech Parameters'!E11=0,0,J5/'Tech Parameters'!E11) -> 0 | K13: =IF('Tech Parameters'!E11=0,0,K5/'Tech Parameters'!E11) -> 0 | L13: =IF('Tech Parameters'!E11=0,0,L5/'Tech Parameters'!E11) -> 0 | M13: =IF('Tech Parameters'!E11=0,0,M5/'Tech Parameters'!E11) -> 0 | N13: =IF('Tech Parameters'!E11=0,0,N5/'Tech Parameters'!E11) -> 0
A14: Natural gas | B14: $/GJ svc | C14: =IF('Tech Parameters'!E12=0,0,C6/'Tech Parameters'!E12) -> 32 | D14: =IF('Tech Parameters'!E12=0,0,D6/'Tech Parameters'!E12) -> 32 | E14: =IF('Tech Parameters'!E12=0,0,E6/'Tech Parameters'!E12) -> 32 | F14: =IF('Tech Parameters'!E12=0,0,F6/'Tech Parameters'!E12) -> 32 | G14: =IF('Tech Parameters'!E12=0,0,G6/'Tech Parameters'!E12) -> 32 | H14: =IF('Tech Parameters'!E12=0,0,H6/'Tech Parameters'!E12) -> 32 | I14: =IF('Tech Parameters'!E12=0,0,I6/'Tech Parameters'!E12) -> 32 | J14: =IF('Tech Parameters'!E12=0,0,J6/'Tech Parameters'!E12) -> 32 | K14: =IF('Tech Parameters'!E12=0,0,K6/'Tech Parameters'!E12) -> 32 | L14: =IF('Tech Parameters'!E12=0,0,L6/'Tech Parameters'!E12) -> 32 | M14: =IF('Tech Parameters'!E12=0,0,M6/'Tech Parameters'!E12) -> 32 | N14: =IF('Tech Parameters'!E12=0,0,N6/'Tech Parameters'!E12) -> 32
A15: Gasoline | B15: $/GJ svc | C15: =IF('Tech Parameters'!E13=0,0,C7/'Tech Parameters'!E13) -> 72 | D15: =IF('Tech Parameters'!E13=0,0,D7/'Tech Parameters'!E13) -> 72 | E15: =IF('Tech Parameters'!E13=0,0,E7/'Tech Parameters'!E13) -> 72 | F15: =IF('Tech Parameters'!E13=0,0,F7/'Tech Parameters'!E13) -> 72 | G15: =IF('Tech Parameters'!E13=0,0,G7/'Tech Parameters'!E13) -> 72 | H15: =IF('Tech Parameters'!E13=0,0,H7/'Tech Parameters'!E13) -> 72 | I15: =IF('Tech Parameters'!E13=0,0,I7/'Tech Parameters'!E13) -> 72 | J15: =IF('Tech Parameters'!E13=0,0,J7/'Tech Parameters'!E13) -> 72 | K15: =IF('Tech Parameters'!E13=0,0,K7/'Tech Parameters'!E13) -> 72 | L15: =IF('Tech Parameters'!E13=0,0,L7/'Tech Parameters'!E13) -> 72 | M15: =IF('Tech Parameters'!E13=0,0,M7/'Tech Parameters'!E13) -> 72 | N15: =IF('Tech Parameters'!E13=0,0,N7/'Tech Parameters'!E13) -> 72
A16: Diesel | B16: $/GJ svc | C16: =IF('Tech Parameters'!E14=0,0,C8/'Tech Parameters'!E14) -> 56.666667 | D16: =IF('Tech Parameters'!E14=0,0,D8/'Tech Parameters'!E14) -> 56.666667 | E16: =IF('Tech Parameters'!E14=0,0,E8/'Tech Parameters'!E14) -> 56.666667 | F16: =IF('Tech Parameters'!E14=0,0,F8/'Tech Parameters'!E14) -> 56.666667 | G16: =IF('Tech Parameters'!E14=0,0,G8/'Tech Parameters'!E14) -> 56.666667 | H16: =IF('Tech Parameters'!E14=0,0,H8/'Tech Parameters'!E14) -> 56.666667 | I16: =IF('Tech Parameters'!E14=0,0,I8/'Tech Parameters'!E14) -> 56.666667 | J16: =IF('Tech Parameters'!E14=0,0,J8/'Tech Parameters'!E14) -> 56.666667 | K16: =IF('Tech Parameters'!E14=0,0,K8/'Tech Parameters'!E14) -> 56.666667 | L16: =IF('Tech Parameters'!E14=0,0,L8/'Tech Parameters'!E14) -> 56.666667 | M16: =IF('Tech Parameters'!E14=0,0,M8/'Tech Parameters'!E14) -> 56.666667 | N16: =IF('Tech Parameters'!E14=0,0,N8/'Tech Parameters'!E14) -> 56.666667
A17: Electricity | B17: $/GJ svc | C17: =IF('Tech Parameters'!E15=0,0,C9/'Tech Parameters'!E15) -> 25.882353 | D17: =IF('Tech Parameters'!E15=0,0,D9/'Tech Parameters'!E15) -> 25.882353 | E17: =IF('Tech Parameters'!E15=0,0,E9/'Tech Parameters'!E15) -> 25.882353 | F17: =IF('Tech Parameters'!E15=0,0,F9/'Tech Parameters'!E15) -> 25.882353 | G17: =IF('Tech Parameters'!E15=0,0,G9/'Tech Parameters'!E15) -> 25.882353 | H17: =IF('Tech Parameters'!E15=0,0,H9/'Tech Parameters'!E15) -> 25.882353 | I17: =IF('Tech Parameters'!E15=0,0,I9/'Tech Parameters'!E15) -> 25.882353 | J17: =IF('Tech Parameters'!E15=0,0,J9/'Tech Parameters'!E15) -> 25.882353 | K17: =IF('Tech Parameters'!E15=0,0,K9/'Tech Parameters'!E15) -> 25.882353 | L17: =IF('Tech Parameters'!E15=0,0,L9/'Tech Parameters'!E15) -> 25.882353 | M17: =IF('Tech Parameters'!E15=0,0,M9/'Tech Parameters'!E15) -> 25.882353 | N17: =IF('Tech Parameters'!E15=0,0,N9/'Tech Parameters'!E15) -> 25.882353
A18: RE generation | B18: $/GJ svc | C18: =IF('Tech Parameters'!E16=0,0,C10/'Tech Parameters'!E16) -> 0 | D18: =IF('Tech Parameters'!E16=0,0,D10/'Tech Parameters'!E16) -> 0 | E18: =IF('Tech Parameters'!E16=0,0,E10/'Tech Parameters'!E16) -> 0 | F18: =IF('Tech Parameters'!E16=0,0,F10/'Tech Parameters'!E16) -> 0 | G18: =IF('Tech Parameters'!E16=0,0,G10/'Tech Parameters'!E16) -> 0 | H18: =IF('Tech Parameters'!E16=0,0,H10/'Tech Parameters'!E16) -> 0 | I18: =IF('Tech Parameters'!E16=0,0,I10/'Tech Parameters'!E16) -> 0 | J18: =IF('Tech Parameters'!E16=0,0,J10/'Tech Parameters'!E16) -> 0 | K18: =IF('Tech Parameters'!E16=0,0,K10/'Tech Parameters'!E16) -> 0 | L18: =IF('Tech Parameters'!E16=0,0,L10/'Tech Parameters'!E16) -> 0 | M18: =IF('Tech Parameters'!E16=0,0,M10/'Tech Parameters'!E16) -> 0 | N18: =IF('Tech Parameters'!E16=0,0,N10/'Tech Parameters'!E16) -> 0
A20: ROAD TRANSPORT — CES Cost Index
C22: =IF(C13=0,0,C13^(1-'Tech Parameters'!$B$5)) -> 0 | D22: =IF(D13=0,0,D13^(1-'Tech Parameters'!$B$5)) -> 0 | E22: =IF(E13=0,0,E13^(1-'Tech Parameters'!$B$5)) -> 0 | F22: =IF(F13=0,0,F13^(1-'Tech Parameters'!$B$5)) -> 0 | G22: =IF(G13=0,0,G13^(1-'Tech Parameters'!$B$5)) -> 0 | H22: =IF(H13=0,0,H13^(1-'Tech Parameters'!$B$5)) -> 0 | I22: =IF(I13=0,0,I13^(1-'Tech Parameters'!$B$5)) -> 0 | J22: =IF(J13=0,0,J13^(1-'Tech Parameters'!$B$5)) -> 0 | ... N22: =IF(N13=0,0,N13^(1-'Tech Parameters'!$B$5)) -> 0
C23: =IF(C14=0,0,C14^(1-'Tech Parameters'!$B$5)) -> 0.1767767 | D23: =IF(D14=0,0,D14^(1-'Tech Parameters'!$B$5)) -> 0.1767767 | E23: =IF(E14=0,0,E14^(1-'Tech Parameters'!$B$5)) -> 0.1767767 | F23: =IF(F14=0,0,F14^(1-'Tech Parameters'!$B$5)) -> 0.1767767 | G23: =IF(G14=0,0,G14^(1-'Tech Parameters'!$B$5)) -> 0.1767767 | H23: =IF(H14=0,0,H14^(1-'Tech Parameters'!$B$5)) -> 0.1767767 | I23: =IF(I14=0,0,I14^(1-'Tech Parameters'!$B$5)) -> 0.1767767 | J23: =IF(J14=0,0,J14^(1-'Tech Parameters'!$B$5)) -> 0.1767767 | ... N23: =IF(N14=0,0,N14^(1-'Tech Parameters'!$B$5)) -> 0.1767767
C24: =IF(C15=0,0,C15^(1-'Tech Parameters'!$B$5)) -> 0.11785113 | D24: =IF(D15=0,0,D15^(1-'Tech Parameters'!$B$5)) -> 0.11785113 | E24: =IF(E15=0,0,E15^(1-'Tech Parameters'!$B$5)) -> 0.11785113 | F24: =IF(F15=0,0,F15^(1-'Tech Parameters'!$B$5)) -> 0.11785113 | G24: =IF(G15=0,0,G15^(1-'Tech Parameters'!$B$5)) -> 0.11785113 | H24: =IF(H15=0,0,H15^(1-'Tech Parameters'!$B$5)) -> 0.11785113 | I24: =IF(I15=0,0,I15^(1-'Tech Parameters'!$B$5)) -> 0.11785113 | J24: =IF(J15=0,0,J15^(1-'Tech Parameters'!$B$5)) -> 0.11785113 | ... N24: =IF(N15=0,0,N15^(1-'Tech Parameters'!$B$5)) -> 0.11785113
C25: =IF(C16=0,0,C16^(1-'Tech Parameters'!$B$5)) -> 0.13284223 | D25: =IF(D16=0,0,D16^(1-'Tech Parameters'!$B$5)) -> 0.13284223 | E25: =IF(E16=0,0,E16^(1-'Tech Parameters'!$B$5)) -> 0.13284223 | F25: =IF(F16=0,0,F16^(1-'Tech Parameters'!$B$5)) -> 0.13284223 | G25: =IF(G16=0,0,G16^(1-'Tech Parameters'!$B$5)) -> 0.13284223 | H25: =IF(H16=0,0,H16^(1-'Tech Parameters'!$B$5)) -> 0.13284223 | I25: =IF(I16=0,0,I16^(1-'Tech Parameters'!$B$5)) -> 0.13284223 | J25: =IF(J16=0,0,J16^(1-'Tech Parameters'!$B$5)) -> 0.13284223 | ... N25: =IF(N16=0,0,N16^(1-'Tech Parameters'!$B$5)) -> 0.13284223
C26: =IF(C17=0,0,C17^(1-'Tech Parameters'!$B$5)) -> 0.19656135 | D26: =IF(D17=0,0,D17^(1-'Tech Parameters'!$B$5)) -> 0.19656135 | E26: =IF(E17=0,0,E17^(1-'Tech Parameters'!$B$5)) -> 0.19656135 | F26: =IF(F17=0,0,F17^(1-'Tech Parameters'!$B$5)) -> 0.19656135 | G26: =IF(G17=0,0,G17^(1-'Tech Parameters'!$B$5)) -> 0.19656135 | H26: =IF(H17=0,0,H17^(1-'Tech Parameters'!$B$5)) -> 0.19656135 | I26: =IF(I17=0,0,I17^(1-'Tech Parameters'!$B$5)) -> 0.19656135 | J26: =IF(J17=0,0,J17^(1-'Tech Parameters'!$B$5)) -> 0.19656135 | ... N26: =IF(N17=0,0,N17^(1-'Tech Parameters'!$B$5)) -> 0.19656135
C27: =IF(C18=0,0,C18^(1-'Tech Parameters'!$B$5)) -> 0 | D27: =IF(D18=0,0,D18^(1-'Tech Parameters'!$B$5)) -> 0 | E27: =IF(E18=0,0,E18^(1-'Tech Parameters'!$B$5)) -> 0 | F27: =IF(F18=0,0,F18^(1-'Tech Parameters'!$B$5)) -> 0 | G27: =IF(G18=0,0,G18^(1-'Tech Parameters'!$B$5)) -> 0 | H27: =IF(H18=0,0,H18^(1-'Tech Parameters'!$B$5)) -> 0 | I27: =IF(I18=0,0,I18^(1-'Tech Parameters'!$B$5)) -> 0 | J27: =IF(J18=0,0,J18^(1-'Tech Parameters'!$B$5)) -> 0 | ... N27: =IF(N18=0,0,N18^(1-'Tech Parameters'!$B$5)) -> 0
C28: ='Tech Parameters'!J11 -> 0 | D28: ='Tech Parameters'!J12 -> 0.0055452865 | E28: ='Tech Parameters'!J13 -> 0.54066543 | F28: ='Tech Parameters'!J14 -> 0.39279113 | G28: ='Tech Parameters'!J15 -> 0.060998152 | H28: ='Tech Parameters'!J16 -> 0
A29: C(t) | B29: $/GJ svc | C29: =(C28*C22+D28*C23+E28*C24+F28*C25+G28*C26+H28*C27)^(1/(1-'Tech Parameters'!$B$5)) -> 60.216236 | D29: =(C28*D22+D28*D23+E28*D24+F28*D25+G28*D26+H28*D27)^(1/(1-'Tech Parameters'!$B$5)) -> 60.216236 | E29: =(C28*E22+D28*E23+E28*E24+F28*E25+G28*E26+H28*E27)^(1/(1-'Tech Parameters'!$B$5)) -> 60.216236 | F29: =(C28*F22+D28*F23+E28*F24+F28*F25+G28*F26+H28*F27)^(1/(1-'Tech Parameters'!$B$5)) -> 60.216236 | G29: =(C28*G22+D28*G23+E28*G24+F28*G25+G28*G26+H28*G27)^(1/(1-'Tech Parameters'!$B$5)) -> 60.216236 | H29: =(C28*H22+D28*H23+E28*H24+F28*H25+G28*H26+H28*H27)^(1/(1-'Tech Parameters'!$B$5)) -> 60.216236 | I29: =(C28*I22+D28*I23+E28*I24+F28*I25+G28*I26+H28*I27)^(1/(1-'Tech Parameters'!$B$5)) -> 60.216236 | J29: =(C28*J22+D28*J23+E28*J24+F28*J25+G28*J26+H28*J27)^(1/(1-'Tech Parameters'!$B$5)) -> 60.216236 | K29: =(C28*K22+D28*K23+E28*K24+F28*K25+G28*K26+H28*K27)^(1/(1-'Tech Parameters'!$B$5)) -> 60.216236 | L29: =(C28*L22+D28*L23+E28*L24+F28*L25+G28*L26+H28*L27)^(1/(1-'Tech Parameters'!$B$5)) -> 60.216236 | M29: =(C28*M22+D28*M23+E28*M24+F28*M25+G28*M26+H28*M27)^(1/(1-'Tech Parameters'!$B$5)) -> 60.216236 | N29: =(C28*N22+D28*N23+E28*N24+F28*N25+G28*N26+H28*N27)^(1/(1-'Tech Parameters'!$B$5)) -> 60.216236
A31: ROAD TRANSPORT — Equilibrium Quantities (PJ)
A32: Coal | B32: PJ | C32: ='Tech Parameters'!D11 -> 0 | D32: =IF(OR(D13=0,C13=0),C41,C41*(D13/C13)^(-'Tech Parameters'!$B$5)*(D29/C29)^('Tech Parameters'!$B$5+'Tech Parameters'!$B$6)) -> 0 | E32: =IF(OR(E13=0,D13=0),D41,D41*(E13/D13)^(-'Tech Parameters'!$B$5)*(E29/D29)^('Tech Parameters'!$B$5+'Tech Parameters'!$B$6)) -> 0 | F32: =IF(OR(F13=0,E13=0),E41,E41*(F13/E13)^(-'Tech Parameters'!$B$5)*(F29/E29)^('Tech Parameters'!$B$5+'Tech Parameters'!$B$6)) -> 0 | G32: =IF(OR(G13=0,F13=0),F41,F41*(G13/F13)^(-'Tech Parameters'!$B$5)*(G29/F29)^('Tech Parameters'!$B$5+'Tech Parameters'!$B$6)) -> 0 | H32: =IF(OR(H13=0,G13=0),G41,G41*(H13/G13)^(-'Tech Parameters'!$B$5)*(H29/G29)^('Tech Parameters'!$B$5+'Tech Parameters'!$B$6)) -> 0 | I32: =IF(OR(I13=0,H13=0),H41,H41*(I13/H13)^(-'Tech Parameters'!$B$5)*(I29/H29)^('Tech Parameters'!$B$5+'Tech Parameters'!$B$6)) -> 0 | J32: =IF(OR(J13=0,I13=0),I41,I41*(J13/I13)^(-'Tech Parameters'!$B$5)*(J29/I29)^('Tech Parameters'!$B$5+'Tech Parameters'!$B$6)) -> 0 | K32: =IF(OR(K13=0,J13=0),J41,J41*(K13/J13)^(-'Tech Parameters'!$B$5)*(K29/J29)^('Tech Parameters'!$B$5+'Tech Parameters'!$B$6)) -> 0 | ... N32: =IF(OR(N13=0,M13=0),M41,M41*(N13/M13)^(-'Tech Parameters'!$B$5)*(N29/M29)^('Tech Parameters'!$B$5+'Tech Parameters'!$B$6)) -> 0
A33: Natural gas | B33: PJ | C33: ='Tech Parameters'!D12 -> 15 | D33: =IF(OR(D14=0,C14=0),C42,C42*(D14/C14)^(-'Tech Parameters'!$B$5)*(D29/C29)^('Tech Parameters'!$B$5+'Tech Parameters'!$B$6)) -> 15 | E33: =IF(OR(E14=0,D14=0),D42,D42*(E14/D14)^(-'Tech Parameters'!$B$5)*(E29/D29)^('Tech Parameters'!$B$5+'Tech Parameters'!$B$6)) -> 15 | F33: =IF(OR(F14=0,E14=0),E42,E42*(F14/E14)^(-'Tech Parameters'!$B$5)*(F29/E29)^('Tech Parameters'!$B$5+'Tech Parameters'!$B$6)) -> 15 | G33: =IF(OR(G14=0,F14=0),F42,F42*(G14/F14)^(-'Tech Parameters'!$B$5)*(G29/F29)^('Tech Parameters'!$B$5+'Tech Parameters'!$B$6)) -> 15 | H33: =IF(OR(H14=0,G14=0),G42,G42*(H14/G14)^(-'Tech Parameters'!$B$5)*(H29/G29)^('Tech Parameters'!$B$5+'Tech Parameters'!$B$6)) -> 15 | I33: =IF(OR(I14=0,H14=0),H42,H42*(I14/H14)^(-'Tech Parameters'!$B$5)*(I29/H29)^('Tech Parameters'!$B$5+'Tech Parameters'!$B$6)) -> 15 | J33: =IF(OR(J14=0,I14=0),I42,I42*(J14/I14)^(-'Tech Parameters'!$B$5)*(J29/I29)^('Tech Parameters'!$B$5+'Tech Parameters'!$B$6)) -> 15 | K33: =IF(OR(K14=0,J14=0),J42,J42*(K14/J14)^(-'Tech Parameters'!$B$5)*(K29/J29)^('Tech Parameters'!$B$5+'Tech Parameters'!$B$6)) -> 15 | ... N33: =IF(OR(N14=0,M14=0),M42,M42*(N14/M14)^(-'Tech Parameters'!$B$5)*(N29/M29)^('Tech Parameters'!$B$5+'Tech Parameters'!$B$6)) -> 15
A34: Gasoline | B34: PJ | C34: ='Tech Parameters'!D13 -> 650 | D34: =IF(OR(D15=0,C15=0),C43,C43*(D15/C15)^(-'Tech Parameters'!$B$5)*(D29/C29)^('Tech Parameters'!$B$5+'Tech Parameters'!$B$6)) -> 650 | E34: =IF(OR(E15=0,D15=0),D43,D43*(E15/D15)^(-'Tech Parameters'!$B$5)*(E29/D29)^('Tech Parameters'!$B$5+'Tech Parameters'!$B$6)) -> 650 | F34: =IF(OR(F15=0,E15=0),E43,E43*(F15/E15)^(-'Tech Parameters'!$B$5)*(F29/E29)^('Tech Parameters'!$B$5+'Tech Parameters'!$B$6)) -> 650 | G34: =IF(OR(G15=0,F15=0),F43,F43*(G15/F15)^(-'Tech Parameters'!$B$5)*(G29/F29)^('Tech Parameters'!$B$5+'Tech Parameters'!$B$6)) -> 650 | H34: =IF(OR(H15=0,G15=0),G43,G43*(H15/G15)^(-'Tech Parameters'!$B$5)*(H29/G29)^('Tech Parameters'!$B$5+'Tech Parameters'!$B$6)) -> 650 | I34: =IF(OR(I15=0,H15=0),H43,H43*(I15/H15)^(-'Tech Parameters'!$B$5)*(I29/H29)^('Tech Parameters'!$B$5+'Tech Parameters'!$B$6)) -> 650 | J34: =IF(OR(J15=0,I15=0),I43,I43*(J15/I15)^(-'Tech Parameters'!$B$5)*(J29/I29)^('Tech Parameters'!$B$5+'Tech Parameters'!$B$6)) -> 650 | K34: =IF(OR(K15=0,J15=0),J43,J43*(K15/J15)^(-'Tech Parameters'!$B$5)*(K29/J29)^('Tech Parameters'!$B$5+'Tech Parameters'!$B$6)) -> 650 | ... N34: =IF(OR(N15=0,M15=0),M43,M43*(N15/M15)^(-'Tech Parameters'!$B$5)*(N29/M29)^('Tech Parameters'!$B$5+'Tech Parameters'!$B$6)) -> 650
A35: Diesel | B35: PJ | C35: ='Tech Parameters'!D14 -> 500 | D35: =IF(OR(D16=0,C16=0),C44,C44*(D16/C16)^(-'Tech Parameters'!$B$5)*(D29/C29)^('Tech Parameters'!$B$5+'Tech Parameters'!$B$6)) -> 500 | E35: =IF(OR(E16=0,D16=0),D44,D44*(E16/D16)^(-'Tech Parameters'!$B$5)*(E29/D29)^('Tech Parameters'!$B$5+'Tech Parameters'!$B$6)) -> 500 | F35: =IF(OR(F16=0,E16=0),E44,E44*(F16/E16)^(-'Tech Parameters'!$B$5)*(F29/E29)^('Tech Parameters'!$B$5+'Tech Parameters'!$B$6)) -> 500 | G35: =IF(OR(G16=0,F16=0),F44,F44*(G16/F16)^(-'Tech Parameters'!$B$5)*(G29/F29)^('Tech Parameters'!$B$5+'Tech Parameters'!$B$6)) -> 500 | H35: =IF(OR(H16=0,G16=0),G44,G44*(H16/G16)^(-'Tech Parameters'!$B$5)*(H29/G29)^('Tech Parameters'!$B$5+'Tech Parameters'!$B$6)) -> 500 | I35: =IF(OR(I16=0,H16=0),H44,H44*(I16/H16)^(-'Tech Parameters'!$B$5)*(I29/H29)^('Tech Parameters'!$B$5+'Tech Parameters'!$B$6)) -> 500 | J35: =IF(OR(J16=0,I16=0),I44,I44*(J16/I16)^(-'Tech Parameters'!$B$5)*(J29/I29)^('Tech Parameters'!$B$5+'Tech Parameters'!$B$6)) -> 500 | K35: =IF(OR(K16=0,J16=0),J44,J44*(K16/J16)^(-'Tech Parameters'!$B$5)*(K29/J29)^('Tech Parameters'!$B$5+'Tech Parameters'!$B$6)) -> 500 | ... N35: =IF(OR(N16=0,M16=0),M44,M44*(N16/M16)^(-'Tech Parameters'!$B$5)*(N29/M29)^('Tech Parameters'!$B$5+'Tech Parameters'!$B$6)) -> 500
