Workbook
Name CountrySelector: CBAM!$B$5
Name CovS1fc: CBAM!$B$11
Name CovS1fp: CBAM!$B$12
Name CovS1no: CBAM!$B$14
Name CovS1np: CBAM!$B$13
Name CovS2: CBAM!$B$15
Name DetailYear: CBAM!$B$6
Name ExportsOnly: CBAM!$B$22
Name MRVmaster: CBAM!$B$19
Name Theta: CBAM!$B$7
Name Version: version!$A$3
Name YearIdx: CBAM!$P$6

Sheet Guide
A1: Pass 8 — Explainer & Legend
A2: What this workbook does, how the levers work, and how to read each sheet.
A4: 1. What this workbook models
B6: Scope | C6: 5 countries (Egypt, Albania, Uzbekistan, Azerbaijan, India) × 8 CBAM-eligible products × 12 years (2024–2035). Tracks production, exports, emissions across 5 scope buckets, EU CBAM obligations, and optimal country-level carbon-pricing responses.
B7: Products | C7: DRI-EAF steel, Scrap-EAF steel, BF-BOF steel, Cement, Ammonia, Urea, Ammonium nitrate, Primary aluminium. BF-BOF appears in all countries' production matrices; only India has non-zero base BF-BOF capacity at this stage.
B8: Five scope buckets | C8: S1.fc — fuel combustion CO₂ (boilers, kilns, heat). S1.fp — fuel-as-reductant CO₂ (BF coke + PCI, DRI shaft NG, SMR reformer NG). S1.np — non-fuel process CO₂ (cement calcination, anode oxidation, urea CO₂ uptake). S1.no — non-CO₂ GHG in CO₂e (N₂O from HNO₃, PFCs from Hall-Héroult cells). S2 — electricity (indirect via grid).
B9: Coverage flags | C9: Each scope has an independent on/off flag on the dashboard (2a, cells B11–B15). These say what the country's domestic CP is levied on. They do NOT change the regulatory definition of CBAM scope — that's controlled by the cs2 flag per product (EU Reg 2023/956 Annex II: cs2=0 for iron/steel and aluminium; cs2=1 for cement and fertilisers).
A11: 2. What's new in Pass 8
B13: Finalised CBAM benchmarks | C13: Implementing Regulation (EU) 2025/2621 adopted 16 Dec 2025. Benchmarks for the default-value pathway (column B): BF-BOF 1.370 (was 1.530), DRI-EAF 0.481 (was 1.033), Scrap-EAF 0.072 (was 0.288), Cement clinker 0.666 (was 0.693), Ammonia 1.522 (unchanged), Urea 0.902 (unchanged), Aluminium 1.423 (was 1.484). The scrap benchmark drop is the largest in proportional terms and ratchets recycled steel firmly into the CBAM net even at low actual intensities. EU default values reset to ~20% above the new benchmark.
B14: Declining grid emission factors | C14: Grid EFs are now 12-year time series rather than constants, declining linearly in line with each country's NDC trajectory. Egypt 0.510 → 0.400 (NDC 42% RE by 2030); Albania 0.045 → 0.035 (already low from hydro); Uzbekistan 0.540 → 0.420 (40% RE by 2035); Azerbaijan 0.460 → 0.370 (30% RE by 2030); India 0.713 → 0.500 (60% non-fossil by 2035 NDC). The s2e formula now resolves the year-indexed value; everything downstream — intensities, CBAM obligation, optimal CP — responds automatically.
A16: 3. Carried over from Pass 7
B18: India added | C18: Fifth country with realistic 2024 production: ~150 Mt crude steel (110 BF-BOF, 32 DRI-EAF, 8 scrap), 440 Mt cement, 17 Mt NH₃, 30 Mt urea, 4.1 Mt aluminium.
B19: BF-BOF integrated | C19: BF-BOF steel is a regular entity in every country's matrix (energy intensity rows, emissions rows, intensity matrix). India is currently the only country with non-zero BF-BOF base capacity; structure exists for all.
B20: 5-scope coverage flags | C20: Independent on/off flags per scope (2a on dashboard). Replaces the previous A/B/C aggregation.
B21: Global MRV per product | C21: Single row B19:I19 on dashboard, one cell per product. Applies to all 5 countries. MRV=0 falls back to the EU default value.
B22: Exports-only tax toggle | C22: B22: when 1, the country's CP is levied only on exports (EU + non-EU). Useful for politically-constrained pricing.
B23: NH₃ chain transparency | C23: Section 8 of dashboard makes the upstream ammonia chain visible. Only direct emissions of ammonia cascade into urea/AN; S2 of ammonia is shown but NOT cascaded — each downstream product accounts for its own electricity.
B24: EF matrix display | C24: Section 6: fuel emission factors (IPCC 2006) and per-product calculated intensities for the selected country, alongside EU benchmarks and default values.
A26: 4. Key levers — what to move first
B28: B5 — country | C28: Pick from egy/alb/uzb/aze/ind. Everything redraws.
B29: B6 — detail year | C29: Year for Section 5 (price impact) and Section 6b (per-product intensities). Other sections show full 12-year series.
B30: B7 — pass-through θ | C30: Share of wedge passed to buyer prices vs absorbed by producer margins. Default 0.7.
B31: B11–B15 — coverage flags | C31: Independent on/off for fc, fp, np, no, s2. Whether S2 is credited against CBAM is separately gated by the cs2 regulatory flag per product (row 20).
B32: B19:I19 — MRV per product | C32: 1 if exporter has actual MRV data; 0 to use EU default. Global per product.
B33: B22 — exports-only tax | C33: 0: CP levied on all production. 1: only on exports.
B34: Row 29 — domestic CP | C34: Defaults to optimal CP from row 28 (the level that exactly captures the CBAM gross). Edit to test sub-optimal or over-shooting pricing.
A36: 5. Sheets in this workbook
B38: dashboard | C38: Inputs and headline outputs. Sections 1-4 are the policy control panel; Sections 5-8 are diagnostic views of the selected country at the detail year.
B39: explainer | C39: This sheet — overview, lever guide, and methodology notes.
B40: input_data | C40: 1,053 rows keyed by code (cty.dom.par.sec.prc.sub). Universal time series, fuel EFs, per-entity constants (now with finalised benchmarks), country-level constants (grid EFs now time series), 5 country × 8 product blocks.
B41: calculations | C41: 284 rows. Country-aware (pulls from CBAM!B5). Uniform per-entity block. s2e formula now resolves year-indexed grid EF.
A43: 6. Methodology notes
B45: Two CBAM benchmark columns | C45: EU Reg 2025/2621 specifies separate benchmarks for column A (use with actual measured data) and column B (use with default values). The workbook uses column B for the default-value pathway when MRV=0 and treats the same benchmark consistently when MRV=1 — a simplification but adequate for first-pass policy analysis.
B46: CBAM factor schedule | C46: EU Reg 2025/2620: 2.5% 2026, 5% 2027, 10% 2028, 22.5% 2029, 48.5% 2030, 61% 2031, 73.5% 2032, 86% 2033, 100% 2034. The factor is the share of certificates that must be purchased (= 1 minus free allocation share).
B47: CBAM scope per product (cs2) | C47: EU Reg 2023/956 Annex II: direct + indirect (S2) for cement, fertilisers, hydrogen. Direct only for iron & steel and aluminium. The cs2 row in section 2b shows the regulatory scope; it gates whether S2 contributes to creditability against CBAM.
B48: NH₃ chain accounting | C48: Upstream ammonia feedstock embedded in urea (0.567 t NH₃/t) and AN (0.213 t NH₃/t). Only ammonia's direct emissions cascade — S2 is NOT cascaded because each downstream product accounts for its own electricity via its own S2 row. This avoids double-counting.
B49: Optimal carbon price | C49: Row 28: country-level CP that exactly captures the CBAM gross as country revenue. Derived analytically as CBAM_gross / (Σ EU_exports × creditable_intensity), where creditable intensity sums the scopes that are BOTH covered by the CP AND in CBAM scope.
B50: Revenue accounting | C50: Country revenue = (CP × covered_intensity) × (EU + non-EU exports + domestic × (1−exports_only)). CBAM credit = (CP × creditable_intensity × EU exports). EU net = MAX(CBAM_gross − credit, 0). Total pool = country revenue + EU net.
B51: Grid EF trajectories | C51: Linear interpolation between 2024 anchors (IEA Emission Factors 2025) and 2035 end-points consistent with NDC commitments. Egypt and Uzbekistan trajectories reflect modest decarbonisation; India's reflects its accelerating non-fossil capacity build-out.
A53: 7. Key regulatory references
...

Sheet CBAM
A1: ="CPAT Policy Dashboard — "&Version -> CPAT Policy Dashboard — v1.6
A2: 5 countries × 8 products × 12 years. 5-scope coverage flags, global MRV per product, exports-only tax option, BF-BOF integrated, NH₃ chain explicitly accounted, EF matrix included.
A4: 1. COUNTRY & VIEW SETTINGS
A5: Country selector | B5: egy | C5: → | D5: Choose from: egy, alb, uzb, aze, ind.
A6: Detail year (for price-impact table) | B6: 2030 | C6: → | D6: Year for the price-impact section. | P6: =MATCH(TEXT($B$6,"0"),input_data!$M$3:$X$3,0) -> 7
A7: Pass-through θ (share of wedge to buyer prices) | B7: 0.7 | C7: → | D7: Share of carbon wedge passed to buyers (rest hits producer margins).
A9: 2. POLICY CHOICES
A10: 2a. Coverage flags — what the domestic CP is levied on (1 = covered, 0 = not)
A11: Coverage S1.fc (Scope 1 — Fuel combustion CO₂) | B11: 1 | C11: → | D11: Combustion fuels (heat, steam).
A12: Coverage S1.fp (Scope 1 — Fuel-as-reductant CO₂) | B12: 1 | C12: → | D12: Fuel-as-reductant (BF coke + PCI, DRI shaft NG, SMR reformer NG).
A13: Coverage S1.np (Scope 1 — Non-fuel process CO₂) | B13: 1 | C13: → | D13: Calcination CO₂ (cement, anode), urea CO₂ uptake (negative for urea).
A14: Coverage S1.no (Scope 1 — Non-CO₂ GHG (CO₂e)) | B14: 1 | C14: → | D14: N₂O from HNO₃, PFCs from Hall-Héroult.
A15: Coverage S2 (Scope 2 — Electricity (indirect)) | B15: 1 | C15: → | D15: Indirect electricity emissions.
A17: 2b. MRV per product (global — applies to all countries; 1 = MRV verified, EU uses actual)
A18: Product → | B18: DRI | C18: Scrap | D18: BF-BOF | E18: Cement | F18: NH₃ | G18: Urea | H18: AN | I18: Al
A19: MRV flag (edit here): | B19: 1 | C19: 1 | D19: 1 | E19: 1 | F19: 1 | G19: 1 | H19: 1 | I19: 1
A20: CBAM S2 scope (reg., Annex II = 0): | B20: =INDEX(input_data!$L:$L,MATCH("all.in.cs2.stl.drg.---",input_data!$A:$A,0)) -> 0 | C20: =INDEX(input_data!$L:$L,MATCH("all.in.cs2.stl.scr.---",input_data!$A:$A,0)) -> 0 | D20: =INDEX(input_data!$L:$L,MATCH("all.in.cs2.stl.bof.---",input_data!$A:$A,0)) -> 0 | E20: =INDEX(input_data!$L:$L,MATCH("all.in.cs2.cmt.dry.---",input_data!$A:$A,0)) -> 1 | F20: =INDEX(input_data!$L:$L,MATCH("all.in.cs2.frt.amc.---",input_data!$A:$A,0)) -> 1 | G20: =INDEX(input_data!$L:$L,MATCH("all.in.cs2.frt.ure.---",input_data!$A:$A,0)) -> 1 | H20: =INDEX(input_data!$L:$L,MATCH("all.in.cs2.frt.nit.---",input_data!$A:$A,0)) -> 1 | I20: =INDEX(input_data!$L:$L,MATCH("all.in.cs2.alu.prp.---",input_data!$A:$A,0)) -> 0
A22: 2c. Tax only exports? (1 = yes — no domestic CP on home consumption; 0 = no) | B22: 0 | C22: → | D22: When 1, the country's CP is levied only on EU + non-EU exports (not on domestic-consumed product). Useful for politically-constrained pricing.
A24: 3. CARBON PRICE TIME SERIES
A25: row | B25: unit | D25: 2024 | E25: 2025 | F25: 2026 | G25: 2027 | H25: 2028 | I25: 2029 | J25: 2030 | K25: 2031 | L25: 2032 | M25: 2033 | N25: 2034 | O25: 2035
A26: EU ETS price | B26: EUR/tCO2 | D26: =INDEX(input_data!$M:$X,MATCH("all.in.ets.---.---.---",input_data!$A:$A,0),1) -> 85 | E26: =INDEX(input_data!$M:$X,MATCH("all.in.ets.---.---.---",input_data!$A:$A,0),2) -> 90 | F26: =INDEX(input_data!$M:$X,MATCH("all.in.ets.---.---.---",input_data!$A:$A,0),3) -> 100 | G26: =INDEX(input_data!$M:$X,MATCH("all.in.ets.---.---.---",input_data!$A:$A,0),4) -> 105 | H26: =INDEX(input_data!$M:$X,MATCH("all.in.ets.---.---.---",input_data!$A:$A,0),5) -> 110 | I26: =INDEX(input_data!$M:$X,MATCH("all.in.ets.---.---.---",input_data!$A:$A,0),6) -> 110 | J26: =INDEX(input_data!$M:$X,MATCH("all.in.ets.---.---.---",input_data!$A:$A,0),7) -> 115 | K26: =INDEX(input_data!$M:$X,MATCH("all.in.ets.---.---.---",input_data!$A:$A,0),8) -> 120 | L26: =INDEX(input_data!$M:$X,MATCH("all.in.ets.---.---.---",input_data!$A:$A,0),9) -> 125 | M26: =INDEX(input_data!$M:$X,MATCH("all.in.ets.---.---.---",input_data!$A:$A,0),10) -> 130 | N26: =INDEX(input_data!$M:$X,MATCH("all.in.ets.---.---.---",input_data!$A:$A,0),11) -> 135 | O26: =INDEX(input_data!$M:$X,MATCH("all.in.ets.---.---.---",input_data!$A:$A,0),12) -> 140
A27: CBAM factor | B27: fraction | D27: =INDEX(input_data!$M:$X,MATCH("all.in.cbf.---.---.---",input_data!$A:$A,0),1) -> 0 | E27: =INDEX(input_data!$M:$X,MATCH("all.in.cbf.---.---.---",input_data!$A:$A,0),2) -> 0 | F27: =INDEX(input_data!$M:$X,MATCH("all.in.cbf.---.---.---",input_data!$A:$A,0),3) -> 0.025 | G27: =INDEX(input_data!$M:$X,MATCH("all.in.cbf.---.---.---",input_data!$A:$A,0),4) -> 0.05 | H27: =INDEX(input_data!$M:$X,MATCH("all.in.cbf.---.---.---",input_data!$A:$A,0),5) -> 0.1 | I27: =INDEX(input_data!$M:$X,MATCH("all.in.cbf.---.---.---",input_data!$A:$A,0),6) -> 0.225 | J27: =INDEX(input_data!$M:$X,MATCH("all.in.cbf.---.---.---",input_data!$A:$A,0),7) -> 0.485 | K27: =INDEX(input_data!$M:$X,MATCH("all.in.cbf.---.---.---",input_data!$A:$A,0),8) -> 0.61 | L27: =INDEX(input_data!$M:$X,MATCH("all.in.cbf.---.---.---",input_data!$A:$A,0),9) -> 0.735 | M27: =INDEX(input_data!$M:$X,MATCH("all.in.cbf.---.---.---",input_data!$A:$A,0),10) -> 0.86 | N27: =INDEX(input_data!$M:$X,MATCH("all.in.cbf.---.---.---",input_data!$A:$A,0),11) -> 1 | O27: =INDEX(input_data!$M:$X,MATCH("all.in.cbf.---.---.---",input_data!$A:$A,0),12) -> 1
A28: ↓ OPTIMAL CP (captures full CBAM as country revenue) | B28: USD/tCO2 | D28: =IFERROR((IFERROR(calculations!M21*calculations!M248,0)+IFERROR(calculations!M49*calculations!M253,0)+IFERROR(calculations!M77*calculations!M258,0)+IFERROR(calculations!M105*calculations!M263,0)+IFERROR(calculations!M133*calculations!M268,0)+IFERROR(calculations!M161*calculations!M273,0)+IFERROR(calculations!M189*calculations!M278,0)+IFERROR(calculations!M217*calculations!M283,0)+IFERROR(calculations!M287*calculations!M316,0)+IFERROR(calculations!M319*calculations!M348,0))/(IFERROR(calculations!M21/calculations!M20*((calculations!M41+calculations!M244)*$B$11+calculations!M42*$B$12+calculations!M43*$B$13+calculations!M44*$B$14+calculations!M45*$B$15*INDEX(input_data!$L:$L,MATCH("all.in.cs2.stl.drg.---",input_data!$A:$A,0))),0)+IFERROR(calculations!M49/calculations!M48*((calculations!M69+calculations!M249)*$B$11+calculations!M70*$B$12+calculations!M71*$B$13+calculations!M72*$B$14+calculations!M73*$B$15*INDEX(input_data!$L:$L,MATCH("all.in.cs2.stl.scr.---",input_data!$A:$A,0))),0)+IFERROR(calculations!M77/calculations!M76*((calculations!M97+calculations!M254)*$B$11+calculations!M98*$B$12+calculations!M99*$B$13+calculations!M100*$B$14+calculations!M101*$B$15*INDEX(input_data!$L:$L,MATCH("all.in.cs2.stl.bof.---",input_data!$A:$A,0))),0)+IFERROR(calculations!M105/calculations!M104*((calculations!M125+calculations!M259)*$B$11+calculations!M126*$B$12+calculations!M127*$B$13+calculations!M128*$B$14+calculations!M129*$B$15*INDEX(input_data!$L:$L,MATCH("all.in.cs2.cmt.dry.---",input_data!$A:$A,0))),0)+IFERROR(calculations!M133/calculations!M132*((calculations!M153+calculations!M264)*$B$11+calculations!M154*$B$12+calculations!M155*$B$13+calculations!M156*$B$14+calculations!M157*$B$15*INDEX(input_data!$L:$L,MATCH("all.in.cs2.frt.amc.---",input_data!$A:$A,0))),0)+IFERROR(calculations!M161/calculations!M160*((calculations!M181+calculations!M269)*$B$11+calculations!M182*$B$12+calculations!M183*$B$13+calculations!M184*$B$14+calculations!M185*$B$15*INDEX(input_data!$L:$L,MATCH("all.in.cs2.frt.ure.---",input_data!$A:$A,0))),0)+IFERROR(calculations!M189/calculations!M188*((calculations!M209+calculations!M274)*$B$11+calculations!M210*$B$12+calculations!M211*$B$13+calculations!M212*$B$14+calculations!M213*$B$15*INDEX(input_data!$L:$L,MATCH("all.in.cs2.frt.nit.---",input_data!$A:$A,0))),0)+IFERROR(calculations!M217/calculations!M216*((calculations!M237+calculations!M279)*$B$11+calculations!M238*$B$12+calculations!M239*$B$13+calculations!M240*$B$14+calculations!M241*$B$15*INDEX(input_data!$L:$L,MATCH("all.in.cs2.alu.prp.---",input_data!$A:$A,0))),0)+IFERROR(calculations!M287/calculations!M286*((calculations!M307+calculations!M312)*$B$11+calculations!M308*$B$12+calculations!M309*$B$13+calculations!M310*$B$14+calculations!M311*$B$15*INDEX(input_data!$L:$L,MATCH("all.in.cs2.stl.oth.---",input_data!$A:$A,0))),0)+IFERROR(calculations!M319/calculations!M318*((calculations!M339+calculations!M344)*$B$11+calculations!M340*$B$12+calculations!M341*$B$13+calculations!M342*$B$14+calculations!M343*$B$15*INDEX(input_data!$L:$L,MATCH("all.in.cs2.frt.otn.---",input_data!$A:$A,0))),0)),0) -> 0 | E28: =IFERROR((IFERROR(calculations!N21*calculations!N248,0)+IFERROR(calculations!N49*calculations!N253,0)+IFERROR(calculations!N77*calculations!N258,0)+IFERROR(calculations!N105*calculations!N263,0)+IFERROR(calculations!N133*calculations!N268,0)+IFERROR(calculations!N161*calculations!N273,0)+IFERROR(calculations!N189*calculations!N278,0)+IFERROR(calculations!N217*calculations!N283,0)+IFERROR(calculations!N287*calculations!N316,0)+IFERROR(calculations!N319*calculations!N348,0))/(IFERROR(calculations!N21/calculations!N20*((calculations!N41+calculations!N244)*$B$11+calculations!N42*$B$12+calculations!N43*$B$13+calculations!N44*$B$14+calculations!N45*$B$15*INDEX(input_data!$L:$L,MATCH("all.in.cs2.stl.drg.---",input_data!$A:$A,0))),0)+IFERROR(calculations!N49/calculations!N48*((calculations!N69+calculations!N249)*$B$11+calculations!N70*$B$12+calculations!N71*$B$13+calculations!N72*$B$14+calculations!N73*$B$15*INDEX(input_data!$L:$L,MATCH("all.in.cs2.stl.scr.---",input_data!$A:$A,0))),0)+IFERROR(calculations!N77/calculations!N76*((calculations!N97+calculations!N254)*$B$11+calculations!N98*$B$12+calculations!N99*$B$13+calculations!N100*$B$14+calculations!N101*$B$15*INDEX(input_data!$L:$L,MATCH("all.in.cs2.stl.bof.---",input_data!$A:$A,0))),0)+IFERROR(calculations!N105/calculations!N104*((calculations!N125+calculations!N259)*$B$11+calculations!N126*$B$12+calculations!N127*$B$13+calculations!N128*$B$14+calculations!N129*$B$15*INDEX(input_data!$L:$L,MATCH("all.in.cs2.cmt.dry.---",input_data!$A:$A,0))),0)+IFERROR(calculations!N133/calculations!N132*((calculations!N153+calculations!N264)*$B$11+calculations!N154*$B$12+calculations!N155*$B$13+calculations!N156*$B$14+calculations!N157*$B$15*INDEX(input_data!$L:$L,MATCH("all.in.cs2.frt.amc.---",input_data!$A:$A,0))),0)+IFERROR(calculations!N161/calculations!N160*((calculations!N181+calculations!N269)*$B$11+calculations!N182*$B$12+calculations!N183*$B$13+calculations!N184*$B$14+calculations!N185*$B$15*INDEX(input_data!$L:$L,MATCH("all.in.cs2.frt.ure.---",input_data!$A:$A,0))),0)+IFERROR(calculations!N189/calculations!N188*((calculations!N209+calculations!N274)*$B$11+calculations!N210*$B$12+calculations!N211*$B$13+calculations!N212*$B$14+calculations!N213*$B$15*INDEX(input_data!$L:$L,MATCH("all.in.cs2.frt.nit.---",input_data!$A:$A,0))),0)+IFERROR(calculations!N217/calculations!N216*((calculations!N237+calculations!N279)*$B$11+calculations!N238*$B$12+calculations!N239*$B$13+calculations!N240*$B$14+calculations!N241*$B$15*INDEX(input_data!$L:$L,MATCH("all.in.cs2.alu.prp.---",input_data!$A:$A,0))),0)+IFERROR(calculations!N287/calculations!N286*((calculations!N307+calculations!N312)*$B$11+calculations!N308*$B$12+calculations!N309*$B$13+calculations!N310*$B$14+calculations!N311*$B$15*INDEX(input_data!$L:$L,MATCH("all.in.cs2.stl.oth.---",input_data!$A:$A,0))),0)+IFERROR(calculations!N319/calculations!N318*((calculations!N339+calculations!N344)*$B$11+calculations!N340*$B$12+calculations!N341*$B$13+calculations!N342*$B$14+calculations!N343*$B$15*INDEX(input_data!$L:$L,MATCH("all.in.cs2.frt.otn.---",input_data!$A:$A,0))),0)),0) -> 0 | F28: =IFERROR((IFERROR(calculations!O21*calculations!O248,0)+IFERROR(calculations!O49*calculations!O253,0)+IFERROR(calculations!O77*calculations!O258,0)+IFERROR(calculations!O105*calculations!O263,0)+IFERROR(calculations!O133*calculations!O268,0)+IFERROR(calculations!O161*calculations!O273,0)+IFERROR(calculations!O189*calculations!O278,0)+IFERROR(calculations!O217*calculations!O283,0)+IFERROR(calculations!O287*calculations!O316,0)+IFERROR(calculations!O319*calculations!O348,0))/(IFERROR(calculations!O21/calculations!O20*((calculations!O41+calculations!O244)*$B$11+calculations!O42*$B$12+calculations!O43*$B$13+calculations!O44*$B$14+calculations!O45*$B$15*INDEX(input_data!$L:$L,MATCH("all.in.cs2.stl.drg.---",input_data!$A:$A,0))),0)+IFERROR(calculations!O49/calculations!O48*((calculations!O69+calculations!O249)*$B$11+calculations!O70*$B$12+calculations!O71*$B$13+calculations!O72*$B$14+calculations!O73*$B$15*INDEX(input_data!$L:$L,MATCH("all.in.cs2.stl.scr.---",input_data!$A:$A,0))),0)+IFERROR(calculations!O77/calculations!O76*((calculations!O97+calculations!O254)*$B$11+calculations!O98*$B$12+calculations!O99*$B$13+calculations!O100*$B$14+calculations!O101*$B$15*INDEX(input_data!$L:$L,MATCH("all.in.cs2.stl.bof.---",input_data!$A:$A,0))),0)+IFERROR(calculations!O105/calculations!O104*((calculations!O125+calculations!O259)*$B$11+calculations!O126*$B$12+calculations!O127*$B$13+calculations!O128*$B$14+calculations!O129*$B$15*INDEX(input_data!$L:$L,MATCH("all.in.cs2.cmt.dry.---",input_data!$A:$A,0))),0)+IFERROR(calculations!O133/calculations!O132*((calculations!O153+calculations!O264)*$B$11+calculations!O154*$B$12+calculations!O155*$B$13+calculations!O156*$B$14+calculations!O157*$B$15*INDEX(input_data!$L:$L,MATCH("all.in.cs2.frt.amc.---",input_data!$A:$A,0))),0)+IFERROR(calculations!O161/calculations!O160*((calculations!O181+calculations!O269)*$B$11+calculations!O182*$B$12+calculations!O183*$B$13+calculations!O184*$B$14+calculations!O185*$B$15*INDEX(input_data!$L:$L,MATCH("all.in.cs2.frt.ure.---",input_data!$A:$A,0))),0)+IFERROR(calculations!O189/calculations!O188*((calculations!O209+calculations!O274)*$B$11+calculations!O210*$B$12+calculations!O211*$B$13+calculations!O212*$B$14+calculations!O213*$B$15*INDEX(input_data!$L:$L,MATCH("all.in.cs2.frt.nit.---",input_data!$A:$A,0))),0)+IFERROR(calculations!O217/calculations!O216*((calculations!O237+calculations!O279)*$B$11+calculations!O238*$B$12+calculations!O239*$B$13+calculations!O240*$B$14+calculations!O241*$B$15*INDEX(input_data!$L:$L,MATCH("all.in.cs2.alu.prp.---",input_data!$A:$A,0))),0)+IFERROR(calculations!O287/calculations!O286*((calculations!O307+calculations!O312)*$B$11+calculations!O308*$B$12+calculations!O309*$B$13+calculations!O310*$B$14+calculations!O311*$B$15*INDEX(input_data!$L:$L,MATCH("all.in.cs2.stl.oth.---",input_data!$A:$A,0))),0)+IFERROR(calculations!O319/calculations!O318*((calculations!O339+calculations!O344)*$B$11+calculations!O340*$B$12+calculations!O341*$B$13+calculations!O342*$B$14+calculations!O343*$B$15*INDEX(input_data!$L:$L,MATCH("all.in.cs2.frt.otn.---",input_data!$A:$A,0))),0)),0) -> 34.6168 | G28: =IFERROR((IFERROR(calculations!P21*calculations!P248,0)+IFERROR(calculations!P49*calculations!P253,0)+IFERROR(calculations!P77*calculations!P258,0)+IFERROR(calculations!P105*calculations!P263,0)+IFERROR(calculations!P133*calculations!P268,0)+IFERROR(calculations!P161*calculations!P273,0)+IFERROR(calculations!P189*calculations!P278,0)+IFERROR(calculations!P217*calculations!P283,0)+IFERROR(calculations!P287*calculations!P316,0)+IFERROR(calculations!P319*calculations!P348,0))/(IFERROR(calculations!P21/calculations!P20*((calculations!P41+calculations!P244)*$B$11+calculations!P42*$B$12+calculations!P43*$B$13+calculations!P44*$B$14+calculations!P45*$B$15*INDEX(input_data!$L:$L,MATCH("all.in.cs2.stl.drg.---",input_data!$A:$A,0))),0)+IFERROR(calculations!P49/calculations!P48*((calculations!P69+calculations!P249)*$B$11+calculations!P70*$B$12+calculations!P71*$B$13+calculations!P72*$B$14+calculations!P73*$B$15*INDEX(input_data!$L:$L,MATCH("all.in.cs2.stl.scr.---",input_data!$A:$A,0))),0)+IFERROR(calculations!P77/calculations!P76*((calculations!P97+calculations!P254)*$B$11+calculations!P98*$B$12+calculations!P99*$B$13+calculations!P100*$B$14+calculations!P101*$B$15*INDEX(input_data!$L:$L,MATCH("all.in.cs2.stl.bof.---",input_data!$A:$A,0))),0)+IFERROR(calculations!P105/calculations!P104*((calculations!P125+calculations!P259)*$B$11+calculations!P126*$B$12+calculations!P127*$B$13+calculations!P128*$B$14+calculations!P129*$B$15*INDEX(input_data!$L:$L,MATCH("all.in.cs2.cmt.dry.---",input_data!$A:$A,0))),0)+IFERROR(calculations!P133/calculations!P132*((calculations!P153+calculations!P264)*$B$11+calculations!P154*$B$12+calculations!P155*$B$13+calculations!P156*$B$14+calculations!P157*$B$15*INDEX(input_data!$L:$L,MATCH("all.in.cs2.frt.amc.---",input_data!$A:$A,0))),0)+IFERROR(calculations!P161/calculations!P160*((calculations!P181+calculations!P269)*$B$11+calculations!P182*$B$12+calculations!P183*$B$13+calculations!P184*$B$14+calculations!P185*$B$15*INDEX(input_data!$L:$L,MATCH("all.in.cs2.frt.ure.---",input_data!$A:$A,0))),0)+IFERROR(calculations!P189/calculations!P188*((calculations!P209+calculations!P274)*$B$11+calculations!P210*$B$12+calculations!P211*$B$13+calculations!P212*$B$14+calculations!P213*$B$15*INDEX(input_data!$L:$L,MATCH("all.in.cs2.frt.nit.---",input_data!$A:$A,0))),0)+IFERROR(calculations!P217/calculations!P216*((calculations!P237+calculations!P279)*$B$11+calculations!P238*$B$12+calculations!P239*$B$13+calculations!P240*$B$14+calculations!P241*$B$15*INDEX(input_data!$L:$L,MATCH("all.in.cs2.alu.prp.---",input_data!$A:$A,0))),0)+IFERROR(calculations!P287/calculations!P286*((calculations!P307+calculations!P312)*$B$11+calculations!P308*$B$12+calculations!P309*$B$13+calculations!P310*$B$14+calculations!P311*$B$15*INDEX(input_data!$L:$L,MATCH("all.in.cs2.stl.oth.---",input_data!$A:$A,0))),0)+IFERROR(calculations!P319/calculations!P318*((calculations!P339+calculations!P344)*$B$11+calculations!P340*$B$12+calculations!P341*$B$13+calculations!P342*$B$14+calculations!P343*$B$15*INDEX(input_data!$L:$L,MATCH("all.in.cs2.frt.otn.---",input_data!$A:$A,0))),0)),0) -> 38.153867 | H28: =IFERROR((IFERROR(calculations!Q21*calculations!Q248,0)+IFERROR(calculations!Q49*calculations!Q253,0)+IFERROR(calculations!Q77*calculations!Q258,0)+IFERROR(calculations!Q105*calculations!Q263,0)+IFERROR(calculations!Q133*calculations!Q268,0)+IFERROR(calculations!Q161*calculations!Q273,0)+IFERROR(calculations!Q189*calculations!Q278,0)+IFERROR(calculations!Q217*calculations!Q283,0)+IFERROR(calculations!Q287*calculations!Q316,0)+IFERROR(calculations!Q319*calculations!Q348,0))/(IFERROR(calculations!Q21/calculations!Q20*((calculations!Q41+calculations!Q244)*$B$11+calculations!Q42*$B$12+calculations!Q43*$B$13+calculations!Q44*$B$14+calculations!Q45*$B$15*INDEX(input_data!$L:$L,MATCH("all.in.cs2.stl.drg.---",input_data!$A:$A,0))),0)+IFERROR(calculations!Q49/calculations!Q48*((calculations!Q69+calculations!Q249)*$B$11+calculations!Q70*$B$12+calculations!Q71*$B$13+calculations!Q72*$B$14+calculations!Q73*$B$15*INDEX(input_data!$L:$L,MATCH("all.in.cs2.stl.scr.---",input_data!$A:$A,0))),0)+IFERROR(calculations!Q77/calculations!Q76*((calculations!Q97+calculations!Q254)*$B$11+calculations!Q98*$B$12+calculations!Q99*$B$13+calculations!Q100*$B$14+calculations!Q101*$B$15*INDEX(input_data!$L:$L,MATCH("all.in.cs2.stl.bof.---",input_data!$A:$A,0))),0)+IFERROR(calculations!Q105/calculations!Q104*((calculations!Q125+calculations!Q259)*$B$11+calculations!Q126*$B$12+calculations!Q127*$B$13+calculations!Q128*$B$14+calculations!Q129*$B$15*INDEX(input_data!$L:$L,MATCH("all.in.cs2.cmt.dry.---",input_data!$A:$A,0))),0)+IFERROR(calculations!Q133/calculations!Q132*((calculations!Q153+calculations!Q264)*$B$11+calculations!Q154*$B$12+calculations!Q155*$B$13+calculations!Q156*$B$14+calculations!Q157*$B$15*INDEX(input_data!$L:$L,MATCH("all.in.cs2.frt.amc.---",input_data!$A:$A,0))),0)+IFERROR(calculations!Q161/calculations!Q160*((calculations!Q181+calculations!Q269)*$B$11+calculations!Q182*$B$12+calculations!Q183*$B$13+calculations!Q184*$B$14+calculations!Q185*$B$15*INDEX(input_data!$L:$L,MATCH("all.in.cs2.frt.ure.---",input_data!$A:$A,0))),0)+IFERROR(calculations!Q189/calculations!Q188*((calculations!Q209+calculations!Q274)*$B$11+calculations!Q210*$B$12+calculations!Q211*$B$13+calculations!Q212*$B$14+calculations!Q213*$B$15*INDEX(input_data!$L:$L,MATCH("all.in.cs2.frt.nit.---",input_data!$A:$A,0))),0)+IFERROR(calculations!Q217/calculations!Q216*((calculations!Q237+calculations!Q279)*$B$11+calculations!Q238*$B$12+calculations!Q239*$B$13+calculations!Q240*$B$14+calculations!Q241*$B$15*INDEX(input_data!$L:$L,MATCH("all.in.cs2.alu.prp.---",input_data!$A:$A,0))),0)+IFERROR(calculations!Q287/calculations!Q286*((calculations!Q307+calculations!Q312)*$B$11+calculations!Q308*$B$12+calculations!Q309*$B$13+calculations!Q310*$B$14+calculations!Q311*$B$15*INDEX(input_data!$L:$L,MATCH("all.in.cs2.stl.oth.---",input_data!$A:$A,0))),0)+IFERROR(calculations!Q319/calculations!Q318*((calculations!Q339+calculations!Q344)*$B$11+calculations!Q340*$B$12+calculations!Q341*$B$13+calculations!Q342*$B$14+calculations!Q343*$B$15*INDEX(input_data!$L:$L,MATCH("all.in.cs2.frt.otn.---",input_data!$A:$A,0))),0)),0) -> 43.768314 | I28: =IFERROR((IFERROR(calculations!R21*calculations!R248,0)+IFERROR(calculations!R49*calculations!R253,0)+IFERROR(calculations!R77*calculations!R258,0)+IFERROR(calculations!R105*calculations!R263,0)+IFERROR(calculations!R133*calculations!R268,0)+IFERROR(calculations!R161*calculations!R273,0)+IFERROR(calculations!R189*calculations!R278,0)+IFERROR(calculations!R217*calculations!R283,0)+IFERROR(calculations!R287*calculations!R316,0)+IFERROR(calculations!R319*calculations!R348,0))/(IFERROR(calculations!R21/calculations!R20*((calculations!R41+calculations!R244)*$B$11+calculations!R42*$B$12+calculations!R43*$B$13+calculations!R44*$B$14+calculations!R45*$B$15*INDEX(input_data!$L:$L,MATCH("all.in.cs2.stl.drg.---",input_data!$A:$A,0))),0)+IFERROR(calculations!R49/calculations!R48*((calculations!R69+calculations!R249)*$B$11+calculations!R70*$B$12+calculations!R71*$B$13+calculations!R72*$B$14+calculations!R73*$B$15*INDEX(input_data!$L:$L,MATCH("all.in.cs2.stl.scr.---",input_data!$A:$A,0))),0)+IFERROR(calculations!R77/calculations!R76*((calculations!R97+calculations!R254)*$B$11+calculations!R98*$B$12+calculations!R99*$B$13+calculations!R100*$B$14+calculations!R101*$B$15*INDEX(input_data!$L:$L,MATCH("all.in.cs2.stl.bof.---",input_data!$A:$A,0))),0)+IFERROR(calculations!R105/calculations!R104*((calculations!R125+calculations!R259)*$B$11+calculations!R126*$B$12+calculations!R127*$B$13+calculations!R128*$B$14+calculations!R129*$B$15*INDEX(input_data!$L:$L,MATCH("all.in.cs2.cmt.dry.---",input_data!$A:$A,0))),0)+IFERROR(calculations!R133/calculations!R132*((calculations!R153+calculations!R264)*$B$11+calculations!R154*$B$12+calculations!R155*$B$13+calculations!R156*$B$14+calculations!R157*$B$15*INDEX(input_data!$L:$L,MATCH("all.in.cs2.frt.amc.---",input_data!$A:$A,0))),0)+IFERROR(calculations!R161/calculations!R160*((calculations!R181+calculations!R269)*$B$11+calculations!R182*$B$12+calculations!R183*$B$13+calculations!R184*$B$14+calculations!R185*$B$15*INDEX(input_data!$L:$L,MATCH("all.in.cs2.frt.ure.---",input_data!$A:$A,0))),0)+IFERROR(calculations!R189/calculations!R188*((calculations!R209+calculations!R274)*$B$11+calculations!R210*$B$12+calculations!R211*$B$13+calculations!R212*$B$14+calculations!R213*$B$15*INDEX(input_data!$L:$L,MATCH("all.in.cs2.frt.nit.---",input_data!$A:$A,0))),0)+IFERROR(calculations!R217/calculations!R216*((calculations!R237+calculations!R279)*$B$11+calculations!R238*$B$12+calculations!R239*$B$13+calculations!R240*$B$14+calculations!R241*$B$15*INDEX(input_data!$L:$L,MATCH("all.in.cs2.alu.prp.---",input_data!$A:$A,0))),0)+IFERROR(calculations!R287/calculations!R286*((calculations!R307+calculations!R312)*$B$11+calculations!R308*$B$12+calculations!R309*$B$13+calculations!R310*$B$14+calculations!R311*$B$15*INDEX(input_data!$L:$L,MATCH("all.in.cs2.stl.oth.---",input_data!$A:$A,0))),0)+IFERROR(calculations!R319/calculations!R318*((calculations!R339+calculations!R344)*$B$11+calculations!R340*$B$12+calculations!R341*$B$13+calculations!R342*$B$14+calculations!R343*$B$15*INDEX(input_data!$L:$L,MATCH("all.in.cs2.frt.otn.---",input_data!$A:$A,0))),0)),0) -> 53.28536 | J28: =IFERROR((IFERROR(calculations!S21*calculations!S248,0)+IFERROR(calculations!S49*calculations!S253,0)+IFERROR(calculations!S77*calculations!S258,0)+IFERROR(calculations!S105*calculations!S263,0)+IFERROR(calculations!S133*calculations!S268,0)+IFERROR(calculations!S161*calculations!S273,0)+IFERROR(calculations!S189*calculations!S278,0)+IFERROR(calculations!S217*calculations!S283,0)+IFERROR(calculations!S287*calculations!S316,0)+IFERROR(calculations!S319*calculations!S348,0))/(IFERROR(calculations!S21/calculations!S20*((calculations!S41+calculations!S244)*$B$11+calculations!S42*$B$12+calculations!S43*$B$13+calculations!S44*$B$14+calculations!S45*$B$15*INDEX(input_data!$L:$L,MATCH("all.in.cs2.stl.drg.---",input_data!$A:$A,0))),0)+IFERROR(calculations!S49/calculations!S48*((calculations!S69+calculations!S249)*$B$11+calculations!S70*$B$12+calculations!S71*$B$13+calculations!S72*$B$14+calculations!S73*$B$15*INDEX(input_data!$L:$L,MATCH("all.in.cs2.stl.scr.---",input_data!$A:$A,0))),0)+IFERROR(calculations!S77/calculations!S76*((calculations!S97+calculations!S254)*$B$11+calculations!S98*$B$12+calculations!S99*$B$13+calculations!S100*$B$14+calculations!S101*$B$15*INDEX(input_data!$L:$L,MATCH("all.in.cs2.stl.bof.---",input_data!$A:$A,0))),0)+IFERROR(calculations!S105/calculations!S104*((calculations!S125+calculations!S259)*$B$11+calculations!S126*$B$12+calculations!S127*$B$13+calculations!S128*$B$14+calculations!S129*$B$15*INDEX(input_data!$L:$L,MATCH("all.in.cs2.cmt.dry.---",input_data!$A:$A,0))),0)+IFERROR(calculations!S133/calculations!S132*((calculations!S153+calculations!S264)*$B$11+calculations!S154*$B$12+calculations!S155*$B$13+calculations!S156*$B$14+calculations!S157*$B$15*INDEX(input_data!$L:$L,MATCH("all.in.cs2.frt.amc.---",input_data!$A:$A,0))),0)+IFERROR(calculations!S161/calculations!S160*((calculations!S181+calculations!S269)*$B$11+calculations!S182*$B$12+calculations!S183*$B$13+calculations!S184*$B$14+calculations!S185*$B$15*INDEX(input_data!$L:$L,MATCH("all.in.cs2.frt.ure.---",input_data!$A:$A,0))),0)+IFERROR(calculations!S189/calculations!S188*((calculations!S209+calculations!S274)*$B$11+calculations!S210*$B$12+calculations!S211*$B$13+calculations!S212*$B$14+calculations!S213*$B$15*INDEX(input_data!$L:$L,MATCH("all.in.cs2.frt.nit.---",input_data!$A:$A,0))),0)+IFERROR(calculations!S217/calculations!S216*((calculations!S237+calculations!S279)*$B$11+calculations!S238*$B$12+calculations!S239*$B$13+calculations!S240*$B$14+calculations!S241*$B$15*INDEX(input_data!$L:$L,MATCH("all.in.cs2.alu.prp.---",input_data!$A:$A,0))),0)+IFERROR(calculations!S287/calculations!S286*((calculations!S307+calculations!S312)*$B$11+calculations!S308*$B$12+calculations!S309*$B$13+calculations!S310*$B$14+calculations!S311*$B$15*INDEX(input_data!$L:$L,MATCH("all.in.cs2.stl.oth.---",input_data!$A:$A,0))),0)+IFERROR(calculations!S319/calculations!S318*((calculations!S339+calculations!S344)*$B$11+calculations!S340*$B$12+calculations!S341*$B$13+calculations!S342*$B$14+calculations!S343*$B$15*INDEX(input_data!$L:$L,MATCH("all.in.cs2.frt.otn.---",input_data!$A:$A,0))),0)),0) -> 76.914135 | K28: =IFERROR((IFERROR(calculations!T21*calculations!T248,0)+IFERROR(calculations!T49*calculations!T253,0)+IFERROR(calculations!T77*calculations!T258,0)+IFERROR(calculations!T105*calculations!T263,0)+IFERROR(calculations!T133*calculations!T268,0)+IFERROR(calculations!T161*calculations!T273,0)+IFERROR(calculations!T189*calculations!T278,0)+IFERROR(calculations!T217*calculations!T283,0)+IFERROR(calculations!T287*calculations!T316,0)+IFERROR(calculations!T319*calculations!T348,0))/(IFERROR(calculations!T21/calculations!T20*((calculations!T41+calculations!T244)*$B$11+calculations!T42*$B$12+calculations!T43*$B$13+calculations!T44*$B$14+calculations!T45*$B$15*INDEX(input_data!$L:$L,MATCH("all.in.cs2.stl.drg.---",input_data!$A:$A,0))),0)+IFERROR(calculations!T49/calculations!T48*((calculations!T69+calculations!T249)*$B$11+calculations!T70*$B$12+calculations!T71*$B$13+calculations!T72*$B$14+calculations!T73*$B$15*INDEX(input_data!$L:$L,MATCH("all.in.cs2.stl.scr.---",input_data!$A:$A,0))),0)+IFERROR(calculations!T77/calculations!T76*((calculations!T97+calculations!T254)*$B$11+calculations!T98*$B$12+calculations!T99*$B$13+calculations!T100*$B$14+calculations!T101*$B$15*INDEX(input_data!$L:$L,MATCH("all.in.cs2.stl.bof.---",input_data!$A:$A,0))),0)+IFERROR(calculations!T105/calculations!T104*((calculations!T125+calculations!T259)*$B$11+calculations!T126*$B$12+calculations!T127*$B$13+calculations!T128*$B$14+calculations!T129*$B$15*INDEX(input_data!$L:$L,MATCH("all.in.cs2.cmt.dry.---",input_data!$A:$A,0))),0)+IFERROR(calculations!T133/calculations!T132*((calculations!T153+calculations!T264)*$B$11+calculations!T154*$B$12+calculations!T155*$B$13+calculations!T156*$B$14+calculations!T157*$B$15*INDEX(input_data!$L:$L,MATCH("all.in.cs2.frt.amc.---",input_data!$A:$A,0))),0)+IFERROR(calculations!T161/calculations!T160*((calculations!T181+calculations!T269)*$B$11+calculations!T182*$B$12+calculations!T183*$B$13+calculations!T184*$B$14+calculations!T185*$B$15*INDEX(input_data!$L:$L,MATCH("all.in.cs2.frt.ure.---",input_data!$A:$A,0))),0)+IFERROR(calculations!T189/calculations!T188*((calculations!T209+calculations!T274)*$B$11+calculations!T210*$B$12+calculations!T211*$B$13+calculations!T212*$B$14+calculations!T213*$B$15*INDEX(input_data!$L:$L,MATCH("all.in.cs2.frt.nit.---",input_data!$A:$A,0))),0)+IFERROR(calculations!T217/calculations!T216*((calculations!T237+calculations!T279)*$B$11+calculations!T238*$B$12+calculations!T239*$B$13+calculations!T240*$B$14+calculations!T241*$B$15*INDEX(input_data!$L:$L,MATCH("all.in.cs2.alu.prp.---",input_data!$A:$A,0))),0)+IFERROR(calculations!T287/calculations!T286*((calculations!T307+calculations!T312)*$B$11+calculations!T308*$B$12+calculations!T309*$B$13+calculations!T310*$B$14+calculations!T311*$B$15*INDEX(input_data!$L:$L,MATCH("all.in.cs2.stl.oth.---",input_data!$A:$A,0))),0)+IFERROR(calculations!T319/calculations!T318*((calculations!T339+calculations!T344)*$B$11+calculations!T340*$B$12+calculations!T341*$B$13+calculations!T342*$B$14+calculations!T343*$B$15*INDEX(input_data!$L:$L,MATCH("all.in.cs2.frt.otn.---",input_data!$A:$A,0))),0)),0) -> 92.786248 | ... O28: =IFERROR((IFERROR(calculations!X21*calculations!X248,0)+IFERROR(calculations!X49*calculations!X253,0)+IFERROR(calculations!X77*calculations!X258,0)+IFERROR(calculations!X105*calculations!X263,0)+IFERROR(calculations!X133*calculations!X268,0)+IFERROR(calculations!X161*calculations!X273,0)+IFERROR(calculations!X189*calculations!X278,0)+IFERROR(calculations!X217*calculations!X283,0)+IFERROR(calculations!X287*calculations!X316,0)+IFERROR(calculations!X319*calculations!X348,0))/(IFERROR(calculations!X21/calculations!X20*((calculations!X41+calculations!X244)*$B$11+calculations!X42*$B$12+calculations!X43*$B$13+calculations!X44*$B$14+calculations!X45*$B$15*INDEX(input_data!$L:$L,MATCH("all.in.cs2.stl.drg.---",input_data!$A:$A,0))),0)+IFERROR(calculations!X49/calculations!X48*((calculations!X69+calculations!X249)*$B$11+calculations!X70*$B$12+calculations!X71*$B$13+calculations!X72*$B$14+calculations!X73*$B$15*INDEX(input_data!$L:$L,MATCH("all.in.cs2.stl.scr.---",input_data!$A:$A,0))),0)+IFERROR(calculations!X77/calculations!X76*((calculations!X97+calculations!X254)*$B$11+calculations!X98*$B$12+calculations!X99*$B$13+calculations!X100*$B$14+calculations!X101*$B$15*INDEX(input_data!$L:$L,MATCH("all.in.cs2.stl.bof.---",input_data!$A:$A,0))),0)+IFERROR(calculations!X105/calculations!X104*((calculations!X125+calculations!X259)*$B$11+calculations!X126*$B$12+calculations!X127*$B$13+calculations!X128*$B$14+calculations!X129*$B$15*INDEX(input_data!$L:$L,MATCH("all.in.cs2.cmt.dry.---",input_data!$A:$A,0))),0)+IFERROR(calculations!X133/calculations!X132*((calculations!X153+calculations!X264)*$B$11+calculations!X154*$B$12+calculations!X155*$B$13+calculations!X156*$B$14+calculations!X157*$B$15*INDEX(input_data!$L:$L,MATCH("all.in.cs2.frt.amc.---",input_data!$A:$A,0))),0)+IFERROR(calculations!X161/calculations!X160*((calculations!X181+calculations!X269)*$B$11+calculations!X182*$B$12+calculations!X183*$B$13+calculations!X184*$B$14+calculations!X185*$B$15*INDEX(input_data!$L:$L,MATCH("all.in.cs2.frt.ure.---",input_data!$A:$A,0))),0)+IFERROR(calculations!X189/calculations!X188*((calculations!X209+calculations!X274)*$B$11+calculations!X210*$B$12+calculations!X211*$B$13+calculations!X212*$B$14+calculations!X213*$B$15*INDEX(input_data!$L:$L,MATCH("all.in.cs2.frt.nit.---",input_data!$A:$A,0))),0)+IFERROR(calculations!X217/calculations!X216*((calculations!X237+calculations!X279)*$B$11+calculations!X238*$B$12+calculations!X239*$B$13+calculations!X240*$B$14+calculations!X241*$B$15*INDEX(input_data!$L:$L,MATCH("all.in.cs2.alu.prp.---",input_data!$A:$A,0))),0)+IFERROR(calculations!X287/calculations!X286*((calculations!X307+calculations!X312)*$B$11+calculations!X308*$B$12+calculations!X309*$B$13+calculations!X310*$B$14+calculations!X311*$B$15*INDEX(input_data!$L:$L,MATCH("all.in.cs2.stl.oth.---",input_data!$A:$A,0))),0)+IFERROR(calculations!X319/calculations!X318*((calculations!X339+calculations!X344)*$B$11+calculations!X340*$B$12+calculations!X341*$B$13+calculations!X342*$B$14+calculations!X343*$B$15*INDEX(input_data!$L:$L,MATCH("all.in.cs2.frt.otn.---",input_data!$A:$A,0))),0)),0) -> 154
A29: ↓ DOMESTIC CARBON PRICE (editable, default = optimal) | B29: USD/tCO2 | D29: =D28 -> 0 | E29: =E28 -> 0 | F29: =F28 -> 34.6168 | G29: =G28 -> 38.153867 | H29: =H28 -> 43.768314 | I29: =I28 -> 53.28536 | J29: =J28 -> 76.914135 | K29: =K28 -> 92.786248 | ... O29: =O28 -> 154
A31: 4. HEADLINE REVENUES (USD millions)
A32: row | B32: unit | D32: 2024 | E32: 2025 | F32: 2026 | G32: 2027 | H32: 2028 | I32: 2029 | J32: 2030 | K32: 2031 | L32: 2032 | M32: 2033 | N32: 2034 | O32: 2035
A33: EU CBAM obligation gross | B33: USD m | D33: =IFERROR(calculations!M21*calculations!M248,0)+IFERROR(calculations!M49*calculations!M253,0)+IFERROR(calculations!M77*calculations!M258,0)+IFERROR(calculations!M105*calculations!M263,0)+IFERROR(calculations!M133*calculations!M268,0)+IFERROR(calculations!M161*calculations!M273,0)+IFERROR(calculations!M189*calculations!M278,0)+IFERROR(calculations!M217*calculations!M283,0)+IFERROR(calculations!M287*calculations!M316,0)+IFERROR(calculations!M319*calculations!M348,0) -> 0 | E33: =IFERROR(calculations!N21*calculations!N248,0)+IFERROR(calculations!N49*calculations!N253,0)+IFERROR(calculations!N77*calculations!N258,0)+IFERROR(calculations!N105*calculations!N263,0)+IFERROR(calculations!N133*calculations!N268,0)+IFERROR(calculations!N161*calculations!N273,0)+IFERROR(calculations!N189*calculations!N278,0)+IFERROR(calculations!N217*calculations!N283,0)+IFERROR(calculations!N287*calculations!N316,0)+IFERROR(calculations!N319*calculations!N348,0) -> 0 | F33: =IFERROR(calculations!O21*calculations!O248,0)+IFERROR(calculations!O49*calculations!O253,0)+IFERROR(calculations!O77*calculations!O258,0)+IFERROR(calculations!O105*calculations!O263,0)+IFERROR(calculations!O133*calculations!O268,0)+IFERROR(calculations!O161*calculations!O273,0)+IFERROR(calculations!O189*calculations!O278,0)+IFERROR(calculations!O217*calculations!O283,0)+IFERROR(calculations!O287*calculations!O316,0)+IFERROR(calculations!O319*calculations!O348,0) -> 76.689832 | G33: =IFERROR(calculations!P21*calculations!P248,0)+IFERROR(calculations!P49*calculations!P253,0)+IFERROR(calculations!P77*calculations!P258,0)+IFERROR(calculations!P105*calculations!P263,0)+IFERROR(calculations!P133*calculations!P268,0)+IFERROR(calculations!P161*calculations!P273,0)+IFERROR(calculations!P189*calculations!P278,0)+IFERROR(calculations!P217*calculations!P283,0)+IFERROR(calculations!P287*calculations!P316,0)+IFERROR(calculations!P319*calculations!P348,0) -> 88.082977 | H33: =IFERROR(calculations!Q21*calculations!Q248,0)+IFERROR(calculations!Q49*calculations!Q253,0)+IFERROR(calculations!Q77*calculations!Q258,0)+IFERROR(calculations!Q105*calculations!Q263,0)+IFERROR(calculations!Q133*calculations!Q268,0)+IFERROR(calculations!Q161*calculations!Q273,0)+IFERROR(calculations!Q189*calculations!Q278,0)+IFERROR(calculations!Q217*calculations!Q283,0)+IFERROR(calculations!Q287*calculations!Q316,0)+IFERROR(calculations!Q319*calculations!Q348,0) -> 105.31264 | I33: =IFERROR(calculations!R21*calculations!R248,0)+IFERROR(calculations!R49*calculations!R253,0)+IFERROR(calculations!R77*calculations!R258,0)+IFERROR(calculations!R105*calculations!R263,0)+IFERROR(calculations!R133*calculations!R268,0)+IFERROR(calculations!R161*calculations!R273,0)+IFERROR(calculations!R189*calculations!R278,0)+IFERROR(calculations!R217*calculations!R283,0)+IFERROR(calculations!R287*calculations!R316,0)+IFERROR(calculations!R319*calculations!R348,0) -> 133.6473 | J33: =IFERROR(calculations!S21*calculations!S248,0)+IFERROR(calculations!S49*calculations!S253,0)+IFERROR(calculations!S77*calculations!S258,0)+IFERROR(calculations!S105*calculations!S263,0)+IFERROR(calculations!S133*calculations!S268,0)+IFERROR(calculations!S161*calculations!S273,0)+IFERROR(calculations!S189*calculations!S278,0)+IFERROR(calculations!S217*calculations!S283,0)+IFERROR(calculations!S287*calculations!S316,0)+IFERROR(calculations!S319*calculations!S348,0) -> 201.1194 | K33: =IFERROR(calculations!T21*calculations!T248,0)+IFERROR(calculations!T49*calculations!T253,0)+IFERROR(calculations!T77*calculations!T258,0)+IFERROR(calculations!T105*calculations!T263,0)+IFERROR(calculations!T133*calculations!T268,0)+IFERROR(calculations!T161*calculations!T273,0)+IFERROR(calculations!T189*calculations!T278,0)+IFERROR(calculations!T217*calculations!T283,0)+IFERROR(calculations!T287*calculations!T316,0)+IFERROR(calculations!T319*calculations!T348,0) -> 252.9825 | ... O33: =IFERROR(calculations!X21*calculations!X248,0)+IFERROR(calculations!X49*calculations!X253,0)+IFERROR(calculations!X77*calculations!X258,0)+IFERROR(calculations!X105*calculations!X263,0)+IFERROR(calculations!X133*calculations!X268,0)+IFERROR(calculations!X161*calculations!X273,0)+IFERROR(calculations!X189*calculations!X278,0)+IFERROR(calculations!X217*calculations!X283,0)+IFERROR(calculations!X287*calculations!X316,0)+IFERROR(calculations!X319*calculations!X348,0) -> 497.03882
